Workbook
Name CompanyAddress: [1]Settings!$C$10
Name CompanyName: '[1]Tour Info'!$F$6
Name Rates: [1]Settings!$C$2:$C$7
Name YesNo: [1]Settings!$C$15:$C$16

Sheet Tour Dates
A1: Tour Dates
A3: Date | B3: City | C3: STATE | D3: VENUE | E3: Country
A4: 46043 | B4: ORLANDO | C4: FL | D4: KIA CENTER | E4: USA
A5: 46044 | B5: JACKSONVILLE | C5: FL | D5: VYSTAR MEMORIAL ARENA | E5: USA
A6: 46046 | B6: KNOXVILLE | C6: TN | D6: THOMPSON-BOLING ARENA | E6: USA
A7: 46047 | B7: CHARLOTTE | C7: NC | D7: SPECTRUM CENTER | E7: USA
A8: 46048 | B8: GREENVILLE | C8: SC | D8: BON SECOURS ARENA | E8: USA
A9: 46050 | B9: UNCASVILLE | C9: CT | D9: MOHEGAN SUN ARENA | E9: USA
A10: 46052 | B10: MONTREAL | C10: QC | D10: BELL CENTRE | E10: CANADA
A11: 46053 | B11: TORONTO | C11: ON | D11: SCOTIABANK ARENA | E11: CANADA
A12: 46055 | B12: COLUMBUS | C12: OH | D12: NATIONWIDE ARENA | E12: USA
A13: 46057 | B13: CINCINNATI | C13: OH | D13: HERITAGE BANK CENTER | E13: USA
A14: 46058 | B14: PEORIA | C14: IL | D14: CIVIC CENTER ARENA | E14: USA
A15: 46060 | B15: TULSA | C15: OK | D15: BOK CENTER | E15: USA
... A23: 46076 | B23: INGLEWOOD | C23: CA | D23: INTUIT DOME | E23: USA

Sheet Inventory
B1: Tour Inventory
B3: Tour | C3: GHOST | D3: GARMENTS x 50 | E3: TRINKETS X 50
B4: Tour Date | C4: JAN-FEB 2026
B5: Formula | E5: Formula | F5: Formula | G5: Formula | J5: QUICK STOCK VIEW | R5: PRODUCT SUMMARY
B6: BC Item Code | C6: Product Description | D6: Supplier | E6: Blank Unit Cost | F6: Print Unit Cost | G6: Full Package | H6: Total Unit Cost | J6: Sales | K6: Used | L6: Road | M6: Ware house | N6: Sales % | P6: End Tour Stock Count | R6: B/F | S6: Purchased | T6: Sold | U6: W/S | V6: Band Comps | W6: GMS Comps | X6: O/U | Y6: Retail | Z6: Web | AA6: Global UK | AB6: Other | AC6: Misprint | AD6: Closing Stock | AE6: Closing Stock
A7: 1 | B7: GHOSNS903311BK | C7: BATWING HOODY | D7: FARSTAR | E7: =VLOOKUP($A:$A,'COG NA'!$A:$G,5,FALSE) -> 0 | F7: =VLOOKUP($A:$A,'COG NA'!$A:$G,6,FALSE) -> 0 | G7: =VLOOKUP($A:$A,'COG NA'!$A:$G,7,FALSE) -> 28.5 | H7: =SUM(E7:G7) -> 28.5 | J7: ='BATWNG HOODY'!$C$64 -> 0 | K7: ='BATWNG HOODY'!$G$64 -> 0 | L7: ='BATWNG HOODY'!$L$64 -> 3667 | M7: ='BATWNG HOODY'!$S$64 -> 3746 | N7: ='BATWNG HOODY'!$M$64 -> 0 | R7: ='BATWNG HOODY'!$V$39 -> 0 | S7: ='BATWNG HOODY'!$V$40 -> 6240 | T7: ='BATWNG HOODY'!$V$41 -> 0 | U7: ='BATWNG HOODY'!$V$44 -> 0 | V7: ='BATWNG HOODY'!$V$42 -> 0 | W7: ='BATWNG HOODY'!$V$43 -> 0 | X7: ='BATWNG HOODY'!$V$46 -> 0 | Y7: ='BATWNG HOODY'!$V$47 -> 0 | Z7: ='BATWNG HOODY'!$V$48 -> 0 | AA7: ='BATWNG HOODY'!$V$49 -> 0 | AB7: ='BATWNG HOODY'!$V$50 -> 2494 | AC7: ='BATWNG HOODY'!$V$51 -> 0 | AD7: ='BATWNG HOODY'!V$52+'BATWNG HOODY'!V$53 -> 3746 | AE7: =(R7+S7)-SUM(T7:AC7) -> 3746
A8: 2 | B8: GHOSRX203275BK | C8: SHORTS BLACK/ WHT PAPA V COSTUME CLAWS | D8: FARSTAR | E8: =VLOOKUP($A:$A,'COG NA'!$A:$G,5,FALSE) -> 0 | F8: =VLOOKUP($A:$A,'COG NA'!$A:$G,6,FALSE) -> 0 | G8: =VLOOKUP($A:$A,'COG NA'!$A:$G,7,FALSE) -> 5.8 | H8: =SUM(E8:G8) -> 5.8 | J8: =SHORTS!$C$64 -> 0 | K8: =SHORTS!$G$64 -> 0 | L8: =SHORTS!$L$64 -> 5358 | M8: =SHORTS!$S$64 -> 4652 | N8: =SHORTS!$M$64 -> 0 | R8: =SHORTS!$V$39 -> 706 | S8: =SHORTS!$V$40 -> 4652 | T8: =SHORTS!$V$41 -> 0 | U8: =SHORTS!$V$44 -> 0 | V8: =SHORTS!$V$42 -> 0 | W8: =SHORTS!$V$43 -> 0 | X8: =SHORTS!$V$46 -> 0 | Y8: =SHORTS!$V$47 -> 0 | Z8: =SHORTS!$V$48 -> 0 | AA8: =SHORTS!$V$49 -> 0 | AB8: =SHORTS!$V$50 -> 0 | AC8: =SHORTS!$V$51 -> 0 | AD8: =SHORTS!V$52+SHORTS!V$53 -> 5358 | AE8: =(R8+S8)-SUM(T8:AC8) -> 5358
A9: 3 | B9: =VLOOKUP(A:A,'COG NA'!A:B,2,FALSE) -> GHOSRX204001BK | C9: =VLOOKUP(B:B,'COG NA'!B:C,2,FALSE) -> BLACK T SKELETOUR 26 ITIN | D9: CULTURE | E9: =VLOOKUP($A:$A,'COG NA'!$A:$G,5,FALSE) -> 0 | F9: =VLOOKUP($A:$A,'COG NA'!$A:$G,6,FALSE) -> 0 | G9: =VLOOKUP($A:$A,'COG NA'!$A:$G,7,FALSE) -> 5.83 | H9: =SUM(E9:G9) -> 5.83 | J9: ='BLK T SKELETOR ITIN'!$C$64 -> 0 | K9: ='BLK T SKELETOR ITIN'!$G$64 -> 0 | L9: ='BLK T SKELETOR ITIN'!$L$64 -> 0 | M9: ='BLK T SKELETOR ITIN'!$S$64 -> 0 | N9: ='BLK T SKELETOR ITIN'!$M$64 -> 0 | R9: ='BLK T SKELETOR ITIN'!$V$39 -> 0 | S9: ='BLK T SKELETOR ITIN'!$V$40 -> 0 | T9: ='BLK T SKELETOR ITIN'!$V$41 -> 0 | U9: ='BLK T SKELETOR ITIN'!$V$44 -> 0 | V9: ='BLK T SKELETOR ITIN'!$V$42 -> 0 | W9: ='BLK T SKELETOR ITIN'!$V$43 -> 0 | X9: ='BLK T SKELETOR ITIN'!$V$46 -> 0 | Y9: ='BLK T SKELETOR ITIN'!$V$47 -> 0 | Z9: ='BLK T SKELETOR ITIN'!$V$48 -> 0 | AA9: ='BLK T SKELETOR ITIN'!$V$49 -> 0 | AB9: ='BLK T SKELETOR ITIN'!$V$50 -> 0 | AC9: ='BLK T SKELETOR ITIN'!$V$51 -> 0 | AD9: ='BLK T SKELETOR ITIN'!V$52+'BLK T SKELETOR ITIN'!V$53 -> 0 | AE9: =(R9+S9)-SUM(T9:AC9) -> 0
A10: 4 | B10: =VLOOKUP(A:A,'COG NA'!A:B,2,FALSE) -> GHOSRX204000BK | C10: =VLOOKUP(B:B,'COG NA'!B:C,2,FALSE) -> BLACK T BAT BRAIN 26 ITIN | D10: CULTURE | E10: =VLOOKUP($A:$A,'COG NA'!$A:$G,5,FALSE) -> 0 | F10: =VLOOKUP($A:$A,'COG NA'!$A:$G,6,FALSE) -> 0 | G10: =VLOOKUP($A:$A,'COG NA'!$A:$G,7,FALSE) -> 5.83 | H10: =SUM(E10:G10) -> 5.83 | J10: ='BLK T BAT BRAIN ITIN'!$C$64 -> 0 | K10: ='BLK T BAT BRAIN ITIN'!$G$64 -> 0 | L10: ='BLK T BAT BRAIN ITIN'!$L$64 -> 0 | M10: ='BLK T BAT BRAIN ITIN'!$S$64 -> 0 | N10: ='BLK T BAT BRAIN ITIN'!$M$64 -> 0 | R10: ='BLK T BAT BRAIN ITIN'!$V$39 -> 0 | S10: ='BLK T BAT BRAIN ITIN'!$V$40 -> 0 | T10: ='BLK T BAT BRAIN ITIN'!$V$41 -> 0 | U10: ='BLK T BAT BRAIN ITIN'!$V$44 -> 0 | V10: ='BLK T BAT BRAIN ITIN'!$V$42 -> 0 | W10: ='BLK T BAT BRAIN ITIN'!$V$43 -> 0 | X10: ='BLK T BAT BRAIN ITIN'!$V$46 -> 0 | Y10: ='BLK T BAT BRAIN ITIN'!$V$47 -> 0 | Z10: ='BLK T BAT BRAIN ITIN'!$V$48 -> 0 | AA10: ='BLK T BAT BRAIN ITIN'!$V$49 -> 0 | AB10: ='BLK T BAT BRAIN ITIN'!$V$50 -> 0 | AC10: ='BLK T BAT BRAIN ITIN'!$V$51 -> 0 | AD10: ='BLK T BAT BRAIN ITIN'!V$52+'BLK T BAT BRAIN ITIN'!V$53 -> 0 | AE10: =(R10+S10)-SUM(T10:AC10) -> 0
A11: 5 | B11: =VLOOKUP(A:A,'COG NA'!A:B,2,FALSE) -> GHOSRX204002BK | C11: =VLOOKUP(B:B,'COG NA'!B:C,2,FALSE) -> BLACK T WESTERN EMERITUS 26 ITIN | D11: CULTURE | E11: =VLOOKUP($A:$A,'COG NA'!$A:$G,5,FALSE) -> 0 | F11: =VLOOKUP($A:$A,'COG NA'!$A:$G,6,FALSE) -> 0 | G11: =VLOOKUP($A:$A,'COG NA'!$A:$G,7,FALSE) -> 5.83 | H11: =SUM(E11:G11) -> 5.83 | J11: ='BLK T WESTERN ITIN'!$C$64 -> 0 | K11: ='BLK T WESTERN ITIN'!$G$64 -> 0 | L11: ='BLK T WESTERN ITIN'!$L$64 -> 0 | M11: ='BLK T WESTERN ITIN'!$S$64 -> 0 | N11: ='BLK T WESTERN ITIN'!$M$64 -> 0 | R11: ='BLK T WESTERN ITIN'!$V$39 -> 0 | S11: ='BLK T WESTERN ITIN'!$V$40 -> 0 | T11: ='BLK T WESTERN ITIN'!$V$41 -> 0 | U11: ='BLK T WESTERN ITIN'!$V$44 -> 0 | V11: ='BLK T WESTERN ITIN'!$V$42 -> 0 | W11: ='BLK T WESTERN ITIN'!$V$43 -> 0 | X11: ='BLK T WESTERN ITIN'!$V$46 -> 0 | Y11: ='BLK T WESTERN ITIN'!$V$47 -> 0 | Z11: ='BLK T WESTERN ITIN'!$V$48 -> 0 | AA11: ='BLK T WESTERN ITIN'!$V$49 -> 0 | AB11: ='BLK T WESTERN ITIN'!$V$50 -> 0 | AC11: ='BLK T WESTERN ITIN'!$V$51 -> 0 | AD11: ='BLK T WESTERN ITIN'!V$52+'BLK T WESTERN ITIN'!V$53 -> 0 | AE11: =(R11+S11)-SUM(T11:AC11) -> 0
A12: 6 | B12: =VLOOKUP(A:A,'COG NA'!A:B,2,FALSE) -> GHOSRX103437OT | C12: =VLOOKUP(B:B,'COG NA'!B:C,2,FALSE) -> CRYSTAL WASHED T AT THE GATES | D12: CULTURE | E12: =VLOOKUP($A:$A,'COG NA'!$A:$G,5,FALSE) -> 0 | F12: =VLOOKUP($A:$A,'COG NA'!$A:$G,6,FALSE) -> 0 | G12: =VLOOKUP($A:$A,'COG NA'!$A:$G,7,FALSE) -> 8.71 | H12: =SUM(E12:G12) -> 8.71 | J12: ='CRYSTAL WASHED'!$C$64 -> 0 | K12: ='CRYSTAL WASHED'!$G$64 -> 0 | L12: ='CRYSTAL WASHED'!$L$64 -> 0 | M12: ='CRYSTAL WASHED'!$S$64 -> 0 | N12: ='CRYSTAL WASHED'!$M$64 -> 0 | R12: ='CRYSTAL WASHED'!$V$39 -> 0 | S12: ='CRYSTAL WASHED'!$V$40 -> 0 | T12: ='CRYSTAL WASHED'!$V$41 -> 0 | U12: ='CRYSTAL WASHED'!$V$44 -> 0 | V12: ='CRYSTAL WASHED'!$V$42 -> 0 | W12: ='CRYSTAL WASHED'!$V$43 -> 0 | X12: ='CRYSTAL WASHED'!$V$46 -> 0 | Y12: ='CRYSTAL WASHED'!$V$47 -> 0 | Z12: ='CRYSTAL WASHED'!$V$48 -> 0 | AA12: ='CRYSTAL WASHED'!$V$49 -> 0 | AB12: ='CRYSTAL WASHED'!$V$50 -> 0 | AC12: ='CRYSTAL WASHED'!$V$51 -> 0 | AD12: ='CRYSTAL WASHED'!V$52+'CRYSTAL WASHED'!V$53 -> 0 | AE12: =(R12+S12)-SUM(T12:AC12) -> 0
A13: 7 | B13: =VLOOKUP(A:A,'COG NA'!A:B,2,FALSE) -> GHOSRX103998BK | C13: =VLOOKUP(B:B,'COG NA'!B:C,2,FALSE) -> BLACK T PAPA COOPER | D13: GAVINA | E13: =VLOOKUP($A:$A,'COG NA'!$A:$G,5,FALSE) -> 0 | F13: =VLOOKUP($A:$A,'COG NA'!$A:$G,6,FALSE) -> 0 | G13: =VLOOKUP($A:$A,'COG NA'!$A:$G,7,FALSE) -> 0 | H13: =SUM(E13:G13) -> 0 | J13: ='BLK T PAPA COOPER'!$C$64 -> 0 | K13: ='BLK T PAPA COOPER'!$G$64 -> 0 | L13: ='BLK T PAPA COOPER'!$L$64 -> 0 | M13: ='BLK T PAPA COOPER'!$S$64 -> 0 | N13: ='BLK T PAPA COOPER'!$M$64 -> 0 | R13: ='BLK T PAPA COOPER'!$V$39 -> 0 | S13: ='BLK T PAPA COOPER'!$V$40 -> 0 | T13: ='BLK T PAPA COOPER'!$V$41 -> 0 | U13: ='BLK T PAPA COOPER'!$V$44 -> 0 | V13: ='BLK T PAPA COOPER'!$V$42 -> 0 | W13: ='BLK T PAPA COOPER'!$V$43 -> 0 | X13: ='BLK T PAPA COOPER'!$V$46 -> 0 | Y13: ='BLK T PAPA COOPER'!$V$47 -> 0 | Z13: ='BLK T PAPA COOPER'!$V$48 -> 0 | AA13: ='BLK T PAPA COOPER'!$V$49 -> 0 | AB13: ='BLK T PAPA COOPER'!$V$50 -> 0 | AC13: ='BLK T PAPA COOPER'!$V$51 -> 0 | AD13: ='BLK T PAPA COOPER'!V$52+'BLK T PAPA COOPER'!V$53 -> 0 | AE13: =(R13+S13)-SUM(T13:AC13) -> 0
A14: 8 | B14: =VLOOKUP(A:A,'COG NA'!A:B,2,FALSE) -> GHOSRX103999OT | C14: =VLOOKUP(B:B,'COG NA'!B:C,2,FALSE) -> WOMENS CROP RAGLAN CHAMBER OF CHILLS | D14: GAVINA | E14: =VLOOKUP($A:$A,'COG NA'!$A:$G,5,FALSE) -> 9.05 | F14: =VLOOKUP($A:$A,'COG NA'!$A:$G,6,FALSE) -> 1.45 | G14: =VLOOKUP($A:$A,'COG NA'!$A:$G,7,FALSE) -> 0 | H14: =SUM(E14:G14) -> 10.5 | J14: ='WOMENS RAGLAN'!$C$64 -> 0 | K14: ='WOMENS RAGLAN'!$G$64 -> 0 | L14: ='WOMENS RAGLAN'!$L$64 -> 0 | M14: ='WOMENS RAGLAN'!$S$64 -> 0 | N14: ='WOMENS RAGLAN'!$M$64 -> 0 | R14: ='WOMENS RAGLAN'!$V$39 -> 0 | S14: ='WOMENS RAGLAN'!$V$40 -> 0 | T14: ='WOMENS RAGLAN'!$V$41 -> 0 | U14: ='WOMENS RAGLAN'!$V$44 -> 0 | V14: ='WOMENS RAGLAN'!$V$42 -> 0 | W14: ='WOMENS RAGLAN'!$V$43 -> 0 | X14: ='WOMENS RAGLAN'!$V$46 -> 0 | Y14: ='WOMENS RAGLAN'!$V$47 -> 0 | Z14: ='WOMENS RAGLAN'!$V$48 -> 0 | AA14: ='WOMENS RAGLAN'!$V$49 -> 0 | AB14: ='WOMENS RAGLAN'!$V$50 -> 0 | AC14: ='WOMENS RAGLAN'!$V$51 -> 0 | AD14: ='WOMENS RAGLAN'!V$52+'WOMENS RAGLAN'!V$53 -> 0 | AE14: =(R14+S14)-SUM(T14:AC14) -> 0
A15: 9 | B15: =VLOOKUP(A:A,'COG NA'!A:B,2,FALSE) -> GHOSRX203401BK | C15: =VLOOKUP(B:B,'COG NA'!B:C,2,FALSE) -> BLACK PO HOODIE SKELETON | D15: GAVINA | E15: =VLOOKUP($A:$A,'COG NA'!$A:$G,5,FALSE) -> 8.25 | F15: =VLOOKUP($A:$A,'COG NA'!$A:$G,6,FALSE) -> 2.95 | G15: =VLOOKUP($A:$A,'COG NA'!$A:$G,7,FALSE) -> 0 | H15: =SUM(E15:G15) -> 11.2 | J15: ='BLK PO HOODIE'!$C$64 -> 0 | K15: ='BLK PO HOODIE'!$G$64 -> 0 | L15: ='BLK PO HOODIE'!$L$64 -> 0 | M15: ='BLK PO HOODIE'!$S$64 -> 0 | N15: ='BLK PO HOODIE'!$M$64 -> 0 | R15: ='BLK PO HOODIE'!$V$39 -> 0 | S15: ='BLK PO HOODIE'!$V$40 -> 0 | T15: ='BLK PO HOODIE'!$V$41 -> 0 | U15: ='BLK PO HOODIE'!$V$44 -> 0 | V15: ='BLK PO HOODIE'!$V$42 -> 0 | W15: ='BLK PO HOODIE'!$V$43 -> 0 | X15: ='BLK PO HOODIE'!$V$46 -> 0 | Y15: ='BLK PO HOODIE'!$V$47 -> 0 | Z15: ='BLK PO HOODIE'!$V$48 -> 0 | AA15: ='BLK PO HOODIE'!$V$49 -> 0 | AB15: ='BLK PO HOODIE'!$V$50 -> 0 | AC15: ='BLK PO HOODIE'!$V$51 -> 0 | AD15: ='BLK PO HOODIE'!V$52+'BLK PO HOODIE'!V$53 -> 0 | AE15: =(R15+S15)-SUM(T15:AC15) -> 0
A16: 10 | B16: =VLOOKUP(A:A,'COG NA'!A:B,2,FALSE) -> 0 | E16: =VLOOKUP($A:$A,'COG NA'!$A:$G,5,FALSE) -> 0 | F16: =VLOOKUP($A:$A,'COG NA'!$A:$G,6,FALSE) -> 0 | G16: =VLOOKUP($A:$A,'COG NA'!$A:$G,7,FALSE) -> 0 | H16: =SUM(E16:G16) -> 0 | J16: ='10'!$C$64 -> 0 | K16: ='10'!$G$64 -> 0 | L16: ='10'!$L$64 -> 0 | M16: ='10'!$S$64 -> 0 | N16: ='10'!$M$64 -> 0 | R16: ='10'!$V$39 -> 0 | S16: ='10'!$V$40 -> 0 | T16: ='10'!$V$41 -> 0 | U16: ='10'!$V$44 -> 0 | V16: ='10'!$V$42 -> 0 | W16: ='10'!$V$43 -> 0 | X16: ='10'!$V$46 -> 0 | Y16: ='10'!$V$47 -> 0 | Z16: ='10'!$V$48 -> 0 | AA16: ='10'!$V$49 -> 0 | AB16: ='10'!$V$50 -> 0 | AC16: ='10'!$V$51 -> 0 | AD16: ='10'!V$52+'10'!V$53 -> 0 | AE16: =(R16+S16)-SUM(T16:AC16) -> 0
A17: 11 | B17: =VLOOKUP(A:A,'COG NA'!A:B,2,FALSE) -> 0 | E17: =VLOOKUP($A:$A,'COG NA'!$A:$G,5,FALSE) -> 0 | F17: =VLOOKUP($A:$A,'COG NA'!$A:$G,6,FALSE) -> 0 | G17: =VLOOKUP($A:$A,'COG NA'!$A:$G,7,FALSE) -> 0 | H17: =SUM(E17:G17) -> 0 | J17: ='11'!$C$64 -> 0 | K17: ='11'!$G$64 -> 0 | L17: ='11'!$L$64 -> 0 | M17: ='11'!$S$64 -> 0 | N17: ='11'!$M$64 -> 0 | R17: ='11'!$V$39 -> 0 | S17: ='11'!$V$40 -> 0 | T17: ='11'!$V$41 -> 0 | U17: ='11'!$V$44 -> 0 | V17: ='11'!$V$42 -> 0 | W17: ='11'!$V$43 -> 0 | X17: ='11'!$V$46 -> 0 | Y17: ='11'!$V$47 -> 0 | Z17: ='11'!$V$48 -> 0 | AA17: ='11'!$V$49 -> 0 | AB17: ='11'!$V$50 -> 0 | AC17: ='11'!$V$51 -> 0 | AD17: ='11'!V$52+'11'!V$53 -> 0 | AE17: =(R17+S17)-SUM(T17:AC17) -> 0
A18: 12 | B18: =VLOOKUP(A:A,'COG NA'!A:B,2,FALSE) -> 0 | E18: =VLOOKUP($A:$A,'COG NA'!$A:$G,5,FALSE) -> 0 | F18: =VLOOKUP($A:$A,'COG NA'!$A:$G,6,FALSE) -> 0 | G18: =VLOOKUP($A:$A,'COG NA'!$A:$G,7,FALSE) -> 0 | H18: =SUM(E18:G18) -> 0 | J18: ='12'!$C$64 -> 0 | K18: ='12'!$G$64 -> 0 | L18: ='12'!$L$64 -> 0 | M18: ='12'!$S$64 -> 0 | N18: ='12'!$M$64 -> 0 | R18: ='12'!$V$39 -> 0 | S18: ='12'!$V$40 -> 0 | T18: ='12'!$V$41 -> 0 | U18: ='12'!$V$44 -> 0 | V18: ='12'!$V$42 -> 0 | W18: ='12'!$V$43 -> 0 | X18: ='12'!$V$46 -> 0 | Y18: ='12'!$V$47 -> 0 | Z18: ='12'!$V$48 -> 0 | AA18: ='12'!$V$49 -> 0 | AB18: ='12'!$V$50 -> 0 | AC18: ='12'!$V$51 -> 0 | AD18: ='12'!V$52+'12'!V$53 -> 0 | AE18: =(R18+S18)-SUM(T18:AC18) -> 0
A19: 13 | B19: =VLOOKUP(A:A,'COG NA'!A:B,2,FALSE) -> 0 | E19: =VLOOKUP($A:$A,'COG NA'!$A:$G,5,FALSE) -> 0 | F19: =VLOOKUP($A:$A,'COG NA'!$A:$G,6,FALSE) -> 0 | G19: =VLOOKUP($A:$A,'COG NA'!$A:$G,7,FALSE) -> 0 | H19: =SUM(E19:G19) -> 0 | J19: ='13'!$C$64 -> 0 | K19: ='13'!$G$64 -> 0 | L19: ='13'!$L$64 -> 0 | M19: ='13'!$S$64 -> 0 | N19: ='13'!$M$64 -> 0 | R19: ='13'!$V$39 -> 0 | S19: ='13'!$V$40 -> 0 | T19: ='13'!$V$41 -> 0 | U19: ='13'!$V$44 -> 0 | V19: ='13'!$V$42 -> 0 | W19: ='13'!$V$43 -> 0 | X19: ='13'!$V$46 -> 0 | Y19: ='13'!$V$47 -> 0 | Z19: ='13'!$V$48 -> 0 | AA19: ='13'!$V$49 -> 0 | AB19: ='13'!$V$50 -> 0 | AC19: ='13'!$V$51 -> 0 | AD19: ='13'!V$52+'13'!V$53 -> 0 | AE19: =(R19+S19)-SUM(T19:AC19) -> 0
A20: 14 | B20: =VLOOKUP(A:A,'COG NA'!A:B,2,FALSE) -> 0 | E20: =VLOOKUP($A:$A,'COG NA'!$A:$G,5,FALSE) -> 0 | F20: =VLOOKUP($A:$A,'COG NA'!$A:$G,6,FALSE) -> 0 | G20: =VLOOKUP($A:$A,'COG NA'!$A:$G,7,FALSE) -> 0 | H20: =SUM(E20:G20) -> 0 | J20: ='14'!$C$64 -> 0 | K20: ='14'!$G$64 -> 0 | L20: ='14'!$L$64 -> 0 | M20: ='14'!$S$64 -> 0 | N20: ='14'!$M$64 -> 0 | R20: ='14'!$V$39 -> 0 | S20: ='14'!$V$40 -> 0 | T20: ='14'!$V$41 -> 0 | U20: ='14'!$V$44 -> 0 | V20: ='14'!$V$42 -> 0 | W20: ='14'!$V$43 -> 0 | X20: ='14'!$V$46 -> 0 | Y20: ='14'!$V$47 -> 0 | Z20: ='14'!$V$48 -> 0 | AA20: ='14'!$V$49 -> 0 | AB20: ='14'!$V$50 -> 0 | AC20: ='14'!$V$51 -> 0 | AD20: ='14'!V$52+'14'!V$53 -> 0 | AE20: =(R20+S20)-SUM(T20:AC20) -> 0
A21: 15 | B21: =VLOOKUP(A:A,'COG NA'!A:B,2,FALSE) -> 0 | E21: =VLOOKUP($A:$A,'COG NA'!$A:$G,5,FALSE) -> 0 | F21: =VLOOKUP($A:$A,'COG NA'!$A:$G,6,FALSE) -> 0 | G21: =VLOOKUP($A:$A,'COG NA'!$A:$G,7,FALSE) -> 0 | H21: =SUM(E21:G21) -> 0 | J21: ='15'!$C$64 -> 0 | K21: ='15'!$G$64 -> 0 | L21: ='15'!$L$64 -> 0 | M21: ='15'!$S$64 -> 0 | N21: ='15'!$M$64 -> 0 | R21: ='15'!$V$39 -> 0 | S21: ='15'!$V$40 -> 0 | T21: ='15'!$V$41 -> 0 | U21: ='15'!$V$44 -> 0 | V21: ='15'!$V$42 -> 0 | W21: ='15'!$V$43 -> 0 | X21: ='15'!$V$46 -> 0 | Y21: ='15'!$V$47 -> 0 | Z21: ='15'!$V$48 -> 0 | AA21: ='15'!$V$49 -> 0 | AB21: ='15'!$V$50 -> 0 | AC21: ='15'!$V$51 -> 0 | AD21: ='15'!V$52+'15'!V$53 -> 0 | AE21: =(R21+S21)-SUM(T21:AC21) -> 0
A22: 16 | B22: =VLOOKUP(A:A,'COG NA'!A:B,2,FALSE) -> 0 | E22: =VLOOKUP($A:$A,'COG NA'!$A:$G,5,FALSE) -> 0 | F22: =VLOOKUP($A:$A,'COG NA'!$A:$G,6,FALSE) -> 0 | G22: =VLOOKUP($A:$A,'COG NA'!$A:$G,7,FALSE) -> 0 | H22: =SUM(E22:G22) -> 0 | J22: ='16'!$C$64 -> 0 | K22: ='16'!$G$64 -> 0 | L22: ='16'!$L$64 -> 0 | M22: ='16'!$S$64 -> 0 | N22: ='16'!$M$64 -> 0 | R22: ='16'!$V$39 -> 0 | S22: ='16'!$V$40 -> 0 | T22: ='16'!$V$41 -> 0 | U22: ='16'!$V$44 -> 0 | V22: ='16'!$V$42 -> 0 | W22: ='16'!$V$43 -> 0 | X22: ='16'!$V$46 -> 0 | Y22: ='16'!$V$47 -> 0 | Z22: ='16'!$V$48 -> 0 | AA22: ='16'!$V$49 -> 0 | AB22: ='16'!$V$50 -> 0 | AC22: ='16'!$V$51 -> 0 | AD22: ='16'!V$52+'16'!V$53 -> 0 | AE22: =(R22+S22)-SUM(T22:AC22) -> 0
A23: 17 | B23: =VLOOKUP(A:A,'COG NA'!A:B,2,FALSE) -> 0 | E23: =VLOOKUP($A:$A,'COG NA'!$A:$G,5,FALSE) -> 0 | F23: =VLOOKUP($A:$A,'COG NA'!$A:$G,6,FALSE) -> 0 | G23: =VLOOKUP($A:$A,'COG NA'!$A:$G,7,FALSE) -> 0 | H23: =SUM(E23:G23) -> 0 | J23: ='17'!$C$64 -> 0 | K23: ='17'!$G$64 -> 0 | L23: ='17'!$L$64 -> 0 | M23: ='17'!$S$64 -> 0 | N23: ='17'!$M$64 -> 0 | R23: ='17'!$V$39 -> 0 | S23: ='17'!$V$40 -> 0 | T23: ='17'!$V$41 -> 0 | U23: ='17'!$V$44 -> 0 | V23: ='17'!$V$42 -> 0 | W23: ='17'!$V$43 -> 0 | X23: ='17'!$V$46 -> 0 | Y23: ='17'!$V$47 -> 0 | Z23: ='17'!$V$48 -> 0 | AA23: ='17'!$V$49 -> 0 | AB23: ='17'!$V$50 -> 0 | AC23: ='17'!$V$51 -> 0 | AD23: ='17'!V$52+'17'!V$53 -> 0 | AE23: =(R23+S23)-SUM(T23:AC23) -> 0
A24: 18 | B24: =VLOOKUP(A:A,'COG NA'!A:B,2,FALSE) -> 0 | E24: =VLOOKUP($A:$A,'COG NA'!$A:$G,5,FALSE) -> 0 | F24: =VLOOKUP($A:$A,'COG NA'!$A:$G,6,FALSE) -> 0 | G24: =VLOOKUP($A:$A,'COG NA'!$A:$G,7,FALSE) -> 0 | H24: =SUM(E24:G24) -> 0 | J24: ='18'!$C$64 -> 0 | K24: ='18'!$G$64 -> 0 | L24: ='18'!$L$64 -> 0 | M24: ='18'!$S$64 -> 0 | N24: ='18'!$M$64 -> 0 | R24: ='18'!$V$39 -> 0 | S24: ='18'!$V$40 -> 0 | T24: ='18'!$V$41 -> 0 | U24: ='18'!$V$44 -> 0 | V24: ='18'!$V$42 -> 0 | W24: ='18'!$V$43 -> 0 | X24: ='18'!$V$46 -> 0 | Y24: ='18'!$V$47 -> 0 | Z24: ='18'!$V$48 -> 0 | AA24: ='18'!$V$49 -> 0 | AB24: ='18'!$V$50 -> 0 | AC24: ='18'!$V$51 -> 0 | AD24: ='18'!V$52+'18'!V$53 -> 0 | AE24: =(R24+S24)-SUM(T24:AC24) -> 0
A25: 19 | B25: =VLOOKUP(A:A,'COG NA'!A:B,2,FALSE) -> 0 | E25: =VLOOKUP($A:$A,'COG NA'!$A:$G,5,FALSE) -> 0 | F25: =VLOOKUP($A:$A,'COG NA'!$A:$G,6,FALSE) -> 0 | G25: =VLOOKUP($A:$A,'COG NA'!$A:$G,7,FALSE) -> 0 | H25: =SUM(E25:G25) -> 0 | J25: ='19'!$C$64 -> 0 | K25: ='19'!$G$64 -> 0 | L25: ='19'!$L$64 -> 0 | M25: ='19'!$S$64 -> 0 | N25: ='19'!$M$64 -> 0 | R25: ='19'!$V$39 -> 0 | S25: ='19'!$V$40 -> 0 | T25: ='19'!$V$41 -> 0 | U25: ='19'!$V$44 -> 0 | V25: ='19'!$V$42 -> 0 | W25: ='19'!$V$43 -> 0 | X25: ='19'!$V$46 -> 0 | Y25: ='19'!$V$47 -> 0 | Z25: ='19'!$V$48 -> 0 | AA25: ='19'!$V$49 -> 0 | AB25: ='19'!$V$50 -> 0 | AC25: ='19'!$V$51 -> 0 | AD25: ='19'!V$52+'19'!V$53 -> 0 | AE25: =(R25+S25)-SUM(T25:AC25) -> 0
A26: 20 | B26: =VLOOKUP(A:A,'COG NA'!A:B,2,FALSE) -> 0 | E26: =VLOOKUP($A:$A,'COG NA'!$A:$G,5,FALSE) -> 0 | F26: =VLOOKUP($A:$A,'COG NA'!$A:$G,6,FALSE) -> 0 | G26: =VLOOKUP($A:$A,'COG NA'!$A:$G,7,FALSE) -> 0 | H26: =SUM(E26:G26) -> 0 | J26: ='20'!$C$64 -> 0 | K26: ='20'!$G$64 -> 0 | L26: ='20'!$L$64 -> 0 | M26: ='20'!$S$64 -> 0 | N26: ='20'!$M$64 -> 0 | R26: ='20'!$V$39 -> 0 | S26: ='20'!$V$40 -> 0 | T26: ='20'!$V$41 -> 0 | U26: ='20'!$V$44 -> 0 | V26: ='20'!$V$42 -> 0 | W26: ='20'!$V$43 -> 0 | X26: ='20'!$V$46 -> 0 | Y26: ='20'!$V$47 -> 0 | Z26: ='20'!$V$48 -> 0 | AA26: ='20'!$V$49 -> 0 | AB26: ='20'!$V$50 -> 0 | AC26: ='20'!$V$51 -> 0 | AD26: ='20'!V$52+'20'!V$53 -> 0 | AE26: =(R26+S26)-SUM(T26:AC26) -> 0
A27: 21 | B27: =VLOOKUP(A:A,'COG NA'!A:B,2,FALSE) -> 0 | E27: =VLOOKUP($A:$A,'COG NA'!$A:$G,5,FALSE) -> 0 | F27: =VLOOKUP($A:$A,'COG NA'!$A:$G,6,FALSE) -> 0 | G27: =VLOOKUP($A:$A,'COG NA'!$A:$G,7,FALSE) -> 0 | H27: =SUM(E27:G27) -> 0 | J27: ='21'!$C$64 -> 0 | K27: ='21'!$G$64 -> 0 | L27: ='21'!$L$64 -> 0 | M27: ='21'!$S$64 -> 0 | N27: ='21'!$M$64 -> 0 | R27: ='21'!$V$39 -> 0 | S27: ='21'!$V$40 -> 0 | T27: ='21'!$V$41 -> 0 | U27: ='21'!$V$44 -> 0 | V27: ='21'!$V$42 -> 0 | W27: ='21'!$V$43 -> 0 | X27: ='21'!$V$46 -> 0 | Y27: ='21'!$V$47 -> 0 | Z27: ='21'!$V$48 -> 0 | AA27: ='21'!$V$49 -> 0 | AB27: ='21'!$V$50 -> 0 | AC27: ='21'!$V$51 -> 0 | AD27: ='21'!V$52+'21'!V$53 -> 0 | AE27: =(R27+S27)-SUM(T27:AC27) -> 0
A28: 22 | B28: =VLOOKUP(A:A,'COG NA'!A:B,2,FALSE) -> 0 | E28: =VLOOKUP($A:$A,'COG NA'!$A:$G,5,FALSE) -> 0 | F28: =VLOOKUP($A:$A,'COG NA'!$A:$G,6,FALSE) -> 0 | G28: =VLOOKUP($A:$A,'COG NA'!$A:$G,7,FALSE) -> 0 | H28: =SUM(E28:G28) -> 0 | J28: ='22'!$C$64 -> 0 | K28: ='22'!$G$64 -> 0 | L28: ='22'!$L$64 -> 0 | M28: ='22'!$S$64 -> 0 | N28: ='22'!$M$64 -> 0 | R28: ='22'!$V$39 -> 0 | S28: ='22'!$V$40 -> 0 | T28: ='22'!$V$41 -> 0 | U28: ='22'!$V$44 -> 0 | V28: ='22'!$V$42 -> 0 | W28: ='22'!$V$43 -> 0 | X28: ='22'!$V$46 -> 0 | Y28: ='22'!$V$47 -> 0 | Z28: ='22'!$V$48 -> 0 | AA28: ='22'!$V$49 -> 0 | AB28: ='22'!$V$50 -> 0 | AC28: ='22'!$V$51 -> 0 | AD28: ='22'!V$52+'22'!V$53 -> 0 | AE28: =(R28+S28)-SUM(T28:AC28) -> 0
A29: 23 | B29: =VLOOKUP(A:A,'COG NA'!A:B,2,FALSE) -> 0 | E29: =VLOOKUP($A:$A,'COG NA'!$A:$G,5,FALSE) -> 0 | F29: =VLOOKUP($A:$A,'COG NA'!$A:$G,6,FALSE) -> 0 | G29: =VLOOKUP($A:$A,'COG NA'!$A:$G,7,FALSE) -> 0 | H29: =SUM(E29:G29) -> 0 | J29: ='23'!$C$64 -> 0 | K29: ='23'!$G$64 -> 0 | L29: ='23'!$L$64 -> 0 | M29: ='23'!$S$64 -> 0 | N29: ='23'!$M$64 -> 0 | R29: ='23'!$V$39 -> 0 | S29: ='23'!$V$40 -> 0 | T29: ='23'!$V$41 -> 0 | U29: ='23'!$V$44 -> 0 | V29: ='23'!$V$42 -> 0 | W29: ='23'!$V$43 -> 0 | X29: ='23'!$V$46 -> 0 | Y29: ='23'!$V$47 -> 0 | Z29: ='23'!$V$48 -> 0 | AA29: ='23'!$V$49 -> 0 | AB29: ='23'!$V$50 -> 0 | AC29: ='23'!$V$51 -> 0 | AD29: ='23'!V$52+'23'!V$53 -> 0 | AE29: =(R29+S29)-SUM(T29:AC29) -> 0
A30: 24 | B30: =VLOOKUP(A:A,'COG NA'!A:B,2,FALSE) -> 0 | E30: =VLOOKUP($A:$A,'COG NA'!$A:$G,5,FALSE) -> 0 | F30: =VLOOKUP($A:$A,'COG NA'!$A:$G,6,FALSE) -> 0 | G30: =VLOOKUP($A:$A,'COG NA'!$A:$G,7,FALSE) -> 0 | H30: =SUM(E30:G30) -> 0 | J30: ='24'!$C$64 -> 0 | K30: ='24'!$G$64 -> 0 | L30: ='24'!$L$64 -> 0 | M30: ='24'!$S$64 -> 0 | N30: ='24'!$M$64 -> 0 | R30: ='24'!$V$39 -> 0 | S30: ='24'!$V$40 -> 0 | T30: ='24'!$V$41 -> 0 | U30: ='24'!$V$44 -> 0 | V30: ='24'!$V$42 -> 0 | W30: ='24'!$V$43 -> 0 | X30: ='24'!$V$46 -> 0 | Y30: ='24'!$V$47 -> 0 | Z30: ='24'!$V$48 -> 0 | AA30: ='24'!$V$49 -> 0 | AB30: ='24'!$V$50 -> 0 | AC30: ='24'!$V$51 -> 0 | AD30: ='24'!V$52+'24'!V$53 -> 0 | AE30: =(R30+S30)-SUM(T30:AC30) -> 0
A31: 25 | B31: =VLOOKUP(A:A,'COG NA'!A:B,2,FALSE) -> 0 | E31: =VLOOKUP($A:$A,'COG NA'!$A:$G,5,FALSE) -> 0 | F31: =VLOOKUP($A:$A,'COG NA'!$A:$G,6,FALSE) -> 0 | G31: =VLOOKUP($A:$A,'COG NA'!$A:$G,7,FALSE) -> 0 | H31: =SUM(E31:G31) -> 0 | J31: ='25'!$C$64 -> 0 | K31: ='25'!$G$64 -> 0 | L31: ='25'!$L$64 -> 0 | M31: ='25'!$S$64 -> 0 | N31: ='25'!$M$64 -> 0 | R31: ='25'!$V$39 -> 0 | S31: ='25'!$V$40 -> 0 | T31: ='25'!$V$41 -> 0 | U31: ='25'!$V$44 -> 0 | V31: ='25'!$V$42 -> 0 | W31: ='25'!$V$43 -> 0 | X31: ='25'!$V$46 -> 0 | Y31: ='25'!$V$47 -> 0 | Z31: ='25'!$V$48 -> 0 | AA31: ='25'!$V$49 -> 0 | AB31: ='25'!$V$50 -> 0 | AC31: ='25'!$V$51 -> 0 | AD31: ='25'!V$52+'25'!V$53 -> 0 | AE31: =(R31+S31)-SUM(T31:AC31) -> 0
A32: 26 | B32: =VLOOKUP(A:A,'COG NA'!A:B,2,FALSE) -> 0 | E32: =VLOOKUP($A:$A,'COG NA'!$A:$G,5,FALSE) -> 0 | F32: =VLOOKUP($A:$A,'COG NA'!$A:$G,6,FALSE) -> 0 | G32: =VLOOKUP($A:$A,'COG NA'!$A:$G,7,FALSE) -> 0 | H32: =SUM(E32:G32) -> 0 | J32: ='26'!$C$64 -> 0 | K32: ='26'!$G$64 -> 0 | L32: ='26'!$L$64 -> 0 | M32: ='26'!$S$64 -> 0 | N32: ='26'!$M$64 -> 0 | R32: ='26'!$V$39 -> 0 | S32: ='26'!$V$40 -> 0 | T32: ='26'!$V$41 -> 0 | U32: ='26'!$V$44 -> 0 | V32: ='26'!$V$42 -> 0 | W32: ='26'!$V$43 -> 0 | X32: ='26'!$V$46 -> 0 | Y32: ='26'!$V$47 -> 0 | Z32: ='26'!$V$48 -> 0 | AA32: ='26'!$V$49 -> 0 | AB32: ='26'!$V$50 -> 0 | AC32: ='26'!$V$51 -> 0 | AD32: ='26'!V$52+'26'!V$53 -> 0 | AE32: =(R32+S32)-SUM(T32:AC32) -> 0
A33: 27 | B33: =VLOOKUP(A:A,'COG NA'!A:B,2,FALSE) -> 0 | E33: =VLOOKUP($A:$A,'COG NA'!$A:$G,5,FALSE) -> 0 | F33: =VLOOKUP($A:$A,'COG NA'!$A:$G,6,FALSE) -> 0 | G33: =VLOOKUP($A:$A,'COG NA'!$A:$G,7,FALSE) -> 0 | H33: =SUM(E33:G33) -> 0 | J33: ='27'!$C$64 -> 0 | K33: ='27'!$G$64 -> 0 | L33: ='27'!$L$64 -> 0 | M33: ='27'!$S$64 -> 0 | N33: ='27'!$M$64 -> 0 | R33: ='27'!$V$39 -> 0 | S33: ='27'!$V$40 -> 0 | T33: ='27'!$V$41 -> 0 | U33: ='27'!$V$44 -> 0 | V33: ='27'!$V$42 -> 0 | W33: ='27'!$V$43 -> 0 | X33: ='27'!$V$46 -> 0 | Y33: ='27'!$V$47 -> 0 | Z33: ='27'!$V$48 -> 0 | AA33: ='27'!$V$49 -> 0 | AB33: ='27'!$V$50 -> 0 | AC33: ='27'!$V$51 -> 0 | AD33: ='27'!V$52+'27'!V$53 -> 0 | AE33: =(R33+S33)-SUM(T33:AC33) -> 0
A34: 28 | B34: =VLOOKUP(A:A,'COG NA'!A:B,2,FALSE) -> 0 | E34: =VLOOKUP($A:$A,'COG NA'!$A:$G,5,FALSE) -> 0 | F34: =VLOOKUP($A:$A,'COG NA'!$A:$G,6,FALSE) -> 0 | G34: =VLOOKUP($A:$A,'COG NA'!$A:$G,7,FALSE) -> 0 | H34: =SUM(E34:G34) -> 0 | J34: ='28'!$C$64 -> 0 | K34: ='28'!$G$64 -> 0 | L34: ='28'!$L$64 -> 0 | M34: ='28'!$S$64 -> 0 | N34: ='28'!$M$64 -> 0 | R34: ='28'!$V$39 -> 0 | S34: ='28'!$V$40 -> 0 | T34: ='28'!$V$41 -> 0 | U34: ='28'!$V$44 -> 0 | V34: ='28'!$V$42 -> 0 | W34: ='28'!$V$43 -> 0 | X34: ='28'!$V$46 -> 0 | Y34: ='28'!$V$47 -> 0 | Z34: ='28'!$V$48 -> 0 | AA34: ='28'!$V$49 -> 0 | AB34: ='28'!$V$50 -> 0 | AC34: ='28'!$V$51 -> 0 | AD34: ='28'!V$52+'28'!V$53 -> 0 | AE34: =(R34+S34)-SUM(T34:AC34) -> 0
A35: 29 | B35: =VLOOKUP(A:A,'COG NA'!A:B,2,FALSE) -> 0 | E35: =VLOOKUP($A:$A,'COG NA'!$A:$G,5,FALSE) -> 0 | F35: =VLOOKUP($A:$A,'COG NA'!$A:$G,6,FALSE) -> 0 | G35: =VLOOKUP($A:$A,'COG NA'!$A:$G,7,FALSE) -> 0 | H35: =SUM(E35:G35) -> 0 | J35: ='29'!$C$64 -> 0 | K35: ='29'!$G$64 -> 0 | L35: ='29'!$L$64 -> 0 | M35: ='29'!$S$64 -> 0 | N35: ='29'!$M$64 -> 0 | R35: ='29'!$V$39 -> 0 | S35: ='29'!$V$40 -> 0 | T35: ='29'!$V$41 -> 0 | U35: ='29'!$V$44 -> 0 | V35: ='29'!$V$42 -> 0 | W35: ='29'!$V$43 -> 0 | X35: ='29'!$V$46 -> 0 | Y35: ='29'!$V$47 -> 0 | Z35: ='29'!$V$48 -> 0 | AA35: ='29'!$V$49 -> 0 | AB35: ='29'!$V$50 -> 0 | AC35: ='29'!$V$51 -> 0 | AD35: ='29'!V$52+'29'!V$53 -> 0 | AE35: =(R35+S35)-SUM(T35:AC35) -> 0
A36: 30 | B36: =VLOOKUP(A:A,'COG NA'!A:B,2,FALSE) -> 0 | E36: =VLOOKUP($A:$A,'COG NA'!$A:$G,5,FALSE) -> 0 | F36: =VLOOKUP($A:$A,'COG NA'!$A:$G,6,FALSE) -> 0 | G36: =VLOOKUP($A:$A,'COG NA'!$A:$G,7,FALSE) -> 0 | H36: =SUM(E36:G36) -> 0 | J36: ='30'!$C$64 -> 0 | K36: ='30'!$G$64 -> 0 | L36: ='30'!$L$64 -> 0 | M36: ='30'!$S$64 -> 0 | N36: ='30'!$M$64 -> 0 | R36: ='30'!$V$39 -> 0 | S36: ='30'!$V$40 -> 0 | T36: ='30'!$V$41 -> 0 | U36: ='30'!$V$44 -> 0 | V36: ='30'!$V$42 -> 0 | W36: ='30'!$V$43 -> 0 | X36: ='30'!$V$46 -> 0 | Y36: ='30'!$V$47 -> 0 | Z36: ='30'!$V$48 -> 0 | AA36: ='30'!$V$49 -> 0 | AB36: ='30'!$V$50 -> 0 | AC36: ='30'!$V$51 -> 0 | AD36: ='30'!V$52+'30'!V$53 -> 0 | AE36: =(R36+S36)-SUM(T36:AC36) -> 0
A37: 31 | B37: =VLOOKUP(A:A,'COG NA'!A:B,2,FALSE) -> 0 | E37: =VLOOKUP($A:$A,'COG NA'!$A:$G,5,FALSE) -> 0 | F37: =VLOOKUP($A:$A,'COG NA'!$A:$G,6,FALSE) -> 0 | G37: =VLOOKUP($A:$A,'COG NA'!$A:$G,7,FALSE) -> 0 | H37: =SUM(E37:G37) -> 0 | J37: ='31'!$C$64 -> 0 | K37: ='31'!$G$64 -> 0 | L37: ='31'!$L$64 -> 0 | M37: ='31'!$S$64 -> 0 | N37: ='31'!$M$64 -> 0 | R37: ='31'!$V$39 -> 0 | S37: ='31'!$V$40 -> 0 | T37: ='31'!$V$41 -> 0 | U37: ='31'!$V$44 -> 0 | V37: ='31'!$V$42 -> 0 | W37: ='31'!$V$43 -> 0 | X37: ='31'!$V$46 -> 0 | Y37: ='31'!$V$47 -> 0 | Z37: ='31'!$V$48 -> 0 | AA37: ='31'!$V$49 -> 0 | AB37: ='31'!$V$50 -> 0 | AC37: ='31'!$V$51 -> 0 | AD37: ='31'!V$52+'31'!V$53 -> 0 | AE37: =(R37+S37)-SUM(T37:AC37) -> 0
A38: 32 | B38: =VLOOKUP(A:A,'COG NA'!A:B,2,FALSE) -> 0 | E38: =VLOOKUP($A:$A,'COG NA'!$A:$G,5,FALSE) -> 0 | F38: =VLOOKUP($A:$A,'COG NA'!$A:$G,6,FALSE) -> 0 | G38: =VLOOKUP($A:$A,'COG NA'!$A:$G,7,FALSE) -> 0 | H38: =SUM(E38:G38) -> 0 | J38: ='32'!$C$64 -> 0 | K38: ='32'!$G$64 -> 0 | L38: ='32'!$L$64 -> 0 | M38: ='32'!$S$64 -> 0 | N38: ='32'!$M$64 -> 0 | R38: ='32'!$V$39 -> 0 | S38: ='32'!$V$40 -> 0 | T38: ='32'!$V$41 -> 0 | U38: ='32'!$V$44 -> 0 | V38: ='32'!$V$42 -> 0 | W38: ='32'!$V$43 -> 0 | X38: ='32'!$V$46 -> 0 | Y38: ='32'!$V$47 -> 0 | Z38: ='32'!$V$48 -> 0 | AA38: ='32'!$V$49 -> 0 | AB38: ='32'!$V$50 -> 0 | AC38: ='32'!$V$51 -> 0 | AD38: ='32'!V$52+'32'!V$53 -> 0 | AE38: =(R38+S38)-SUM(T38:AC38) -> 0
A39: 33 | B39: =VLOOKUP(A:A,'COG NA'!A:B,2,FALSE) -> 0 | E39: =VLOOKUP($A:$A,'COG NA'!$A:$G,5,FALSE) -> 0 | F39: =VLOOKUP($A:$A,'COG NA'!$A:$G,6,FALSE) -> 0 | G39: =VLOOKUP($A:$A,'COG NA'!$A:$G,7,FALSE) -> 0 | H39: =SUM(E39:G39) -> 0 | J39: ='33'!$C$64 -> 0 | K39: ='33'!$G$64 -> 0 | L39: ='33'!$L$64 -> 0 | M39: ='33'!$S$64 -> 0 | N39: ='33'!$M$64 -> 0 | R39: ='33'!$V$39 -> 0 | S39: ='33'!$V$40 -> 0 | T39: ='33'!$V$41 -> 0 | U39: ='33'!$V$44 -> 0 | V39: ='33'!$V$42 -> 0 | W39: ='33'!$V$43 -> 0 | X39: ='33'!$V$46 -> 0 | Y39: ='33'!$V$47 -> 0 | Z39: ='33'!$V$48 -> 0 | AA39: ='33'!$V$49 -> 0 | AB39: ='33'!$V$50 -> 0 | AC39: ='33'!$V$51 -> 0 | AD39: ='33'!V$52+'33'!V$53 -> 0 | AE39: =(R39+S39)-SUM(T39:AC39) -> 0
A40: 34 | B40: =VLOOKUP(A:A,'COG NA'!A:B,2,FALSE) -> 0 | E40: =VLOOKUP($A:$A,'COG NA'!$A:$G,5,FALSE) -> 0 | F40: =VLOOKUP($A:$A,'COG NA'!$A:$G,6,FALSE) -> 0 | G40: =VLOOKUP($A:$A,'COG NA'!$A:$G,7,FALSE) -> 0 | H40: =SUM(E40:G40) -> 0 | J40: ='34'!$C$64 -> 0 | K40: ='34'!$G$64 -> 0 | L40: ='34'!$L$64 -> 0 | M40: ='34'!$S$64 -> 0 | N40: ='34'!$M$64 -> 0 | R40: ='34'!$V$39 -> 0 | S40: ='34'!$V$40 -> 0 | T40: ='34'!$V$41 -> 0 | U40: ='34'!$V$44 -> 0 | V40: ='34'!$V$42 -> 0 | W40: ='34'!$V$43 -> 0 | X40: ='34'!$V$46 -> 0 | Y40: ='34'!$V$47 -> 0 | Z40: ='34'!$V$48 -> 0 | AA40: ='34'!$V$49 -> 0 | AB40: ='34'!$V$50 -> 0 | AC40: ='34'!$V$51 -> 0 | AD40: ='34'!V$52+'34'!V$53 -> 0 | AE40: =(R40+S40)-SUM(T40:AC40) -> 0
A41: 35 | B41: =VLOOKUP(A:A,'COG NA'!A:B,2,FALSE) -> 0 | E41: =VLOOKUP($A:$A,'COG NA'!$A:$G,5,FALSE) -> 0 | F41: =VLOOKUP($A:$A,'COG NA'!$A:$G,6,FALSE) -> 0 | G41: =VLOOKUP($A:$A,'COG NA'!$A:$G,7,FALSE) -> 0 | H41: =SUM(E41:G41) -> 0 | J41: ='35'!$C$64 -> 0 | K41: ='35'!$G$64 -> 0 | L41: ='35'!$L$64 -> 0 | M41: ='35'!$S$64 -> 0 | N41: ='35'!$M$64 -> 0 | R41: ='35'!$V$39 -> 0 | S41: ='35'!$V$40 -> 0 | T41: ='35'!$V$41 -> 0 | U41: ='35'!$V$44 -> 0 | V41: ='35'!$V$42 -> 0 | W41: ='35'!$V$43 -> 0 | X41: ='35'!$V$46 -> 0 | Y41: ='35'!$V$47 -> 0 | Z41: ='35'!$V$48 -> 0 | AA41: ='35'!$V$49 -> 0 | AB41: ='35'!$V$50 -> 0 | AC41: ='35'!$V$51 -> 0 | AD41: ='35'!V$52+'35'!V$53 -> 0 | AE41: =(R41+S41)-SUM(T41:AC41) -> 0
...

Sheet BUDGET
A1: GLOBAL MERCHANDISING SERVICES, INC
A2: TOUR BUDGET - NORTH AMERICA
A4: ARTIST | B4: =Inventory!C3 -> GHOST | I4: BRAND MANAGER
A5: TERRITORY | B5: NORTH AMERICA | I5: CURRENCY | K5: USD
A6: TOUR START/LOAD IN DATE | I6: FIRST SHOW CITY
A7: TOUR FINISH/LOUD OUT DATE | I7: LAST SHOW CITY
A8: TOUR DAYS | B8: =B7-B6 -> 0 | I8: TRANSPORT - RECOUP | K8: YES
A9: ROAD MANAGER - GMS | B9: YES | I9: SECURITY - RECOUP | K9: YES
A11: TOUR ASSUMPTIONS | B11: USA | E11: CANADA | H11: FESTIVALS | K11: TOUR TOTAL
A13: TOTAL CAPACITY | K13: =E13+B13+H13 -> 0
A14: PROJ.ATTENDANCE | B14: 1 | E14: 1 | H14: 1 | K14: =IFERROR(K15/K13,0) -> 0
A15: PROJ.ATTENDANCE | B15: =B13*B14 -> 0 | E15: =E13*E14 -> 0 | H15: =H13*H14 -> 0 | K15: =E15+B15+H15 -> 0
A16: TOUR STAFF | K16: =B16 -> 0
A17: NO.OF SHOWS | K17: =E17+B17+H17 -> 0
A18: P/HEAD | K18: =IFERROR(K20/K15,0) -> 0
A20: GROSS SALES | B20: =B18*B15 -> 0 | E20: =E18*E15 -> 0 | H20: =H18*H15 -> 0 | K20: =E20+B20+H20 -> 0
A21: CREDIT CARD % | B21: 1 | E21: 1 | H21: 1 | K21: =IFERROR(K22/K20,0) -> 0
A22: CREDT CARD AMOUNT | B22: =B20*B21 -> 0 | E22: =E20*E21 -> 0 | H22: =H20*H21 -> 0 | K22: =E22+B22+H22 -> 0
A23: TAX: | B23: =B20*C23/(1+C23) -> 0 | C23: 0.08 | E23: =E20*F23/(1+F23) -> 0 | F23: 0.13 | H23: =H20*I23/(1+I23) -> 0 | I23: 0.08 | K23: =E23+B23+H23 -> 0 | L23: =IF(K23=0,0,K23/$K$24) -> 0
A24: NET SALES | B24: =B20-B23 -> 0 | E24: =E20-E23 -> 0 | H24: =H20-H23 -> 0 | K24: =E24+B24+H24 -> 0
A27: TOUR COSTS - ON NET | B27: =B11 -> USA | E27: =E11 -> CANADA | H27: =H11 -> FESTIVALS | K27: =K11 -> TOUR TOTAL
A29: COST OF GOODS | B29: =ROUND((B$24*C29),2) -> 0 | C29: 0 | E29: =ROUND((E$24*F29),2) -> 0 | F29: 0 | H29: =ROUND((H$24*I29),2) -> 0 | I29: 0 | K29: =B29+E29+H29 -> 0 | L29: =IF(K29=0,0,K29/$K$24) -> 0
A30: COST OF GOODS - UPLIFT | B30: =ROUND(B29*C30,2) -> 0 | C30: 0 | E30: =ROUND(E29*F30,2) -> 0 | F30: 0 | H30: =ROUND(H29*I30,2) -> 0 | I30: 0 | K30: =B30+E30+H30 -> 0 | L30: =IF(K30=0,0,K30/$K$24) -> 0
A31: HALL FEES | B31: =ROUND((B$24*C31),2) -> 0 | C31: 0 | E31: =ROUND((E$24*F31),2) -> 0 | F31: 0 | H31: =ROUND((H$24*I31),2) -> 0 | I31: 0 | K31: =B31+E31+H31 -> 0 | L31: =IF(K31=0,0,K31/$K$24) -> 0
A32: VENDORS | B32: =ROUND((B$24*C32),2) -> 0 | C32: 0 | E32: =ROUND((E$24*F32),2) -> 0 | F32: 0 | H32: =ROUND((H$24*I32),2) -> 0 | I32: 0 | K32: =B32+E32+H32 -> 0 | L32: =IF(K32=0,0,K32/$K$24) -> 0
A33: CREDIT CARD FEES | B33: =ROUND(((B$24*B21)*C33),2) -> 0 | C33: 0 | E33: =ROUND(((E$24*E21)*F33),2) -> 0 | F33: 0 | H33: =ROUND(((H$24*H21)*I33),2) -> 0 | I33: 0 | K33: =B33+E33+H33 -> 0 | L33: =IF(K33=0,0,K33/$K$24) -> 0
A34: BOOTLEG SECURITY & LEGAL | B34: =IF($K$9="YES",0,ROUND((B$24*C34),2)) -> 0 | C34: 0 | E34: =IF($K$9="YES",0,ROUND((E$24*F34),2)) -> 0 | F34: 0 | H34: =IF($K$9="YES",0,ROUND((H$24*I34),2)) -> 0 | I34: 0 | K34: =B34+E34+H34 -> 0 | L34: =IF(K34=0,0,K34/$K$24) -> 0
A35: FREIGHT COST | B35: =ROUND((B$24*C35),2) -> 0 | C35: 0 | E35: =ROUND((E$24*F35),2) -> 0 | F35: 0 | H35: =ROUND((H$24*I35),2) -> 0 | I35: 0 | K35: =B35+E35+H35 -> 0 | L35: =IF(K35=0,0,K35/$K$24) -> 0
A36: DUTIES/TAXES | B36: =ROUND((B$29*C36),2) -> 0 | C36: 0 | E36: =ROUND((E$29*F36),2) -> 0 | F36: 0 | H36: =ROUND((H$29*I36),2) -> 0 | I36: 0 | K36: =B36+E36+H36 -> 0 | L36: =IF(K36=0,0,K36/$K$24) -> 0
A37: ROAD EXPENSES | B37: =IF($K$8="YES",B68-SUM(B63:B66),B68) -> 0 | C37: =IF(B37=0,0,B37/B24) -> 0 | E37: =IF($K$8="YES",E68-SUM(E63:E66),E68) -> 0 | F37: =IF(E37=0,0,E37/E24) -> 0 | H37: =IF($K$8="YES",H68-SUM(H63:H66),H68) -> 0 | I37: =IF(H37=0,0,H37/H24) -> 0 | K37: =B37+E37+H37 -> 0 | L37: =IF(K37=0,0,K37/$K$24) -> 0
A38: ADMIN FEE | B38: =ROUND((B$24*C38),2) -> 0 | C38: 0.03 | E38: =ROUND((E$24*F38),2) -> 0 | F38: 0.03 | H38: =ROUND((H$24*I38),2) -> 0 | I38: 0.03 | K38: =B38+E38+H38 -> 0 | L38: =IF(K38=0,0,K38/$K$24) -> 0
A39: TRANSPORT - RECOUPABLE | B39: =IF($K$8="YES",SUM(B63:B66),0) -> 0 | C39: =IF(B39=0,0,B39/B24) -> 0 | E39: =IF($K$8="YES",SUM(E63:E66),0) -> 0 | F39: =IF(E39=0,0,E39/E24) -> 0 | H39: =IF($K$8="YES",SUM(H63:H66),0) -> 0 | I39: =IF(H39=0,0,H39/H24) -> 0 | K39: =B39+E39+H39 -> 0 | L39: =IF(K39=0,0,K39/$K$24) -> 0
A40: SECURITY - RECOUPABLE | B40: =IF($K$9="YES",ROUND((B$24*C40),2),0) -> 0 | C40: =C34 -> 0 | E40: =IF($K$9="YES",ROUND((E$24*F40),2),0) -> 0 | F40: =F34 -> 0 | H40: =IF($K$9="YES",ROUND((H$24*I40),2),0) -> 0 | I40: =I34 -> 0 | K40: =B40+E40+H40 -> 0 | L40: =IF(K40=0,0,K40/$K$24) -> 0
A42: TOTAL TOUR COSTS | B42: =SUM(B29:B38) -> 0 | C42: =IF(B42=0,0,B42/B24) -> 0 | E42: =SUM(E29:E38) -> 0 | F42: =IF(E42=0,0,E42/E24) -> 0 | H42: =SUM(H29:H38) -> 0 | I42: =IF(H42=0,0,H42/H24) -> 0 | K42: =SUM(K29:K38) -> 0 | L42: =IF(K42=0,0,K42/K24) -> 0
A43: PROFIT | B43: =B24-B42 -> 0 | C43: =IF(B43=0,0,B43/B24) -> 0 | E43: =E24-E42 -> 0 | F43: =IF(E43=0,0,E43/E24) -> 0 | H43: =H24-H42 -> 0 | I43: =IF(H43=0,0,H43/H24) -> 0 | K43: =B43+E43+H43 -> 0 | L43: =IF(K43=0,0,K43/K24) -> 0
A44: ARTIST | B44: =B43*C44 -> 0 | C44: 0.8 | E44: =E43*F44 -> 0 | F44: 0.8 | H44: =H43*I44 -> 0 | I44: 0.8 | K44: =B44+E44+H44 -> 0 | L44: =IF(K44=0,0,K44/K43) -> 0
A45: GLOBAL | B45: =B43*C45 -> 0 | C45: =1-C44 -> 0.2 | E45: =E43*F45 -> 0 | F45: =1-F44 -> 0.2 | H45: =H43*I45 -> 0 | I45: =1-I44 -> 0.2 | K45: =B45+E45+H45 -> 0 | L45: =IF(K45=0,0,K45/K43) -> 0
A48: ROAD EXPENSES BREAKDOWN | B48: =B11 -> USA | E48: =E11 -> CANADA | H48: =H11 -> FESTIVALS | K48: =K11 -> TOUR TOTAL
A50: DAYS | B50: 0 | E50: 0 | H50: 0 | K50: =B50+E50+H50 -> 0
A51: HOTELS | B51: 0 | E51: 0 | H51: 0 | K51: =B51+E51+H51 -> 0
...

Sheet COG NA
A1: GLOBAL MERCHANDISING SERVICES, INC.
A2: 46027
A3: TOUR COST OF GOODS SCHEDULE - NORTH AMERICA in USD
A6: Brand Manager: | C6: KAYLA
A7: Enter sales tax rate: | C7: 0
A8: Enter specials rate: | C8: N/A | E8: CLOSE WHEN PDFing and SENDING TO CLIENT
A9: APPAREL | Q9: APPAREL - ADJUSTED PRICE FOR SPECIAL
A10: ITEM # | B10: SKU # | C10: DESCRIPTION | D10: SIZE | E10: BLANK | F10: PRINT | G10: FULL PACKAGE | H10: COG | I10: COG 2 | J10: TOTAL COG | K10: SUGGESTED PRICE | L10: =("TAX @ " &C7) -> TAX @ 0 | M10: AFTER TAX ADJ. GROSS | N10: PRODUCT COST % (A.T.G.) | O10: SPECIAL YES/NO | Q10: SPECIAL ITEM PRICE | R10: =L10 -> TAX @ 0 | S10: AFTER TAX ADJ. GROSS | T10: SPECIAL COST % (A.T.G.) | U10: SPECIAL YES/NO
A11: 1 | B11: GHOSNS903311BK | C11: BATWING HOODY | D11: SM-XL | E11: 0 | F11: 0 | G11: 28.5 | H11: =SUM(E11:G11) -> 28.5 | I11: 0 | J11: =SUM(H11:I11) -> 28.5 | K11: 125 | L11: =$C$7 -> 0 | M11: =K11-IF(K11<>0,K11-(K11/(1+L11)),0) -> 125 | N11: =IFERROR(J11/M11,0) -> 0.228 | O11: =IF(N11>$C$8,"YES","NO") -> NO | Q11: 0 | R11: =$C$7 -> 0 | S11: =Q11-IF(Q11<>0,Q11-(Q11/(1+R11)),0) -> 0 | T11: =IFERROR(J11/S11,0) -> 0 | U11: =IF(T11>$C$8,"YES","NO") -> NO
D12: 2XL | E12: 0 | F12: 0 | G12: 28.5 | H12: =SUM(E12:G12) -> 28.5 | I12: 0 | J12: =SUM(H12:I12) -> 28.5 | K12: 125 | L12: =$C$7 -> 0 | M12: =K12-IF(K12<>0,K12-(K12/(1+L12)),0) -> 125 | N12: =IFERROR(J12/M12,0) -> 0.228 | O12: =IF(N12>$C$8,"YES","NO") -> NO | Q12: 0 | R12: =$C$7 -> 0 | S12: =Q12-IF(Q12<>0,Q12-(Q12/(1+R12)),0) -> 0 | T12: =IFERROR(J12/S12,0) -> 0 | U12: =IF(T12>$C$8,"YES","NO") -> NO
D13: 3XL | E13: 0 | F13: 0 | G13: 28.5 | H13: =SUM(E13:G13) -> 28.5 | I13: 0 | J13: =SUM(H13:I13) -> 28.5 | K13: 125 | L13: =$C$7 -> 0 | M13: =K13-IF(K13<>0,K13-(K13/(1+L13)),0) -> 125 | N13: =IFERROR(J13/M13,0) -> 0.228 | O13: =IF(N13>$C$8,"YES","NO") -> NO | Q13: 0 | R13: =$C$7 -> 0 | S13: =Q13-IF(Q13<>0,Q13-(Q13/(1+R13)),0) -> 0 | T13: =IFERROR(J13/S13,0) -> 0 | U13: =IF(T13>$C$8,"YES","NO") -> NO
D14: 4XL | E14: 0 | F14: 0 | G14: 0 | H14: =SUM(E14:G14) -> 0 | I14: 0 | J14: =SUM(H14:I14) -> 0 | K14: 0 | L14: =$C$7 -> 0 | M14: =K14-IF(K14<>0,K14-(K14/(1+L14)),0) -> 0 | N14: =IFERROR(J14/M14,0) -> 0 | O14: =IF(N14>$C$8,"YES","NO") -> NO | Q14: 0 | R14: =$C$7 -> 0 | S14: =Q14-IF(Q14<>0,Q14-(Q14/(1+R14)),0) -> 0 | T14: =IFERROR(J14/S14,0) -> 0 | U14: =IF(T14>$C$8,"YES","NO") -> NO
A15: =A11+1 -> 2 | B15: GHOSRX203275BK | C15: SHORTS BLK/ WHT PAPA V CLAWS | D15: SM-XL | E15: 0 | F15: 0 | G15: 5.8 | H15: =SUM(E15:G15) -> 5.8 | I15: 0 | J15: =SUM(H15:I15) -> 5.8 | K15: 50 | L15: =$C$7 -> 0 | M15: =K15-IF(K15<>0,K15-(K15/(1+L15)),0) -> 50 | N15: =IFERROR(J15/M15,0) -> 0.116 | O15: =IF(N15>$C$8,"YES","NO") -> NO | Q15: 0 | R15: =$C$7 -> 0 | S15: =Q15-IF(Q15<>0,Q15-(Q15/(1+R15)),0) -> 0 | T15: =IFERROR(J15/S15,0) -> 0 | U15: =IF(T15>$C$8,"YES","NO") -> NO
D16: 2XL | E16: 0 | F16: 0 | G16: 5.8 | H16: =SUM(E16:G16) -> 5.8 | I16: 0 | J16: =SUM(H16:I16) -> 5.8 | K16: 50 | L16: =$C$7 -> 0 | M16: =K16-IF(K16<>0,K16-(K16/(1+L16)),0) -> 50 | N16: =IFERROR(J16/M16,0) -> 0.116 | O16: =IF(N16>$C$8,"YES","NO") -> NO | Q16: 0 | R16: =$C$7 -> 0 | S16: =Q16-IF(Q16<>0,Q16-(Q16/(1+R16)),0) -> 0 | T16: =IFERROR(J16/S16,0) -> 0 | U16: =IF(T16>$C$8,"YES","NO") -> NO
D17: 3XL | E17: 0 | F17: 0 | G17: 5.8 | H17: =SUM(E17:G17) -> 5.8 | I17: 0 | J17: =SUM(H17:I17) -> 5.8 | K17: 50 | L17: =$C$7 -> 0 | M17: =K17-IF(K17<>0,K17-(K17/(1+L17)),0) -> 50 | N17: =IFERROR(J17/M17,0) -> 0.116 | O17: =IF(N17>$C$8,"YES","NO") -> NO | Q17: 0 | R17: =$C$7 -> 0 | S17: =Q17-IF(Q17<>0,Q17-(Q17/(1+R17)),0) -> 0 | T17: =IFERROR(J17/S17,0) -> 0 | U17: =IF(T17>$C$8,"YES","NO") -> NO
D18: 4XL | E18: 0 | F18: 0 | G18: 0 | H18: =SUM(E18:G18) -> 0 | I18: 0 | J18: =SUM(H18:I18) -> 0 | K18: 0 | L18: =$C$7 -> 0 | M18: =K18-IF(K18<>0,K18-(K18/(1+L18)),0) -> 0 | N18: =IFERROR(J18/M18,0) -> 0 | O18: =IF(N18>$C$8,"YES","NO") -> NO | Q18: 0 | R18: =$C$7 -> 0 | S18: =Q18-IF(Q18<>0,Q18-(Q18/(1+R18)),0) -> 0 | T18: =IFERROR(J18/S18,0) -> 0 | U18: =IF(T18>$C$8,"YES","NO") -> NO
A19: =A15+1 -> 3 | B19: GHOSRX204001BK | C19: BLACK T SKELETOUR 26 ITIN | D19: SM-XL | E19: 0 | F19: 0 | G19: 5.83 | H19: =SUM(E19:G19) -> 5.83 | I19: 0 | J19: =SUM(H19:I19) -> 5.83 | K19: 50 | L19: =$C$7 -> 0 | M19: =K19-IF(K19<>0,K19-(K19/(1+L19)),0) -> 50 | N19: =IFERROR(J19/M19,0) -> 0.1166 | O19: =IF(N19>$C$8,"YES","NO") -> NO | Q19: 0 | R19: =$C$7 -> 0 | S19: =Q19-IF(Q19<>0,Q19-(Q19/(1+R19)),0) -> 0 | T19: =IFERROR(J19/S19,0) -> 0 | U19: =IF(T19>$C$8,"YES","NO") -> NO
D20: 2XL | E20: 0 | F20: 0 | G20: 8.09 | H20: =SUM(E20:G20) -> 8.09 | I20: 0 | J20: =SUM(H20:I20) -> 8.09 | K20: 50 | L20: =$C$7 -> 0 | M20: =K20-IF(K20<>0,K20-(K20/(1+L20)),0) -> 50 | N20: =IFERROR(J20/M20,0) -> 0.1618 | O20: =IF(N20>$C$8,"YES","NO") -> NO | Q20: 0 | R20: =$C$7 -> 0 | S20: =Q20-IF(Q20<>0,Q20-(Q20/(1+R20)),0) -> 0 | T20: =IFERROR(J20/S20,0) -> 0 | U20: =IF(T20>$C$8,"YES","NO") -> NO
D21: 3XL | E21: 0 | F21: 0 | G21: 9.46 | H21: =SUM(E21:G21) -> 9.46 | I21: 0 | J21: =SUM(H21:I21) -> 9.46 | K21: 50 | L21: =$C$7 -> 0 | M21: =K21-IF(K21<>0,K21-(K21/(1+L21)),0) -> 50 | N21: =IFERROR(J21/M21,0) -> 0.1892 | O21: =IF(N21>$C$8,"YES","NO") -> NO | Q21: 0 | R21: =$C$7 -> 0 | S21: =Q21-IF(Q21<>0,Q21-(Q21/(1+R21)),0) -> 0 | T21: =IFERROR(J21/S21,0) -> 0 | U21: =IF(T21>$C$8,"YES","NO") -> NO
D22: 4XL | E22: 0 | F22: 0 | G22: 0 | H22: =SUM(E22:G22) -> 0 | I22: 0 | J22: =SUM(H22:I22) -> 0 | K22: 0 | L22: =$C$7 -> 0 | M22: =K22-IF(K22<>0,K22-(K22/(1+L22)),0) -> 0 | N22: =IFERROR(J22/M22,0) -> 0 | O22: =IF(N22>$C$8,"YES","NO") -> NO | Q22: 0 | R22: =$C$7 -> 0 | S22: =Q22-IF(Q22<>0,Q22-(Q22/(1+R22)),0) -> 0 | T22: =IFERROR(J22/S22,0) -> 0 | U22: =IF(T22>$C$8,"YES","NO") -> NO
A23: =A19+1 -> 4 | B23: GHOSRX204000BK | C23: BLACK T BAT BRAIN 26 ITIN | D23: SM-XL | E23: 0 | F23: 0 | G23: 5.83 | H23: =SUM(E23:G23) -> 5.83 | I23: 0 | J23: =SUM(H23:I23) -> 5.83 | K23: 50 | L23: =$C$7 -> 0 | M23: =K23-IF(K23<>0,K23-(K23/(1+L23)),0) -> 50 | N23: =IFERROR(J23/M23,0) -> 0.1166 | O23: =IF(N23>$C$8,"YES","NO") -> NO | Q23: 0 | R23: =$C$7 -> 0 | S23: =Q23-IF(Q23<>0,Q23-(Q23/(1+R23)),0) -> 0 | T23: =IFERROR(J23/S23,0) -> 0 | U23: =IF(T23>$C$8,"YES","NO") -> NO
D24: 2XL | E24: 0 | F24: 0 | G24: 8.09 | H24: =SUM(E24:G24) -> 8.09 | I24: 0 | J24: =SUM(H24:I24) -> 8.09 | K24: 50 | L24: =$C$7 -> 0 | M24: =K24-IF(K24<>0,K24-(K24/(1+L24)),0) -> 50 | N24: =IFERROR(J24/M24,0) -> 0.1618 | O24: =IF(N24>$C$8,"YES","NO") -> NO | Q24: 0 | R24: =$C$7 -> 0 | S24: =Q24-IF(Q24<>0,Q24-(Q24/(1+R24)),0) -> 0 | T24: =IFERROR(J24/S24,0) -> 0 | U24: =IF(T24>$C$8,"YES","NO") -> NO
D25: 3XL | E25: 0 | F25: 0 | G25: 9.46 | H25: =SUM(E25:G25) -> 9.46 | I25: 0 | J25: =SUM(H25:I25) -> 9.46 | K25: 50 | L25: =$C$7 -> 0 | M25: =K25-IF(K25<>0,K25-(K25/(1+L25)),0) -> 50 | N25: =IFERROR(J25/M25,0) -> 0.1892 | O25: =IF(N25>$C$8,"YES","NO") -> NO | Q25: 0 | R25: =$C$7 -> 0 | S25: =Q25-IF(Q25<>0,Q25-(Q25/(1+R25)),0) -> 0 | T25: =IFERROR(J25/S25,0) -> 0 | U25: =IF(T25>$C$8,"YES","NO") -> NO
D26: 4XL | E26: 0 | F26: 0 | G26: 0 | H26: =SUM(E26:G26) -> 0 | I26: 0 | J26: =SUM(H26:I26) -> 0 | K26: 0 | L26: =$C$7 -> 0 | M26: =K26-IF(K26<>0,K26-(K26/(1+L26)),0) -> 0 | N26: =IFERROR(J26/M26,0) -> 0 | O26: =IF(N26>$C$8,"YES","NO") -> NO | Q26: 0 | R26: =$C$7 -> 0 | S26: =Q26-IF(Q26<>0,Q26-(Q26/(1+R26)),0) -> 0 | T26: =IFERROR(J26/S26,0) -> 0 | U26: =IF(T26>$C$8,"YES","NO") -> NO
A27: =A23+1 -> 5 | B27: GHOSRX204002BK | C27: BLACK T WESTERN EMERITUS 26 ITIN | D27: SM-XL | E27: 0 | F27: 0 | G27: 5.83 | H27: =SUM(E27:G27) -> 5.83 | I27: 0 | J27: =SUM(H27:I27) -> 5.83 | K27: 50 | L27: =$C$7 -> 0 | M27: =K27-IF(K27<>0,K27-(K27/(1+L27)),0) -> 50 | N27: =IFERROR(J27/M27,0) -> 0.1166 | O27: =IF(N27>$C$8,"YES","NO") -> NO | Q27: 0 | R27: =$C$7 -> 0 | S27: =Q27-IF(Q27<>0,Q27-(Q27/(1+R27)),0) -> 0 | T27: =IFERROR(J27/S27,0) -> 0 | U27: =IF(T27>$C$8,"YES","NO") -> NO
D28: 2XL | E28: 0 | F28: 0 | G28: 8.09 | H28: =SUM(E28:G28) -> 8.09 | I28: 0 | J28: =SUM(H28:I28) -> 8.09 | K28: 50 | L28: =$C$7 -> 0 | M28: =K28-IF(K28<>0,K28-(K28/(1+L28)),0) -> 50 | N28: =IFERROR(J28/M28,0) -> 0.1618 | O28: =IF(N28>$C$8,"YES","NO") -> NO | Q28: 0 | R28: =$C$7 -> 0 | S28: =Q28-IF(Q28<>0,Q28-(Q28/(1+R28)),0) -> 0 | T28: =IFERROR(J28/S28,0) -> 0 | U28: =IF(T28>$C$8,"YES","NO") -> NO
D29: 3XL | E29: 0 | F29: 0 | G29: 9.46 | H29: =SUM(E29:G29) -> 9.46 | I29: 0 | J29: =SUM(H29:I29) -> 9.46 | K29: 50 | L29: =$C$7 -> 0 | M29: =K29-IF(K29<>0,K29-(K29/(1+L29)),0) -> 50 | N29: =IFERROR(J29/M29,0) -> 0.1892 | O29: =IF(N29>$C$8,"YES","NO") -> NO | Q29: 0 | R29: =$C$7 -> 0 | S29: =Q29-IF(Q29<>0,Q29-(Q29/(1+R29)),0) -> 0 | T29: =IFERROR(J29/S29,0) -> 0 | U29: =IF(T29>$C$8,"YES","NO") -> NO
D30: 4XL | E30: 0 | F30: 0 | G30: 0 | H30: =SUM(E30:G30) -> 0 | I30: 0 | J30: =SUM(H30:I30) -> 0 | K30: 0 | L30: =$C$7 -> 0 | M30: =K30-IF(K30<>0,K30-(K30/(1+L30)),0) -> 0 | N30: =IFERROR(J30/M30,0) -> 0 | O30: =IF(N30>$C$8,"YES","NO") -> NO | Q30: 0 | R30: =$C$7 -> 0 | S30: =Q30-IF(Q30<>0,Q30-(Q30/(1+R30)),0) -> 0 | T30: =IFERROR(J30/S30,0) -> 0 | U30: =IF(T30>$C$8,"YES","NO") -> NO
A31: =A27+1 -> 6 | B31: GHOSRX103437OT | C31: CRYSTAL WASHED T AT THE GATES | D31: SM-XL | E31: 0 | F31: 0 | G31: 8.71 | H31: =SUM(E31:G31) -> 8.71 | I31: 0 | J31: =SUM(H31:I31) -> 8.71 | K31: 60 | L31: =$C$7 -> 0 | M31: =K31-IF(K31<>0,K31-(K31/(1+L31)),0) -> 60 | N31: =IFERROR(J31/M31,0) -> 0.14516667 | O31: =IF(N31>$C$8,"YES","NO") -> NO | Q31: 0 | R31: =$C$7 -> 0 | S31: =Q31-IF(Q31<>0,Q31-(Q31/(1+R31)),0) -> 0 | T31: =IFERROR(J31/S31,0) -> 0 | U31: =IF(T31>$C$8,"YES","NO") -> NO
D32: 2XL | E32: 0 | F32: 0 | G32: 11.27 | H32: =SUM(E32:G32) -> 11.27 | I32: 0 | J32: =SUM(H32:I32) -> 11.27 | K32: 60 | L32: =$C$7 -> 0 | M32: =K32-IF(K32<>0,K32-(K32/(1+L32)),0) -> 60 | N32: =IFERROR(J32/M32,0) -> 0.18783333 | O32: =IF(N32>$C$8,"YES","NO") -> NO | Q32: 0 | R32: =$C$7 -> 0 | S32: =Q32-IF(Q32<>0,Q32-(Q32/(1+R32)),0) -> 0 | T32: =IFERROR(J32/S32,0) -> 0 | U32: =IF(T32>$C$8,"YES","NO") -> NO
D33: 3XL | E33: 0 | F33: 0 | G33: 12.13 | H33: =SUM(E33:G33) -> 12.13 | I33: 0 | J33: =SUM(H33:I33) -> 12.13 | K33: 60 | L33: =$C$7 -> 0 | M33: =K33-IF(K33<>0,K33-(K33/(1+L33)),0) -> 60 | N33: =IFERROR(J33/M33,0) -> 0.20216667 | O33: =IF(N33>$C$8,"YES","NO") -> NO | Q33: 0 | R33: =$C$7 -> 0 | S33: =Q33-IF(Q33<>0,Q33-(Q33/(1+R33)),0) -> 0 | T33: =IFERROR(J33/S33,0) -> 0 | U33: =IF(T33>$C$8,"YES","NO") -> NO
D34: 4XL | E34: 0 | F34: 0 | G34: 0 | H34: =SUM(E34:G34) -> 0 | I34: 0 | J34: =SUM(H34:I34) -> 0 | K34: 0 | L34: =$C$7 -> 0 | M34: =K34-IF(K34<>0,K34-(K34/(1+L34)),0) -> 0 | N34: =IFERROR(J34/M34,0) -> 0 | O34: =IF(N34>$C$8,"YES","NO") -> NO | Q34: 0 | R34: =$C$7 -> 0 | S34: =Q34-IF(Q34<>0,Q34-(Q34/(1+R34)),0) -> 0 | T34: =IFERROR(J34/S34,0) -> 0 | U34: =IF(T34>$C$8,"YES","NO") -> NO
A35: =A31+1 -> 7 | B35: GHOSRX103998BK | C35: BLACK T PAPA COOPER | D35: SM-XL | E35: 0 | F35: 0 | G35: 0 | H35: =SUM(E35:G35) -> 0 | I35: 0 | J35: =SUM(H35:I35) -> 0 | K35: 50 | L35: =$C$7 -> 0 | M35: =K35-IF(K35<>0,K35-(K35/(1+L35)),0) -> 50 | N35: =IFERROR(J35/M35,0) -> 0 | O35: =IF(N35>$C$8,"YES","NO") -> NO | Q35: 0 | R35: =$C$7 -> 0 | S35: =Q35-IF(Q35<>0,Q35-(Q35/(1+R35)),0) -> 0 | T35: =IFERROR(J35/S35,0) -> 0 | U35: =IF(T35>$C$8,"YES","NO") -> NO
D36: 2XL | E36: 0 | F36: 0 | G36: 0 | H36: =SUM(E36:G36) -> 0 | I36: 0 | J36: =SUM(H36:I36) -> 0 | K36: 50 | L36: =$C$7 -> 0 | M36: =K36-IF(K36<>0,K36-(K36/(1+L36)),0) -> 50 | N36: =IFERROR(J36/M36,0) -> 0 | O36: =IF(N36>$C$8,"YES","NO") -> NO | Q36: 0 | R36: =$C$7 -> 0 | S36: =Q36-IF(Q36<>0,Q36-(Q36/(1+R36)),0) -> 0 | T36: =IFERROR(J36/S36,0) -> 0 | U36: =IF(T36>$C$8,"YES","NO") -> NO
D37: 3XL | E37: 0 | F37: 0 | G37: 0 | H37: =SUM(E37:G37) -> 0 | I37: 0 | J37: =SUM(H37:I37) -> 0 | K37: 50 | L37: =$C$7 -> 0 | M37: =K37-IF(K37<>0,K37-(K37/(1+L37)),0) -> 50 | N37: =IFERROR(J37/M37,0) -> 0 | O37: =IF(N37>$C$8,"YES","NO") -> NO | Q37: 0 | R37: =$C$7 -> 0 | S37: =Q37-IF(Q37<>0,Q37-(Q37/(1+R37)),0) -> 0 | T37: =IFERROR(J37/S37,0) -> 0 | U37: =IF(T37>$C$8,"YES","NO") -> NO
D38: 4XL | E38: 0 | F38: 0 | G38: 0 | H38: =SUM(E38:G38) -> 0 | I38: 0 | J38: =SUM(H38:I38) -> 0 | K38: 0 | L38: =$C$7 -> 0 | M38: =K38-IF(K38<>0,K38-(K38/(1+L38)),0) -> 0 | N38: =IFERROR(J38/M38,0) -> 0 | O38: =IF(N38>$C$8,"YES","NO") -> NO | Q38: 0 | R38: =$C$7 -> 0 | S38: =Q38-IF(Q38<>0,Q38-(Q38/(1+R38)),0) -> 0 | T38: =IFERROR(J38/S38,0) -> 0 | U38: =IF(T38>$C$8,"YES","NO") -> NO
A39: =A35+1 -> 8 | B39: GHOSRX103999OT | C39: WOMENS CROP RAGLAN CHAMBER OF CHILLS | D39: SM-XL | E39: 9.05 | F39: 1.45 | G39: 0 | H39: =SUM(E39:G39) -> 10.5 | I39: 0 | J39: =SUM(H39:I39) -> 10.5 | K39: 50 | L39: =$C$7 -> 0 | M39: =K39-IF(K39<>0,K39-(K39/(1+L39)),0) -> 50 | N39: =IFERROR(J39/M39,0) -> 0.21 | O39: =IF(N39>$C$8,"YES","NO") -> NO | Q39: 0 | R39: =$C$7 -> 0 | S39: =Q39-IF(Q39<>0,Q39-(Q39/(1+R39)),0) -> 0 | T39: =IFERROR(J39/S39,0) -> 0 | U39: =IF(T39>$C$8,"YES","NO") -> NO
D40: 2XL | E40: 0 | F40: 0 | G40: 0 | H40: =SUM(E40:G40) -> 0 | I40: 0 | J40: =SUM(H40:I40) -> 0 | K40: 0 | L40: =$C$7 -> 0 | M40: =K40-IF(K40<>0,K40-(K40/(1+L40)),0) -> 0 | N40: =IFERROR(J40/M40,0) -> 0 | O40: =IF(N40>$C$8,"YES","NO") -> NO | Q40: 0 | R40: =$C$7 -> 0 | S40: =Q40-IF(Q40<>0,Q40-(Q40/(1+R40)),0) -> 0 | T40: =IFERROR(J40/S40,0) -> 0 | U40: =IF(T40>$C$8,"YES","NO") -> NO
D41: 3XL | E41: 0 | F41: 0 | G41: 0 | H41: =SUM(E41:G41) -> 0 | I41: 0 | J41: =SUM(H41:I41) -> 0 | K41: 0 | L41: =$C$7 -> 0 | M41: =K41-IF(K41<>0,K41-(K41/(1+L41)),0) -> 0 | N41: =IFERROR(J41/M41,0) -> 0 | O41: =IF(N41>$C$8,"YES","NO") -> NO | Q41: 0 | R41: =$C$7 -> 0 | S41: =Q41-IF(Q41<>0,Q41-(Q41/(1+R41)),0) -> 0 | T41: =IFERROR(J41/S41,0) -> 0 | U41: =IF(T41>$C$8,"YES","NO") -> NO
D42: 4XL | E42: 0 | F42: 0 | G42: 0 | H42: =SUM(E42:G42) -> 0 | I42: 0 | J42: =SUM(H42:I42) -> 0 | K42: 0 | L42: =$C$7 -> 0 | M42: =K42-IF(K42<>0,K42-(K42/(1+L42)),0) -> 0 | N42: =IFERROR(J42/M42,0) -> 0 | O42: =IF(N42>$C$8,"YES","NO") -> NO | Q42: 0 | R42: =$C$7 -> 0 | S42: =Q42-IF(Q42<>0,Q42-(Q42/(1+R42)),0) -> 0 | T42: =IFERROR(J42/S42,0) -> 0 | U42: =IF(T42>$C$8,"YES","NO") -> NO
...

Sheet Selling Prices
A1: Tour Inventory
B3: Tour | C3: =Inventory!C3 -> GHOST
B4: Tour Date | C4: =Inventory!C4 -> JAN-FEB 2026
D6: USD | E6: CAD
B7: NAV Item Code | C7: Product Description | D7: Selling Price | E7: Selling Price | F7: Selling Price | G7: Selling Price
A8: 1 | B8: =Inventory!B7 -> GHOSNS903311BK | C8: =Inventory!C7 -> BATWING HOODY | D8: ='Projection Sheet'!D15 -> 125
A9: 2 | B9: =Inventory!B8 -> GHOSRX203275BK | C9: =Inventory!C8 -> SHORTS BLACK/ WHT PAPA V COSTUME CLAWS | D9: ='Projection Sheet'!D16 -> 45
A10: 3 | B10: =Inventory!B9 -> GHOSRX204001BK | C10: =Inventory!C9 -> BLACK T SKELETOUR 26 ITIN | D10: ='Projection Sheet'!D17 -> 50
A11: 4 | B11: =Inventory!B10 -> GHOSRX204000BK | C11: =Inventory!C10 -> BLACK T BAT BRAIN 26 ITIN | D11: ='Projection Sheet'!D18 -> 50
A12: 5 | B12: =Inventory!B11 -> GHOSRX204002BK | C12: =Inventory!C11 -> BLACK T WESTERN EMERITUS 26 ITIN | D12: ='Projection Sheet'!D19 -> 50
A13: 6 | B13: =Inventory!B12 -> GHOSRX103437OT | C13: =Inventory!C12 -> CRYSTAL WASHED T AT THE GATES | D13: ='Projection Sheet'!D20 -> 60
A14: 7 | B14: =Inventory!B13 -> GHOSRX103998BK | C14: =Inventory!C13 -> BLACK T PAPA COOPER | D14: ='Projection Sheet'!D21 -> 50
A15: 8 | B15: =Inventory!B14 -> GHOSRX103999OT | C15: =Inventory!C14 -> WOMENS CROP RAGLAN CHAMBER OF CHILLS | D15: ='Projection Sheet'!D22 -> 50
A16: 9 | B16: =Inventory!B15 -> GHOSRX203401BK | C16: =Inventory!C15 -> BLACK PO HOODIE SKELETON | D16: ='Projection Sheet'!D23 -> 80
A17: 10 | B17: =Inventory!B16 -> 0 | C17: =Inventory!C16 -> 0 | D17: ='Projection Sheet'!D24 -> 1
A18: 11 | B18: =Inventory!B17 -> 0 | C18: =Inventory!C17 -> 0 | D18: ='Projection Sheet'!D25 -> 1
A19: 12 | B19: =Inventory!B18 -> 0 | C19: =Inventory!C18 -> 0 | D19: ='Projection Sheet'!D26 -> 1
... A67: 60 | B67: =Inventory!B66 -> 0 | C67: =Inventory!C66 -> 0 | D67: ='Projection Sheet'!D74 -> 1
A68: 61 | B68: =Inventory!B67 -> 0 | C68: =Inventory!C67 -> 0 | D68: ='Projection Sheet'!D75 -> 1
A69: 62 | B69: =Inventory!B68 -> 0 | C69: =Inventory!C68 -> 0 | D69: ='Projection Sheet'!D76 -> 1
A70: 63 | B70: =Inventory!B69 -> 0 | C70: =Inventory!C69 -> 0 | D70: ='Projection Sheet'!D77 -> 1
A71: 64 | B71: =Inventory!B70 -> 0 | C71: =Inventory!C70 -> 0 | D71: ='Projection Sheet'!D78 -> 1
A72: 65 | B72: =Inventory!B71 -> 0 | C72: =Inventory!C71 -> 0 | D72: ='Projection Sheet'!D79 -> 1
A73: 66 | B73: =Inventory!B72 -> 0 | C73: =Inventory!C72 -> 0 | D73: ='Projection Sheet'!D80 -> 1
A74: 67 | B74: =Inventory!B73 -> GHOSRX103241BK | C74: =Inventory!C73 -> CHOKER PAPA V | D74: ='Projection Sheet'!D81 -> 30
A75: 68 | B75: =Inventory!B74 -> GHOSRX203254GR | C75: =Inventory!C74 -> KEYCHAIN SKELETON GRUCIFIX | D75: ='Projection Sheet'!D82 -> 15
A76: 69 | B76: =Inventory!B75 -> GHOSRX903403OT | C76: =Inventory!C75 -> PATCH SET OF 3 | D76: ='Projection Sheet'!D83 -> 20
A77: 70 | B77: =Inventory!B76 -> GHOSRX003611BK | C77: =Inventory!C76 -> 0 | D77: ='Projection Sheet'!D84 -> 1
A78: 71 | B78: =Inventory!B77 -> GHOSRX903408OT | C78: =Inventory!C77 -> LP SKELETA POLTERGEIST | D78: ='Projection Sheet'!D85 -> 40
A79: 72 | B79: =Inventory!B78 -> GHOSNS203369OT | C79: =Inventory!C78 -> FOILED COMIC BOOK SISTER IMPERATOR # 1 | D79: ='Projection Sheet'!D86 -> 30
... A82: 75 | B82: =Inventory!B81 -> GHOSNS103624OT | C82: =Inventory!C81 -> FOILED COMIC BOOK SISTER IMPERATOR #4 | D82: ='Projection Sheet'!D89 -> 15
A83: 76 | B83: =Inventory!B82 -> GHOSRX003470OT | C83: =Inventory!C82 -> ROLLING STONE MAG & ALBUM | D83: ='Projection Sheet'!#REF! -> #REF!
A84: 77 | B84: =Inventory!B83 -> GHOSRX003611BK | C84: =Inventory!C83 -> LP SKELETA BLACK VINYL | D84: ='Projection Sheet'!#REF! -> #REF!
A85: 78 | B85: =Inventory!B84 -> GHOSCG103805PU | C85: =Inventory!C84 -> LP PURPLE LENTICULAR (CONSIGNMENT) | D85: ='Projection Sheet'!#REF! -> #REF!
A86: 79 | B86: =Inventory!B85 -> GHOSCG103844BK | C86: =Inventory!C85 -> CASSETTE (CONSIGNMENT) | D86: ='Projection Sheet'!#REF! -> #REF!
A87: 80 | B87: =Inventory!B86 -> 0 | C87: =Inventory!C86 -> 0 | D87: ='Projection Sheet'!#REF! -> #REF!
A88: 81 | B88: =Inventory!B87 -> 0 | C88: =Inventory!C87 -> 0 | D88: ='Projection Sheet'!#REF! -> #REF!
A89: 82 | B89: =Inventory!B88 -> 0 | C89: =Inventory!C88 -> 0 | D89: ='Projection Sheet'!#REF! -> #REF!
A90: 83 | B90: =Inventory!B89 -> 0 | C90: =Inventory!C89 -> 0 | D90: ='Projection Sheet'!#REF! -> #REF!
A91: 84 | B91: =Inventory!B90 -> 0 | C91: =Inventory!C90 -> 0 | D91: ='Projection Sheet'!#REF! -> #REF!
...

Sheet Projection Sheet
F2: SM | G2: MED | H2: LG | I2: XL | J2: 2X | K2: 3X | L2: TOTAL | N2: TOUR STOCK | O2: ORDER QTY | P2: TOTAL | Q2: SIZE | R2: SIZE % | S2: AMOUNT | T2: LESS TOUR INV | U2: ORDER QTY | X2: TS | Y2: LADIES | Z2: LS | AA2: ZIP | AB2: SHORT
L3: =SUM(F3:K3) -> 0 | N3: 0 | O3: 2160 | P3: =N3+O3 -> 2160 | Q3: SM | R3: 0.09 | S3: =P3*R3 -> 194.4 | T3: 0 | U3: =S3-T3 -> 194.4 | X3: 0.05 | Y3: 0.21 | Z3: 0.04 | AA3: 0.04 | AB3: 0.17
L4: =SUM(F4:K4) -> 0 | P4: =P3 -> 2160 | Q4: MED | R4: 0.23 | S4: =P4*R4 -> 496.8 | T4: 0 | U4: =S4-T4 -> 496.8 | X4: 0.12 | Y4: 0.3 | Z4: 0.17 | AA4: 0.17 | AB4: 0.25
L5: =SUM(F5:K5) -> 0 | P5: =P3 -> 2160 | Q5: LG | R5: 0.28 | S5: =P5*R5 -> 604.8 | T5: 0 | U5: =S5-T5 -> 604.8 | X5: 0.27 | Y5: 0.26 | Z5: 0.24 | AA5: 0.24 | AB5: 0.25 | AG5: DATE | AH5: CITY | AI5: ST | AJ5: VENUE | AK5: CAPACITY | AL5: SOLD | AM5: EXPECT | AO5: PH | AP5: GROSS
B6: DATE: | C6: 45944 | L6: =SUM(F6:K6) -> 0 | P6: =P3 -> 2160 | Q6: XL | R6: 0.2 | S6: =P6*R6 -> 432 | T6: 0 | U6: =S6-T6 -> 432 | X6: 0.27 | Y6: 0.23 | Z6: 0.26 | AA6: 0.26 | AB6: 0.21 | AG6: ='Tour Dates'!A4 -> 46043 | AH6: ='Tour Dates'!B4 -> ORLANDO | AI6: ='Tour Dates'!C4 -> FL | AJ6: ='Tour Dates'!D4 -> KIA CENTER | AK6: 9061 | AL6: 6589 | AM6: 7500 | AO6: 35 | AP6: =AM6*AO6 -> 262500
B7: BAND: | C7: =Inventory!C3 -> GHOST | L7: =SUM(F7:K7) -> 0 | P7: =P5 -> 2160 | Q7: 2X | R7: 0.14 | S7: =P7*R7 -> 302.4 | T7: 0 | U7: =S7-T7 -> 302.4 | X7: 0.19 | Y7: 0 | Z7: 0.18 | AA7: 0.18 | AB7: 0.13 | AG7: ='Tour Dates'!A5 -> 46044 | AH7: ='Tour Dates'!B5 -> JACKSONVILLE | AI7: ='Tour Dates'!C5 -> FL | AJ7: ='Tour Dates'!D5 -> VYSTAR MEMORIAL ARENA | AK7: 5265 | AL7: 3275 | AM7: 3750 | AO7: 35 | AP7: =AM7*AO7 -> 131250
B8: TOUR: | C8: North America | L8: =SUM(F8:K8) -> 0 | P8: =P5 -> 2160 | Q8: 3X | R8: 0.06 | S8: =P8*R8 -> 129.6 | T8: 0 | U8: =S8-T8 -> 129.6 | X8: 0.1 | Y8: 0 | Z8: 0.09 | AA8: 0.09 | AB8: 0 | AG8: ='Tour Dates'!A6 -> 46046 | AH8: ='Tour Dates'!B6 -> KNOXVILLE | AI8: ='Tour Dates'!C6 -> TN | AJ8: ='Tour Dates'!D6 -> THOMPSON-BOLING ARENA | AK8: 9698 | AL8: 6720 | AM8: 7000 | AO8: 35 | AP8: =AM8*AO8 -> 245000
B9: # OF SHOWS: | C9: 20 | R9: =SUM(R3:R8) -> 1 | T9: =SUM(T3:T8) -> 0 | U9: =SUM(U3:U8) -> 2160 | X9: 0 | Y9: 0 | Z9: 0.02 | AA9: 0.02 | AB9: 0 | AG9: ='Tour Dates'!A7 -> 46047 | AH9: ='Tour Dates'!B7 -> CHARLOTTE | AI9: ='Tour Dates'!C7 -> NC | AJ9: ='Tour Dates'!D7 -> SPECTRUM CENTER | AK9: 10355 | AL9: 6464 | AM9: 7500 | AO9: 35 | AP9: =AM9*AO9 -> 262500
B10: ATTENDANCE: | C10: =AM46 -> 134885 | X10: =SUM(X3:X9) -> 1 | Y10: =SUM(Y3:Y9) -> 1 | Z10: =SUM(Z3:Z9) -> 1 | AA10: =SUM(AA3:AA9) -> 1 | AB10: =SUM(AB3:AB9) -> 1.01 | AG10: ='Tour Dates'!A8 -> 46048 | AH10: ='Tour Dates'!B8 -> GREENVILLE | AI10: ='Tour Dates'!C8 -> SC | AJ10: ='Tour Dates'!D8 -> BON SECOURS ARENA | AK10: 5978 | AL10: 3321 | AM10: 3800 | AO10: 35 | AP10: =AM10*AO10 -> 133000
AG11: ='Tour Dates'!A9 -> 46050 | AH11: ='Tour Dates'!B9 -> UNCASVILLE | AI11: ='Tour Dates'!C9 -> CT | AJ11: ='Tour Dates'!D9 -> MOHEGAN SUN ARENA | AK11: 4835 | AL11: 4818 | AM11: 4835 | AO11: 35 | AP11: =AM11*AO11 -> 169225
D12: EXP. GROSS | E12: =C10*E13 -> 3372125 | F12: =C10*F13 -> 4046550 | G12: =C10*G13 -> 4316320 | H12: =C10*H13 -> 4855860 | I12: STOCK | J12: STOCK | K12: STOCK | L12: STOCK | M12: STOCK | N12: STOCK | O12: PO's | P12: PRODUCT OVER (+) or UNDER (-) | T12: BLANKS | U12: PRINTER | V12: SM | W12: MED | X12: LG | Y12: XL | Z12: 2X | AA12: 3X | AB12: TOTAL | AC12: DUE | AD12: BLANK PO | AE12: PRINT PO | AG12: ='Tour Dates'!A10 -> 46052 | AH12: ='Tour Dates'!B10 -> MONTREAL | AI12: ='Tour Dates'!C10 -> QC | AJ12: ='Tour Dates'!D10 -> BELL CENTRE | AK12: 12268 | AL12: 8978 | AM12: 10000 | AO12: 25 | AP12: =AM12*AO12 -> 250000
C13: =SUM(C15:C89) -> 0.99 | D13: PRICE/P.H. | E13: 25 | F13: 30 | G13: 32 | H13: 36 | I13: TOUR | J13: CITY-A | K13: CITY-B | L13: MEXICO | M13: WEB | N13: ANAHEIM | O13: ON ORDER | P13: =E13 -> 25 | Q13: =F13 -> 30 | R13: =G13 -> 32 | S13: =H13 -> 36 | AG13: ='Tour Dates'!A11 -> 46053 | AH13: ='Tour Dates'!B11 -> TORONTO | AI13: ='Tour Dates'!C11 -> ON | AJ13: ='Tour Dates'!D11 -> SCOTIABANK ARENA | AK13: 11715 | AL13: 9785 | AM13: 11000 | AO13: 30 | AP13: =AM13*AO13 -> 330000
A14: SKU # | B14: DESIGN | C14: % GROSS | AG14: ='Tour Dates'!A12 -> 46055 | AH14: ='Tour Dates'!B12 -> COLUMBUS | AI14: ='Tour Dates'!C12 -> OH | AJ14: ='Tour Dates'!D12 -> NATIONWIDE ARENA | AK14: 9654 | AL14: 5612 | AM14: 6500 | AO14: 35 | AP14: =AM14*AO14 -> 227500
A15: =Inventory!B7 -> GHOSNS903311BK | B15: =Inventory!C7 -> BATWING HOODY | C15: 0.105 | D15: 125 | E15: =E12/D15*C15 -> 2832.585 | F15: =F12/D15*C15 -> 3399.102 | G15: =G12/D15*C15 -> 3625.7088 | H15: =H12/D15*C15 -> 4078.9224 | I15: 0 | J15: 0 | K15: 0 | L15: 0 | M15: 0 | N15: 0 | O15: 6000 | P15: =I15+J15+K15+L15+M15+N15+O15-E15 -> 3167.415 | Q15: =I15+J15+K15+L15+M15+N15+O15-F15 -> 2600.898 | R15: =I15+J15+K15+L15+M15+N15+O15-G15 -> 2374.2912 | S15: =I15+J15+K15+L15+M15+N15+O15-H15 -> 1921.0776 | T15: CUSTOM | U15: =Inventory!D7 -> FARSTAR | V15: 500 | W15: 1200 | X15: 1800 | Y15: 1300 | Z15: 800 | AA15: 400 | AB15: =SUM(V15:AA15) -> 6000 | AC15: 45986 | AG15: ='Tour Dates'!A13 -> 46057 | AH15: ='Tour Dates'!B13 -> CINCINNATI | AI15: ='Tour Dates'!C13 -> OH | AJ15: ='Tour Dates'!D13 -> HERITAGE BANK CENTER | AK15: 7861 | AL15: 4787 | AM15: 5500 | AO15: 35 | AP15: =AM15*AO15 -> 192500
