Workbook
Name CompanyAddress: [1]Settings!$C$10
Name CompanyName: '[1]Tour Info'!$F$6
Name Rates: [1]Settings!$C$2:$C$7
Name YesNo: [1]Settings!$C$15:$C$16

Sheet Tour Dates
A1: Tour Dates
A3: Date | B3: City | C3: STATE | D3: VENUE | E3: Country
A4: 45847 | B4: Baltimore | C4: MD | D4: CFG Bank Arena | E4: USA
A5: 45849 | B5: Atlanta | C5: GA | D5: State Farm Arena | E5: USA
A6: 45850 | B6: Tampa | C6: FL | D6: Amalie Arena | E6: USA
A7: 45851 | B7: Miami | C7: FL | D7: Kaseya Center | E7: USA
A8: 45853 | B8: Raleigh | C8: NC | D8: Lenovo Center | E8: USA
A9: 45855 | B9: Cleveland | C9: OH | D9: Rocket Mortgage FieldHouse | E9: USA
A10: 45856 | B10: Pittsburgh | C10: PA | D10: PPG Paints Arena | E10: USA
A11: 45857 | B11: Philadelphia | C11: PA | D11: Wells Fargo Center | E11: USA
A12: 45859 | B12: Boston | C12: MA | D12: TD Garden | E12: USA
A13: 45860 | B13: New York | C13: NY | D13: Madison Square Garden | E13: USA
A14: 45862 | B14: Detroit | C14: MI | D14: Little Caesars Arena | E14: USA
A15: 45863 | B15: Louisville | C15: KY | D15: KFC Yum! Center | E15: USA
... A25: 45878 | B25: Las Vegas | C25: NV | D25: MGM Grand Garden Arena | E25: USA
A26: 8/10/2025 | B26: San Diego | C26: CA | D26: Viejas Arena | E26: USA
A27: 8/11/2025 | B27: Phoenix | C27: AZ | D27: Footprint Center | E27: USA
A28: 8/14/2025 | B28: Austin | C28: TX | D28: Moody Center | E28: USA
A29: 8/15/2025 | B29: Fort Worth | C29: TX | D29: Dickies Arena | E29: USA
A30: 8/16/2025 | B30: Houston | C30: TX | D30: Toyota Center | E30: USA

Sheet Inventory
B1: Tour Inventory
B3: Tour | C3: GHOST | D3: GARMENTS x 20 | E3: TRINKETS X 20
B4: Tour Date | C4: SUMMER 2025
E5: Formula | F5: Formula | G5: Formula | J5: QUICK STOCK VIEW | R5: PRODUCT SUMMARY
B6: BC Item Code | C6: Product Description | D6: Supplier | E6: Blank Unit Cost | F6: Print Unit Cost | G6: Full Package | H6: Total Unit Cost | J6: Sales | K6: Used | L6: Road | M6: Ware house | N6: Sales % | P6: End Tour Stock Count | R6: B/F | S6: Purchased | T6: Sold | U6: W/S | V6: Band Comps | W6: GMS Comps | X6: O/U | Y6: Retail | Z6: Web | AA6: Global UK | AB6: Other | AC6: Misprint | AD6: Closing Stock | AE6: Closing Stock
A7: 1 | B7: GHOSRX203729BK | C7: BLACK T SKELETOUR 2025 ITIN | D7: CULTURE | E7: =VLOOKUP($A:$A,'COGS NEW TEMPLATE'!$A:$G,5,FALSE) -> 0 | F7: =VLOOKUP($A:$A,'COGS NEW TEMPLATE'!$A:$G,6,FALSE) -> 0 | G7: =VLOOKUP($A:$A,'COGS NEW TEMPLATE'!$A:$G,7,FALSE) -> 5.7 | H7: =SUM(E7:G7) -> 5.7 | J7: ='BLK T ADMAT ITIN'!$C$64 -> 23973 | K7: ='BLK T ADMAT ITIN'!$G$64 -> 24021 | L7: ='BLK T ADMAT ITIN'!$L$64 -> 0 | M7: ='BLK T ADMAT ITIN'!$S$64 -> 684 | N7: ='BLK T ADMAT ITIN'!$M$64 -> 0.15037037 | R7: ='BLK T ADMAT ITIN'!$V$39 -> 0 | S7: ='BLK T ADMAT ITIN'!$V$40 -> 25108 | T7: ='BLK T ADMAT ITIN'!$V$41 -> 23973 | U7: ='BLK T ADMAT ITIN'!$V$44 -> 8 | V7: ='BLK T ADMAT ITIN'!$V$42 -> 27 | W7: ='BLK T ADMAT ITIN'!$V$43 -> 13 | X7: ='BLK T ADMAT ITIN'!$V$46 -> 133 | Y7: ='BLK T ADMAT ITIN'!$V$47 -> 0 | Z7: ='BLK T ADMAT ITIN'!$V$48 -> 270 | AA7: ='BLK T ADMAT ITIN'!$V$49 -> 0 | AB7: ='BLK T ADMAT ITIN'!$V$50 -> 0 | AC7: ='BLK T ADMAT ITIN'!$V$51 -> 0 | AD7: ='BLK T ADMAT ITIN'!V$52+'BLK T ADMAT ITIN'!V$53 -> 684 | AE7: =(R7+S7)-SUM(T7:AC7) -> 684
A8: 2 | B8: GHOSRX203728BK | C8: BLACK T SKELETA ALBUM COVER 2025 ITIN | D8: CULTURE | E8: =VLOOKUP($A:$A,'COGS NEW TEMPLATE'!$A:$G,5,FALSE) -> 0 | F8: =VLOOKUP($A:$A,'COGS NEW TEMPLATE'!$A:$G,6,FALSE) -> 0 | G8: =VLOOKUP($A:$A,'COGS NEW TEMPLATE'!$A:$G,7,FALSE) -> 5.7 | H8: =SUM(E8:G8) -> 5.7 | J8: ='BLK T SKELETA ITIN'!$C$64 -> 17260 | K8: ='BLK T SKELETA ITIN'!$G$64 -> 17296 | L8: ='BLK T SKELETA ITIN'!$L$64 -> 0 | M8: ='BLK T SKELETA ITIN'!$S$64 -> 58 | N8: ='BLK T SKELETA ITIN'!$M$64 -> 0.10777778 | R8: ='BLK T SKELETA ITIN'!$V$39 -> 0 | S8: ='BLK T SKELETA ITIN'!$V$40 -> 17527 | T8: ='BLK T SKELETA ITIN'!$V$41 -> 17260 | U8: ='BLK T SKELETA ITIN'!$V$44 -> 4 | V8: ='BLK T SKELETA ITIN'!$V$42 -> 22 | W8: ='BLK T SKELETA ITIN'!$V$43 -> 10 | X8: ='BLK T SKELETA ITIN'!$V$46 -> 173 | Y8: ='BLK T SKELETA ITIN'!$V$47 -> 0 | Z8: ='BLK T SKELETA ITIN'!$V$48 -> 0 | AA8: ='BLK T SKELETA ITIN'!$V$49 -> 0 | AB8: ='BLK T SKELETA ITIN'!$V$50 -> 0 | AC8: ='BLK T SKELETA ITIN'!$V$51 -> 0 | AD8: ='BLK T SKELETA ITIN'!V$52+'BLK T SKELETA ITIN'!V$53 -> 58 | AE8: =(R8+S8)-SUM(T8:AC8) -> 58
A9: 3 | B9: GHOSRX203730BK | C9: BLACK T WESTERN EMERITUS 2025 ITIN | D9: CULTURE | E9: =VLOOKUP($A:$A,'COGS NEW TEMPLATE'!$A:$G,5,FALSE) -> 0 | F9: =VLOOKUP($A:$A,'COGS NEW TEMPLATE'!$A:$G,6,FALSE) -> 0 | G9: =VLOOKUP($A:$A,'COGS NEW TEMPLATE'!$A:$G,7,FALSE) -> 5.7 | H9: =SUM(E9:G9) -> 5.7 | J9: ='BLK T EMERITUS ITIN'!$C$64 -> 28239 | K9: ='BLK T EMERITUS ITIN'!$G$64 -> 28281 | L9: ='BLK T EMERITUS ITIN'!$L$64 -> 0 | M9: ='BLK T EMERITUS ITIN'!$S$64 -> 0 | N9: ='BLK T EMERITUS ITIN'!$M$64 -> 0.1762963 | R9: ='BLK T EMERITUS ITIN'!$V$39 -> 0 | S9: ='BLK T EMERITUS ITIN'!$V$40 -> 28590 | T9: ='BLK T EMERITUS ITIN'!$V$41 -> 28239 | U9: ='BLK T EMERITUS ITIN'!$V$44 -> 7 | V9: ='BLK T EMERITUS ITIN'!$V$42 -> 24 | W9: ='BLK T EMERITUS ITIN'!$V$43 -> 11 | X9: ='BLK T EMERITUS ITIN'!$V$46 -> 141 | Y9: ='BLK T EMERITUS ITIN'!$V$47 -> 0 | Z9: ='BLK T EMERITUS ITIN'!$V$48 -> 168 | AA9: ='BLK T EMERITUS ITIN'!$V$49 -> 0 | AB9: ='BLK T EMERITUS ITIN'!$V$50 -> 0 | AC9: ='BLK T EMERITUS ITIN'!$V$51 -> 0 | AD9: ='BLK T EMERITUS ITIN'!V$52+'BLK T EMERITUS ITIN'!V$53 -> 0 | AE9: =(R9+S9)-SUM(T9:AC9) -> 0
A10: 4 | B10: GHOSRX103726BK | C10: BLACK TANK OPUS EPONYMOUS | D10: CULTURE | E10: =VLOOKUP($A:$A,'COGS NEW TEMPLATE'!$A:$G,5,FALSE) -> 0 | F10: =VLOOKUP($A:$A,'COGS NEW TEMPLATE'!$A:$G,6,FALSE) -> 0 | G10: =VLOOKUP($A:$A,'COGS NEW TEMPLATE'!$A:$G,7,FALSE) -> 7.38 | H10: =SUM(E10:G10) -> 7.38 | J10: ='TANK TOP'!$C$64 -> 4001 | K10: ='TANK TOP'!$G$64 -> 4019 | L10: ='TANK TOP'!$L$64 -> 0 | M10: ='TANK TOP'!$S$64 -> 0 | N10: ='TANK TOP'!$M$64 -> 0.025555556 | R10: ='TANK TOP'!$V$39 -> 0 | S10: ='TANK TOP'!$V$40 -> 4179 | T10: ='TANK TOP'!$V$41 -> 4001 | U10: ='TANK TOP'!$V$44 -> 1 | V10: ='TANK TOP'!$V$42 -> 15 | W10: ='TANK TOP'!$V$43 -> 2 | X10: ='TANK TOP'!$V$46 -> 8 | Y10: ='TANK TOP'!$V$47 -> 0 | Z10: ='TANK TOP'!$V$48 -> 152 | AA10: ='TANK TOP'!$V$49 -> 0 | AB10: ='TANK TOP'!$V$50 -> 0 | AC10: ='TANK TOP'!$V$51 -> 0 | AD10: ='TANK TOP'!V$52+'TANK TOP'!V$53 -> 0 | AE10: =(R10+S10)-SUM(T10:AC10) -> 0
A11: 5 | B11: GHOSRX203400BK | C11: LADIES CROP TOP SHOWGHOULS | D11: GMSUK | E11: =VLOOKUP($A:$A,'COGS NEW TEMPLATE'!$A:$G,5,FALSE) -> 0 | F11: =VLOOKUP($A:$A,'COGS NEW TEMPLATE'!$A:$G,6,FALSE) -> 0 | G11: =VLOOKUP($A:$A,'COGS NEW TEMPLATE'!$A:$G,7,FALSE) -> 9.77 | H11: =SUM(E11:G11) -> 9.77 | J11: ='LADIES CROP TOP'!$C$64 -> 3160 | K11: ='LADIES CROP TOP'!$G$64 -> 3167 | L11: ='LADIES CROP TOP'!$L$64 -> 0 | M11: ='LADIES CROP TOP'!$S$64 -> 0 | N11: ='LADIES CROP TOP'!$M$64 -> 0.01962963 | R11: ='LADIES CROP TOP'!$V$39 -> 0 | S11: ='LADIES CROP TOP'!$V$40 -> 3156 | T11: ='LADIES CROP TOP'!$V$41 -> 3160 | U11: ='LADIES CROP TOP'!$V$44 -> 0 | V11: ='LADIES CROP TOP'!$V$42 -> 2 | W11: ='LADIES CROP TOP'!$V$43 -> 5 | X11: ='LADIES CROP TOP'!$V$46 -> -11 | Y11: ='LADIES CROP TOP'!$V$47 -> 0 | Z11: ='LADIES CROP TOP'!$V$48 -> 0 | AA11: ='LADIES CROP TOP'!$V$49 -> 0 | AB11: ='LADIES CROP TOP'!$V$50 -> 0 | AC11: ='LADIES CROP TOP'!$V$51 -> 0 | AD11: ='LADIES CROP TOP'!V$52+'LADIES CROP TOP'!V$53 -> 0 | AE11: =(R11+S11)-SUM(T11:AC11) -> 0
A12: 6 | B12: GHOSRX203727PK | C12: LADIES PINK RAGLAN GARGOYLE | D12: CULTURE | E12: =VLOOKUP($A:$A,'COGS NEW TEMPLATE'!$A:$G,5,FALSE) -> 0 | F12: =VLOOKUP($A:$A,'COGS NEW TEMPLATE'!$A:$G,6,FALSE) -> 0 | G12: =VLOOKUP($A:$A,'COGS NEW TEMPLATE'!$A:$G,7,FALSE) -> 12.29 | H12: =SUM(E12:G12) -> 12.29 | J12: ='LADIES RAGLAN '!$C$64 -> 2939 | K12: ='LADIES RAGLAN '!$G$64 -> 2959 | L12: ='LADIES RAGLAN '!$L$64 -> 0 | M12: ='LADIES RAGLAN '!$S$64 -> 242 | N12: ='LADIES RAGLAN '!$M$64 -> 0.018888889 | R12: ='LADIES RAGLAN '!$V$39 -> 0 | S12: ='LADIES RAGLAN '!$V$40 -> 3307 | T12: ='LADIES RAGLAN '!$V$41 -> 2939 | U12: ='LADIES RAGLAN '!$V$44 -> 1 | V12: ='LADIES RAGLAN '!$V$42 -> 15 | W12: ='LADIES RAGLAN '!$V$43 -> 4 | X12: ='LADIES RAGLAN '!$V$46 -> 6 | Y12: ='LADIES RAGLAN '!$V$47 -> 0 | Z12: ='LADIES RAGLAN '!$V$48 -> 100 | AA12: ='LADIES RAGLAN '!$V$49 -> 0 | AB12: ='LADIES RAGLAN '!$V$50 -> 0 | AC12: ='LADIES RAGLAN '!$V$51 -> 0 | AD12: ='LADIES RAGLAN '!V$52+'LADIES RAGLAN '!V$53 -> 242 | AE12: =(R12+S12)-SUM(T12:AC12) -> 242
A13: 7 | E13: =VLOOKUP($A:$A,'COGS NEW TEMPLATE'!$A:$G,5,FALSE) -> 0 | F13: =VLOOKUP($A:$A,'COGS NEW TEMPLATE'!$A:$G,6,FALSE) -> 0 | G13: =VLOOKUP($A:$A,'COGS NEW TEMPLATE'!$A:$G,7,FALSE) -> 0 | H13: =SUM(E13:G13) -> 0 | J13: ='7'!$C$64 -> 0 | K13: ='7'!$G$64 -> 0 | L13: ='7'!$L$64 -> 0 | M13: ='7'!$S$64 -> 0 | N13: ='7'!$M$64 -> 0 | R13: ='7'!$V$39 -> 0 | S13: ='7'!$V$40 -> 0 | T13: ='7'!$V$41 -> 0 | U13: ='7'!$V$44 -> 0 | V13: ='7'!$V$42 -> 0 | W13: ='7'!$V$43 -> 0 | X13: ='7'!$V$46 -> 0 | Y13: ='7'!$V$47 -> 0 | Z13: ='7'!$V$48 -> 0 | AA13: ='7'!$V$49 -> 0 | AB13: ='7'!$V$50 -> 0 | AC13: ='7'!$V$51 -> 0 | AD13: ='7'!V$52+'7'!V$53 -> 0 | AE13: =(R13+S13)-SUM(T13:AC13) -> 0
A14: 8 | B14: GHOSNS903311BK | C14: BATWING HOODY | D14: FARSTAR | E14: =VLOOKUP($A:$A,'COGS NEW TEMPLATE'!$A:$G,5,FALSE) -> 0 | F14: =VLOOKUP($A:$A,'COGS NEW TEMPLATE'!$A:$G,6,FALSE) -> 0 | G14: =VLOOKUP($A:$A,'COGS NEW TEMPLATE'!$A:$G,7,FALSE) -> 28.5 | H14: =SUM(E14:G14) -> 28.5 | J14: ='BATWING HOODY'!$C$64 -> 6179 | K14: ='BATWING HOODY'!$G$64 -> 6196 | L14: ='BATWING HOODY'!$L$64 -> 0 | M14: ='BATWING HOODY'!$S$69 -> 1093 | N14: ='BATWING HOODY'!$M$64 -> 0.097407407 | R14: ='BATWING HOODY'!$V$44 -> 0 | S14: ='BATWING HOODY'!$V$45 -> 7225 | T14: ='BATWING HOODY'!$V$46 -> 6179 | U14: ='BATWING HOODY'!$V$49 -> 4 | V14: ='BATWING HOODY'!$V$47 -> 11 | W14: ='BATWING HOODY'!$V$48 -> 2 | X14: ='BATWING HOODY'!$V$51 -> -64 | Y14: ='BATWING HOODY'!$V$52 -> 0 | Z14: ='BATWING HOODY'!$V$53 -> 0 | AA14: ='BATWING HOODY'!$V$54 -> 0 | AB14: ='BATWING HOODY'!$V$55 -> 0 | AC14: ='BATWING HOODY'!$V$56 -> 0 | AD14: ='BATWING HOODY'!V$57+'BATWING HOODY'!V$58 -> 1093 | AE14: =(R14+S14)-SUM(T14:AC14) -> 1093
A15: 9 | B15: GHOSRX203401BK | C15: PULLOVER HOODY SKELETON | D15: CULTURE | E15: =VLOOKUP($A:$A,'COGS NEW TEMPLATE'!$A:$G,5,FALSE) -> 0 | F15: =VLOOKUP($A:$A,'COGS NEW TEMPLATE'!$A:$G,6,FALSE) -> 0 | G15: =VLOOKUP($A:$A,'COGS NEW TEMPLATE'!$A:$G,7,FALSE) -> 14.19 | H15: =SUM(E15:G15) -> 14.19 | J15: ='PO HOODY'!$C$64 -> 7347 | K15: ='PO HOODY'!$G$64 -> 7366 | L15: ='PO HOODY'!$L$64 -> 0 | M15: ='PO HOODY'!$S$64 -> 57 | N15: ='PO HOODY'!$M$64 -> 0.074074074 | R15: ='PO HOODY'!$V$39 -> 0 | S15: ='PO HOODY'!$V$40 -> 7518 | T15: ='PO HOODY'!$V$41 -> 7347 | U15: ='PO HOODY'!$V$44 -> 3 | V15: ='PO HOODY'!$V$42 -> 8 | W15: ='PO HOODY'!$V$43 -> 8 | X15: ='PO HOODY'!$V$46 -> 54 | Y15: ='PO HOODY'!$V$47 -> 0 | Z15: ='PO HOODY'!$V$48 -> 41 | AA15: ='PO HOODY'!$V$49 -> 0 | AB15: ='PO HOODY'!$V$50 -> 0 | AC15: ='PO HOODY'!$V$51 -> 0 | AD15: ='PO HOODY'!V$52+'PO HOODY'!V$53 -> 57 | AE15: =(R15+S15)-SUM(T15:AC15) -> 57
A16: 10 | B16: GHOSRX203275BK | C16: SHORTS BLACK/ WHT PAPA V COSTUME CLAWS | D16: CULTURE | E16: =VLOOKUP($A:$A,'COGS NEW TEMPLATE'!$A:$G,5,FALSE) -> 5.5 | F16: =VLOOKUP($A:$A,'COGS NEW TEMPLATE'!$A:$G,6,FALSE) -> 0 | G16: =VLOOKUP($A:$A,'COGS NEW TEMPLATE'!$A:$G,7,FALSE) -> 0 | H16: =SUM(E16:G16) -> 5.5 | J16: ='SHORTS BLK'!$C$64 -> 6578 | K16: ='SHORTS BLK'!$G$64 -> 6586 | L16: ='SHORTS BLK'!$L$64 -> 0 | M16: ='SHORTS BLK'!$S$64 -> 706 | N16: ='SHORTS BLK'!$M$64 -> 0.036666667 | R16: ='SHORTS BLK'!$V$39 -> 0 | S16: ='SHORTS BLK'!$V$40 -> 7476 | T16: ='SHORTS BLK'!$V$41 -> 6578 | U16: ='SHORTS BLK'!$V$44 -> 4 | V16: ='SHORTS BLK'!$V$42 -> 2 | W16: ='SHORTS BLK'!$V$43 -> 2 | X16: ='SHORTS BLK'!$V$46 -> 15 | Y16: ='SHORTS BLK'!$V$47 -> 0 | Z16: ='SHORTS BLK'!$V$48 -> 169 | AA16: ='SHORTS BLK'!$V$49 -> 0 | AB16: ='SHORTS BLK'!$V$50 -> 0 | AC16: ='SHORTS BLK'!$V$51 -> 0 | AD16: ='SHORTS BLK'!V$52+'SHORTS BLK'!V$53 -> 706 | AE16: =(R16+S16)-SUM(T16:AC16) -> 706
A17: 11 | B17: GHOSRX103510OT | C17: TIE DYE T TOP HAT | D17: GMSUK | E17: =VLOOKUP($A:$A,'COGS NEW TEMPLATE'!$A:$G,5,FALSE) -> 0 | F17: =VLOOKUP($A:$A,'COGS NEW TEMPLATE'!$A:$G,6,FALSE) -> 0 | G17: =VLOOKUP($A:$A,'COGS NEW TEMPLATE'!$A:$G,7,FALSE) -> 12.15 | H17: =SUM(E17:G17) -> 12.15 | J17: ='TIE DYE T'!$C$64 -> 2356 | K17: ='TIE DYE T'!$G$64 -> 2357 | L17: ='TIE DYE T'!$L$64 -> 0 | M17: ='TIE DYE T'!$S$64 -> 19 | N17: ='TIE DYE T'!$M$64 -> 0.016796296 | R17: ='TIE DYE T'!$V$39 -> 0 | S17: ='TIE DYE T'!$V$40 -> 2407 | T17: ='TIE DYE T'!$V$41 -> 2356 | U17: ='TIE DYE T'!$V$44 -> 0 | V17: ='TIE DYE T'!$V$42 -> 1 | W17: ='TIE DYE T'!$V$43 -> 0 | X17: ='TIE DYE T'!$V$46 -> 31 | Y17: ='TIE DYE T'!$V$47 -> 0 | Z17: ='TIE DYE T'!$V$48 -> 0 | AA17: ='TIE DYE T'!$V$49 -> 0 | AB17: ='TIE DYE T'!$V$50 -> 0 | AC17: ='TIE DYE T'!$V$51 -> 0 | AD17: ='TIE DYE T'!V$52+'TIE DYE T'!V$53 -> 19 | AE17: =(R17+S17)-SUM(T17:AC17) -> 19
A18: 12 | B18: GHOSRX103437OT | C18: CRYSTAL WASHED T AT THE GATES | D18: CULTURE DAYTONA | E18: =VLOOKUP($A:$A,'COGS NEW TEMPLATE'!$A:$G,5,FALSE) -> 0 | F18: =VLOOKUP($A:$A,'COGS NEW TEMPLATE'!$A:$G,6,FALSE) -> 0 | G18: =VLOOKUP($A:$A,'COGS NEW TEMPLATE'!$A:$G,7,FALSE) -> 8.71 | H18: =SUM(E18:G18) -> 8.71 | J18: ='CRYSTAL WASHED T'!$C$64 -> 6264 | K18: ='CRYSTAL WASHED T'!$G$64 -> 6276 | L18: ='CRYSTAL WASHED T'!$L$64 -> 0 | M18: ='CRYSTAL WASHED T'!$S$64 -> 0 | N18: ='CRYSTAL WASHED T'!$M$64 -> 0.047407407 | R18: ='CRYSTAL WASHED T'!$V$39 -> 0 | S18: ='CRYSTAL WASHED T'!$V$40 -> 6667 | T18: ='CRYSTAL WASHED T'!$V$41 -> 6264 | U18: ='CRYSTAL WASHED T'!$V$44 -> 0 | V18: ='CRYSTAL WASHED T'!$V$42 -> 5 | W18: ='CRYSTAL WASHED T'!$V$43 -> 7 | X18: ='CRYSTAL WASHED T'!$V$46 -> 58 | Y18: ='CRYSTAL WASHED T'!$V$47 -> 0 | Z18: ='CRYSTAL WASHED T'!$V$48 -> 0 | AA18: ='CRYSTAL WASHED T'!$V$49 -> 0 | AB18: ='CRYSTAL WASHED T'!$V$50 -> 333 | AC18: ='CRYSTAL WASHED T'!$V$51 -> 0 | AD18: ='CRYSTAL WASHED T'!V$52+'CRYSTAL WASHED T'!V$53 -> 0 | AE18: =(R18+S18)-SUM(T18:AC18) -> 0
A19: 13 | B19: GHOSRX203738BL | C19: OILWASHED NAVY BLUE T COME TOGETHER | D19: CULTURE DAYTONA | E19: =VLOOKUP($A:$A,'COGS NEW TEMPLATE'!$A:$G,5,FALSE) -> 0 | F19: =VLOOKUP($A:$A,'COGS NEW TEMPLATE'!$A:$G,6,FALSE) -> 0 | G19: =VLOOKUP($A:$A,'COGS NEW TEMPLATE'!$A:$G,7,FALSE) -> 11.15 | H19: =SUM(E19:G19) -> 11.15 | J19: ='OIL WASHED T'!$C$64 -> 2274 | K19: ='OIL WASHED T'!$G$64 -> 2293 | L19: ='OIL WASHED T'!$L$64 -> 0 | M19: ='OIL WASHED T'!$S$64 -> 431 | N19: ='OIL WASHED T'!$M$64 -> 0.016666667 | R19: ='OIL WASHED T'!$V$39 -> 0 | S19: ='OIL WASHED T'!$V$40 -> 2717 | T19: ='OIL WASHED T'!$V$41 -> 2274 | U19: ='OIL WASHED T'!$V$44 -> 0 | V19: ='OIL WASHED T'!$V$42 -> 15 | W19: ='OIL WASHED T'!$V$43 -> 4 | X19: ='OIL WASHED T'!$V$46 -> -7 | Y19: ='OIL WASHED T'!$V$47 -> 0 | Z19: ='OIL WASHED T'!$V$48 -> 0 | AA19: ='OIL WASHED T'!$V$49 -> 0 | AB19: ='OIL WASHED T'!$V$50 -> 0 | AC19: ='OIL WASHED T'!$V$51 -> 0 | AD19: ='OIL WASHED T'!V$52+'OIL WASHED T'!V$53 -> 431 | AE19: =(R19+S19)-SUM(T19:AC19) -> 431
A20: 14 | B20: GHOSRX203570RD | C20: SHORTS RED/WHITE LOGO | D20: CULTURE | E20: =VLOOKUP($A:$A,'COGS NEW TEMPLATE'!$A:$G,5,FALSE) -> 0 | F20: =VLOOKUP($A:$A,'COGS NEW TEMPLATE'!$A:$G,6,FALSE) -> 0 | G20: =VLOOKUP($A:$A,'COGS NEW TEMPLATE'!$A:$G,7,FALSE) -> 12.19 | H20: =SUM(E20:G20) -> 12.19 | J20: ='SHORTS RED'!$C$64 -> 566 | K20: ='SHORTS RED'!$G$64 -> 566 | L20: ='SHORTS RED'!$L$64 -> 0 | M20: ='SHORTS RED'!$S$64 -> 0 | N20: ='SHORTS RED'!$M$64 -> 0.0037037037 | R20: ='SHORTS RED'!$V$39 -> 0 | S20: ='SHORTS RED'!$V$40 -> 574 | T20: ='SHORTS RED'!$V$41 -> 566 | U20: ='SHORTS RED'!$V$44 -> 0 | V20: ='SHORTS RED'!$V$42 -> 0 | W20: ='SHORTS RED'!$V$43 -> 0 | X20: ='SHORTS RED'!$V$46 -> 8 | Y20: ='SHORTS RED'!$V$47 -> 0 | Z20: ='SHORTS RED'!$V$48 -> 0 | AA20: ='SHORTS RED'!$V$49 -> 0 | AB20: ='SHORTS RED'!$V$50 -> 0 | AC20: ='SHORTS RED'!$V$51 -> 0 | AD20: ='SHORTS RED'!V$52+'SHORTS RED'!V$53 -> 0 | AE20: =(R20+S20)-SUM(T20:AC20) -> 0
A21: 15 | B21: GHOSRX203800BK | C21: EVENT T TAMPA | D21: CULTURE DAYTONA | E21: =VLOOKUP($A:$A,'COGS NEW TEMPLATE'!$A:$G,5,FALSE) -> 0 | F21: =VLOOKUP($A:$A,'COGS NEW TEMPLATE'!$A:$G,6,FALSE) -> 0 | G21: =VLOOKUP($A:$A,'COGS NEW TEMPLATE'!$A:$G,7,FALSE) -> 6.2 | H21: =SUM(E21:G21) -> 6.2 | J21: =TAMPA!$C$64 -> 776 | K21: =TAMPA!$G$64 -> 788 | L21: =TAMPA!$L$64 -> 0 | M21: =TAMPA!$S$64 -> 0 | N21: =TAMPA!$M$64 -> 0.0044444444 | R21: =TAMPA!$V$39 -> 0 | S21: =TAMPA!$V$40 -> 788 | T21: =TAMPA!$V$41 -> 776 | U21: =TAMPA!$V$44 -> 0 | V21: =TAMPA!$V$42 -> 12 | W21: =TAMPA!$V$43 -> 0 | X21: =TAMPA!$V$46 -> 0 | Y21: =TAMPA!$V$47 -> 0 | Z21: =TAMPA!$V$48 -> 0 | AA21: =TAMPA!$V$49 -> 0 | AB21: =TAMPA!$V$50 -> 0 | AC21: =TAMPA!$V$51 -> 0 | AD21: =TAMPA!V$52+TAMPA!V$53 -> 0 | AE21: =(R21+S21)-SUM(T21:AC21) -> 0
A22: 16 | B22: GHOSRX203799BK | C22: EVENT T PHILLY | D22: CULTURE | E22: =VLOOKUP($A:$A,'COGS NEW TEMPLATE'!$A:$G,5,FALSE) -> 0 | F22: =VLOOKUP($A:$A,'COGS NEW TEMPLATE'!$A:$G,6,FALSE) -> 0 | G22: =VLOOKUP($A:$A,'COGS NEW TEMPLATE'!$A:$G,7,FALSE) -> 5.7 | H22: =SUM(E22:G22) -> 5.7 | J22: =PHILLY!$C$64 -> 973 | K22: =PHILLY!$G$64 -> 982 | L22: =PHILLY!$L$64 -> 0 | M22: =PHILLY!$S$64 -> 0 | N22: =PHILLY!$M$64 -> 0.0048148148 | R22: =PHILLY!$V$39 -> 0 | S22: =PHILLY!$V$40 -> 1087 | T22: =PHILLY!$V$41 -> 973 | U22: =PHILLY!$V$44 -> 0 | V22: =PHILLY!$V$42 -> 9 | W22: =PHILLY!$V$43 -> 0 | X22: =PHILLY!$V$46 -> 0 | Y22: =PHILLY!$V$47 -> 0 | Z22: =PHILLY!$V$48 -> 96 | AA22: =PHILLY!$V$49 -> 0 | AB22: =PHILLY!$V$50 -> 0 | AC22: =PHILLY!$V$51 -> 0 | AD22: =PHILLY!V$52+PHILLY!V$53 -> 9 | AE22: =(R22+S22)-SUM(T22:AC22) -> 9
A23: 17 | B23: GHOSRX203798BK | C23: EVENT T BOSTON | D23: CULTURE | E23: =VLOOKUP($A:$A,'COGS NEW TEMPLATE'!$A:$G,5,FALSE) -> 0 | F23: =VLOOKUP($A:$A,'COGS NEW TEMPLATE'!$A:$G,6,FALSE) -> 0 | G23: =VLOOKUP($A:$A,'COGS NEW TEMPLATE'!$A:$G,7,FALSE) -> 5.7 | H23: =SUM(E23:G23) -> 5.7 | J23: =BOSTON!$C$64 -> 897 | K23: =BOSTON!$G$64 -> 906 | L23: =BOSTON!$L$64 -> 0 | M23: =BOSTON!$S$64 -> 0 | N23: =BOSTON!$M$64 -> 0.0048148148 | R23: =BOSTON!$V$39 -> 0 | S23: =BOSTON!$V$40 -> 1088 | T23: =BOSTON!$V$41 -> 897 | U23: =BOSTON!$V$44 -> 0 | V23: =BOSTON!$V$42 -> 9 | W23: =BOSTON!$V$43 -> 0 | X23: =BOSTON!$V$46 -> 0 | Y23: =BOSTON!$V$47 -> 0 | Z23: =BOSTON!$V$48 -> 173 | AA23: =BOSTON!$V$49 -> 0 | AB23: =BOSTON!$V$50 -> 0 | AC23: =BOSTON!$V$51 -> 0 | AD23: =BOSTON!V$52+BOSTON!V$53 -> 9 | AE23: =(R23+S23)-SUM(T23:AC23) -> 9
A24: 18 | B24: GHOSRX203801BK | C24: EVENT T NEW YORK | D24: CULTURE | E24: =VLOOKUP($A:$A,'COGS NEW TEMPLATE'!$A:$G,5,FALSE) -> 0 | F24: =VLOOKUP($A:$A,'COGS NEW TEMPLATE'!$A:$G,6,FALSE) -> 0 | G24: =VLOOKUP($A:$A,'COGS NEW TEMPLATE'!$A:$G,7,FALSE) -> 5.7 | H24: =SUM(E24:G24) -> 5.7 | J24: ='NEW YORK'!$C$64 -> 1409 | K24: ='NEW YORK'!$G$64 -> 1433 | L24: ='NEW YORK'!$L$64 -> 0 | M24: ='NEW YORK'!$S$64 -> 0 | N24: ='NEW YORK'!$M$64 -> 0.0066666667 | R24: ='NEW YORK'!$V$39 -> 0 | S24: ='NEW YORK'!$V$40 -> 1440 | T24: ='NEW YORK'!$V$41 -> 1409 | U24: ='NEW YORK'!$V$44 -> 0 | V24: ='NEW YORK'!$V$42 -> 21 | W24: ='NEW YORK'!$V$43 -> 3 | X24: ='NEW YORK'!$V$46 -> 7 | Y24: ='NEW YORK'!$V$47 -> 0 | Z24: ='NEW YORK'!$V$48 -> 0 | AA24: ='NEW YORK'!$V$49 -> 0 | AB24: ='NEW YORK'!$V$50 -> 0 | AC24: ='NEW YORK'!$V$51 -> 0 | AD24: ='NEW YORK'!V$52+'NEW YORK'!V$53 -> 0 | AE24: =(R24+S24)-SUM(T24:AC24) -> 0
A25: 19 | B25: GHOSRX203822BK | C25: EVENT T CHICAGO | D25: CULTURE | E25: =VLOOKUP($A:$A,'COGS NEW TEMPLATE'!$A:$G,5,FALSE) -> 0 | F25: =VLOOKUP($A:$A,'COGS NEW TEMPLATE'!$A:$G,6,FALSE) -> 0 | G25: =VLOOKUP($A:$A,'COGS NEW TEMPLATE'!$A:$G,7,FALSE) -> 5.7 | H25: =SUM(E25:G25) -> 5.7 | J25: =CHICAGO!$C$64 -> 690 | K25: =CHICAGO!$G$64 -> 699 | L25: =CHICAGO!$L$64 -> 0 | M25: =CHICAGO!$S$64 -> 0 | N25: =CHICAGO!$M$64 -> 0.0040740741 | R25: =CHICAGO!$V$39 -> 0 | S25: =CHICAGO!$V$40 -> 1062 | T25: =CHICAGO!$V$41 -> 690 | U25: =CHICAGO!$V$44 -> 0 | V25: =CHICAGO!$V$42 -> 9 | W25: =CHICAGO!$V$43 -> 0 | X25: =CHICAGO!$V$46 -> 0 | Y25: =CHICAGO!$V$47 -> 0 | Z25: =CHICAGO!$V$48 -> 363 | AA25: =CHICAGO!$V$49 -> 0 | AB25: =CHICAGO!$V$50 -> 0 | AC25: =CHICAGO!$V$51 -> 0 | AD25: =CHICAGO!V$52+CHICAGO!V$53 -> 0 | AE25: =(R25+S25)-SUM(T25:AC25) -> 0
A26: 20 | E26: =VLOOKUP($A:$A,'COGS NEW TEMPLATE'!$A:$G,5,FALSE) -> 0 | F26: =VLOOKUP($A:$A,'COGS NEW TEMPLATE'!$A:$G,6,FALSE) -> 0 | G26: =VLOOKUP($A:$A,'COGS NEW TEMPLATE'!$A:$G,7,FALSE) -> 0 | H26: =SUM(E26:G26) -> 0 | J26: ='20'!$C$64 -> 0 | K26: ='20'!$G$64 -> 0 | L26: ='20'!$L$64 -> 0 | M26: ='20'!$S$64 -> 0 | N26: ='20'!$M$64 -> 0 | R26: ='20'!$V$39 -> 0 | S26: ='20'!$V$40 -> 0 | T26: ='20'!$V$41 -> 0 | U26: ='20'!$V$44 -> 0 | V26: ='20'!$V$42 -> 0 | W26: ='20'!$V$43 -> 0 | X26: ='20'!$V$46 -> 0 | Y26: ='20'!$V$47 -> 0 | Z26: ='20'!$V$48 -> 0 | AA26: ='20'!$V$49 -> 0 | AB26: ='20'!$V$50 -> 0 | AC26: ='20'!$V$51 -> 0 | AD26: ='20'!V$52+'20'!V$53 -> 0 | AE26: =(R26+S26)-SUM(T26:AC26) -> 0
A27: 21 | J27: ='21'!$C$64 -> 0 | K27: ='21'!$G$64 -> 0 | L27: ='21'!$L$64 -> 0 | M27: ='21'!$S$64 -> 0 | N27: ='21'!$M$64 -> 0 | R27: ='21'!$V$39 -> 0 | S27: ='21'!$V$40 -> 0 | T27: ='21'!$V$41 -> 0 | U27: ='21'!$V$44 -> 0 | V27: ='21'!$V$42 -> 0 | W27: ='21'!$V$43 -> 0 | X27: ='21'!$V$46 -> 0 | Y27: ='21'!$V$47 -> 0 | Z27: ='21'!$V$48 -> 0 | AA27: ='21'!$V$49 -> 0 | AB27: ='21'!$V$50 -> 0 | AC27: ='21'!$V$51 -> 0 | AD27: ='21'!V$52+'21'!V$53 -> 0 | AE27: =(R27+S27)-SUM(T27:AC27) -> 0
A28: 22 | B28: GHOSNS103665BK | C28: HAT SATANIC PANIC | D28: WELLSUCCEED | E28: =VLOOKUP($A:$A,'COGS NEW TEMPLATE'!$A:$G,5,FALSE) -> 3.92 | F28: =VLOOKUP($A:$A,'COGS NEW TEMPLATE'!$A:$G,6,FALSE) -> 0 | G28: =VLOOKUP($A:$A,'COGS NEW TEMPLATE'!$A:$G,7,FALSE) -> 0 | H28: =SUM(E28:G28) -> 3.92 | J28: =HAT!$C$64 -> 1212 | K28: =HAT!$G$64 -> 1215 | L28: =HAT!$L$64 -> 0 | M28: =HAT!$S$64 -> 0 | N28: =HAT!$M$64 -> 0.0055925926 | R28: =HAT!$V$39 -> 1215 | S28: =HAT!$V$40 -> 0 | T28: =HAT!$V$41 -> 1212 | U28: =HAT!$V$44 -> 0 | V28: =HAT!$V$42 -> 3 | W28: =HAT!$V$43 -> 0 | X28: =HAT!$V$46 -> 0 | Y28: =HAT!$V$47 -> 0 | Z28: =HAT!$V$48 -> 0 | AA28: =HAT!$V$49 -> 0 | AB28: =HAT!$V$50 -> 0 | AC28: =HAT!$V$51 -> 0 | AD28: =HAT!V$52+HAT!V$53 -> 0 | AE28: =(R28+S28)-SUM(T28:AC28) -> 0
A29: 23 | B29: GHOSNS903309GR | C29: MASK BURNT GHOUL | D29: FARSTAR | E29: =VLOOKUP($A:$A,'COGS NEW TEMPLATE'!$A:$G,5,FALSE) -> 4.8 | F29: =VLOOKUP($A:$A,'COGS NEW TEMPLATE'!$A:$G,6,FALSE) -> 0 | G29: =VLOOKUP($A:$A,'COGS NEW TEMPLATE'!$A:$G,7,FALSE) -> 0 | H29: =SUM(E29:G29) -> 4.8 | J29: =MASK!$C$64 -> 3857 | K29: =MASK!$G$64 -> 3861 | L29: =MASK!$L$64 -> 0 | M29: =MASK!$S$64 -> 0 | N29: =MASK!$M$64 -> 0.020740741 | R29: =MASK!$V$39 -> 0 | S29: =MASK!$V$40 -> 4060 | T29: =MASK!$V$41 -> 3857 | U29: =MASK!$V$44 -> 2 | V29: =MASK!$V$42 -> 2 | W29: =MASK!$V$43 -> 0 | X29: =MASK!$V$46 -> 0 | Y29: =MASK!$V$47 -> 0 | Z29: =MASK!$V$48 -> 0 | AA29: =MASK!$V$49 -> 0 | AB29: =MASK!$V$50 -> 199 | AC29: =MASK!$V$51 -> 0 | AD29: =MASK!V$52+MASK!V$53 -> 0 | AE29: =(R29+S29)-SUM(T29:AC29) -> 0
A30: 24 | B30: GHOSNS903279OT | C30: PLUSHIE FRATER IMPERATOR | D30: FARSTAR | E30: =VLOOKUP($A:$A,'COGS NEW TEMPLATE'!$A:$G,5,FALSE) -> 8.9 | F30: =VLOOKUP($A:$A,'COGS NEW TEMPLATE'!$A:$G,6,FALSE) -> 0 | G30: =VLOOKUP($A:$A,'COGS NEW TEMPLATE'!$A:$G,7,FALSE) -> 0 | H30: =SUM(E30:G30) -> 8.9 | J30: =PLUSHIE!$C$64 -> 11108 | K30: =PLUSHIE!$G$64 -> 11118 | L30: =PLUSHIE!$L$64 -> 0 | M30: =PLUSHIE!$S$64 -> 0 | N30: =PLUSHIE!$M$64 -> 0.068888889 | R30: =PLUSHIE!$V$39 -> 0 | S30: =PLUSHIE!$V$40 -> 15998 | T30: =PLUSHIE!$V$41 -> 11108 | U30: =PLUSHIE!$V$44 -> 0 | V30: =PLUSHIE!$V$42 -> 10 | W30: =PLUSHIE!$V$43 -> 0 | X30: =PLUSHIE!$V$46 -> 0 | Y30: =PLUSHIE!$V$47 -> 0 | Z30: =PLUSHIE!$V$48 -> 0 | AA30: =PLUSHIE!$V$49 -> 0 | AB30: =PLUSHIE!$V$50 -> 1640 | AC30: =PLUSHIE!$V$51 -> 0 | AD30: =PLUSHIE!V$52+PLUSHIE!V$53 -> 3240 | AE30: =(R30+S30)-SUM(T30:AC30) -> 3240
A31: 25 | B31: GHOSRX103259OT | C31: CLEAR SLING BAG-SILVER LOGO | D31: FARSTAR | E31: =VLOOKUP($A:$A,'COGS NEW TEMPLATE'!$A:$G,5,FALSE) -> 3.8 | F31: =VLOOKUP($A:$A,'COGS NEW TEMPLATE'!$A:$G,6,FALSE) -> 0 | G31: =VLOOKUP($A:$A,'COGS NEW TEMPLATE'!$A:$G,7,FALSE) -> 0 | H31: =SUM(E31:G31) -> 3.8 | J31: ='CLEAR SLING BAG'!$C$64 -> 1373 | K31: ='CLEAR SLING BAG'!$G$64 -> 1380 | L31: ='CLEAR SLING BAG'!$L$64 -> 0 | M31: ='CLEAR SLING BAG'!$S$64 -> 1522 | N31: ='CLEAR SLING BAG'!$M$64 -> 0.0088888889 | R31: ='CLEAR SLING BAG'!$V$39 -> 0 | S31: ='CLEAR SLING BAG'!$V$40 -> 3319 | T31: ='CLEAR SLING BAG'!$V$41 -> 1373 | U31: ='CLEAR SLING BAG'!$V$44 -> 1 | V31: ='CLEAR SLING BAG'!$V$42 -> 6 | W31: ='CLEAR SLING BAG'!$V$43 -> 0 | X31: ='CLEAR SLING BAG'!$V$46 -> -83 | Y31: ='CLEAR SLING BAG'!$V$47 -> 0 | Z31: ='CLEAR SLING BAG'!$V$48 -> 300 | AA31: ='CLEAR SLING BAG'!$V$49 -> 0 | AB31: ='CLEAR SLING BAG'!$V$50 -> 200 | AC31: ='CLEAR SLING BAG'!$V$51 -> 0 | AD31: ='CLEAR SLING BAG'!V$52+'CLEAR SLING BAG'!V$53 -> 1522 | AE31: =(R31+S31)-SUM(T31:AC31) -> 1522
A32: 26 | B32: GHOSRX103241BK | C32: CHOKER PAPA V | D32: FARSTAR | E32: =VLOOKUP($A:$A,'COGS NEW TEMPLATE'!$A:$G,5,FALSE) -> 3.6 | F32: =VLOOKUP($A:$A,'COGS NEW TEMPLATE'!$A:$G,6,FALSE) -> 0 | G32: =VLOOKUP($A:$A,'COGS NEW TEMPLATE'!$A:$G,7,FALSE) -> 0 | H32: =SUM(E32:G32) -> 3.6 | J32: =CHOKER!$C$64 -> 2043 | K32: =CHOKER!$G$64 -> 2048 | L32: =CHOKER!$L$64 -> 0 | M32: =CHOKER!$S$64 -> 1511 | N32: =CHOKER!$M$64 -> 0.0096296296 | R32: =CHOKER!$V$39 -> 0 | S32: =CHOKER!$V$40 -> 3859 | T32: =CHOKER!$V$41 -> 2043 | U32: =CHOKER!$V$44 -> 0 | V32: =CHOKER!$V$42 -> 4 | W32: =CHOKER!$V$43 -> 1 | X32: =CHOKER!$V$46 -> 0 | Y32: =CHOKER!$V$47 -> 0 | Z32: =CHOKER!$V$48 -> 0 | AA32: =CHOKER!$V$49 -> 0 | AB32: =CHOKER!$V$50 -> 300 | AC32: =CHOKER!$V$51 -> 0 | AD32: =CHOKER!V$52+CHOKER!V$53 -> 1511 | AE32: =(R32+S32)-SUM(T32:AC32) -> 1511
A33: 27 | B33: GHOSRX203254GR | C33: KEYCHAIN SKELETON GRUCIFIX | D33: FARSTAR | E33: =VLOOKUP($A:$A,'COGS NEW TEMPLATE'!$A:$G,5,FALSE) -> 1.5 | F33: =VLOOKUP($A:$A,'COGS NEW TEMPLATE'!$A:$G,6,FALSE) -> 0 | G33: =VLOOKUP($A:$A,'COGS NEW TEMPLATE'!$A:$G,7,FALSE) -> 0 | H33: =SUM(E33:G33) -> 1.5 | J33: =KEYCHAIN!$C$64 -> 7144 | K33: =KEYCHAIN!$G$64 -> 7154 | L33: =KEYCHAIN!$L$64 -> 0 | M33: =KEYCHAIN!$S$64 -> 2629 | N33: =KEYCHAIN!$M$64 -> 0.014444444 | R33: =KEYCHAIN!$V$39 -> 0 | S33: =KEYCHAIN!$V$40 -> 10483 | T33: =KEYCHAIN!$V$41 -> 7144 | U33: =KEYCHAIN!$V$44 -> 0 | V33: =KEYCHAIN!$V$42 -> 5 | W33: =KEYCHAIN!$V$43 -> 5 | X33: =KEYCHAIN!$V$46 -> 100 | Y33: =KEYCHAIN!$V$47 -> 0 | Z33: =KEYCHAIN!$V$48 -> 0 | AA33: =KEYCHAIN!$V$49 -> 0 | AB33: =KEYCHAIN!$V$50 -> 600 | AC33: =KEYCHAIN!$V$51 -> 0 | AD33: =KEYCHAIN!V$52+KEYCHAIN!V$53 -> 2629 | AE33: =(R33+S33)-SUM(T33:AC33) -> 2629
A34: 28 | B34: GHOSRX903403OT | C34: PATCH SET OF 3 | D34: WELLSUCCEED | E34: =VLOOKUP($A:$A,'COGS NEW TEMPLATE'!$A:$G,5,FALSE) -> 2.05 | F34: =VLOOKUP($A:$A,'COGS NEW TEMPLATE'!$A:$G,6,FALSE) -> 0 | G34: =VLOOKUP($A:$A,'COGS NEW TEMPLATE'!$A:$G,7,FALSE) -> 0 | H34: =SUM(E34:G34) -> 2.05 | J34: ='PATCH SET'!$C$64 -> 4925 | K34: ='PATCH SET'!$G$64 -> 4931 | L34: ='PATCH SET'!$L$64 -> 0 | M34: ='PATCH SET'!$S$64 -> 1479 | N34: ='PATCH SET'!$M$64 -> 0.011851852 | R34: ='PATCH SET'!$V$39 -> 0 | S34: ='PATCH SET'!$V$40 -> 6910 | T34: ='PATCH SET'!$V$41 -> 4925 | U34: ='PATCH SET'!$V$44 -> 0 | V34: ='PATCH SET'!$V$42 -> 5 | W34: ='PATCH SET'!$V$43 -> 1 | X34: ='PATCH SET'!$V$46 -> 0 | Y34: ='PATCH SET'!$V$47 -> 0 | Z34: ='PATCH SET'!$V$48 -> 0 | AA34: ='PATCH SET'!$V$49 -> 0 | AB34: ='PATCH SET'!$V$50 -> 500 | AC34: ='PATCH SET'!$V$51 -> 0 | AD34: ='PATCH SET'!V$52+'PATCH SET'!V$53 -> 1479 | AE34: =(R34+S34)-SUM(T34:AC34) -> 1479
A35: 29 | B35: GHOSNS103814BK | C35: TOUR PROGRAM | D35: VANDALAY | E35: =VLOOKUP($A:$A,'COGS NEW TEMPLATE'!$A:$G,5,FALSE) -> 5.59 | F35: =VLOOKUP($A:$A,'COGS NEW TEMPLATE'!$A:$G,6,FALSE) -> 0 | G35: =VLOOKUP($A:$A,'COGS NEW TEMPLATE'!$A:$G,7,FALSE) -> 0 | H35: =SUM(E35:G35) -> 5.59 | J35: ='TOUR PROGRAM'!$C$64 -> 989 | K35: ='TOUR PROGRAM'!$G$64 -> 1118 | L35: ='TOUR PROGRAM'!$L$64 -> 0 | M35: ='TOUR PROGRAM'!$S$64 -> 2230 | N35: ='TOUR PROGRAM'!$M$64 -> 0.0035 | R35: ='TOUR PROGRAM'!$V$39 -> 0 | S35: ='TOUR PROGRAM'!$V$40 -> 5415 | T35: ='TOUR PROGRAM'!$V$41 -> 989 | U35: ='TOUR PROGRAM'!$V$44 -> 0 | V35: ='TOUR PROGRAM'!$V$42 -> 126 | W35: ='TOUR PROGRAM'!$V$43 -> 3 | X35: ='TOUR PROGRAM'!$V$46 -> 2 | Y35: ='TOUR PROGRAM'!$V$47 -> 0 | Z35: ='TOUR PROGRAM'!$V$48 -> 1015 | AA35: ='TOUR PROGRAM'!$V$49 -> 0 | AB35: ='TOUR PROGRAM'!$V$50 -> 1050 | AC35: ='TOUR PROGRAM'!$V$51 -> 0 | AD35: ='TOUR PROGRAM'!V$52+'TOUR PROGRAM'!V$53 -> 2230 | AE35: =(R35+S35)-SUM(T35:AC35) -> 2230
A36: 30 | B36: GHOSRX903408OT | C36: LP SKELETA POLTERGEIST | D36: CONCORD | E36: =VLOOKUP($A:$A,'COGS NEW TEMPLATE'!$A:$G,5,FALSE) -> 16.89 | F36: =VLOOKUP($A:$A,'COGS NEW TEMPLATE'!$A:$G,6,FALSE) -> 0 | G36: =VLOOKUP($A:$A,'COGS NEW TEMPLATE'!$A:$G,7,FALSE) -> 0 | H36: =SUM(E36:G36) -> 16.89 | J36: ='LP SKELETA POLTER'!$C$64 -> 1519 | K36: ='LP SKELETA POLTER'!$G$64 -> 1520 | L36: ='LP SKELETA POLTER'!$L$64 -> 0 | M36: ='LP SKELETA POLTER'!$S$64 -> 330 | N36: ='LP SKELETA POLTER'!$M$64 -> 0.0098148148 | R36: ='LP SKELETA POLTER'!$V$39 -> 0 | S36: ='LP SKELETA POLTER'!$V$40 -> 2000 | T36: ='LP SKELETA POLTER'!$V$41 -> 1519 | U36: ='LP SKELETA POLTER'!$V$44 -> 0 | V36: ='LP SKELETA POLTER'!$V$42 -> 0 | W36: ='LP SKELETA POLTER'!$V$43 -> 1 | X36: ='LP SKELETA POLTER'!$V$46 -> 0 | Y36: ='LP SKELETA POLTER'!$V$47 -> 0 | Z36: ='LP SKELETA POLTER'!$V$48 -> 0 | AA36: ='LP SKELETA POLTER'!$V$49 -> 0 | AB36: ='LP SKELETA POLTER'!$V$50 -> 150 | AC36: ='LP SKELETA POLTER'!$V$51 -> 0 | AD36: ='LP SKELETA POLTER'!V$52+'LP SKELETA POLTER'!V$53 -> 330 | AE36: =(R36+S36)-SUM(T36:AC36) -> 330
A37: 31 | B37: GHOSNS203369OT | C37: FOILED COMIC BOOK SISTER IMPERATOR # 1 | D37: DARK HORSE COMICS | E37: =VLOOKUP($A:$A,'COGS NEW TEMPLATE'!$A:$G,5,FALSE) -> 4.25 | F37: =VLOOKUP($A:$A,'COGS NEW TEMPLATE'!$A:$G,6,FALSE) -> 0 | G37: =VLOOKUP($A:$A,'COGS NEW TEMPLATE'!$A:$G,7,FALSE) -> 0 | H37: =SUM(E37:G37) -> 4.25 | J37: ='COMIC BOOK #1'!$C$64 -> 1303 | K37: ='COMIC BOOK #1'!$G$64 -> 1305 | L37: ='COMIC BOOK #1'!$L$64 -> 0 | M37: ='COMIC BOOK #1'!$S$64 -> 1195 | N37: ='COMIC BOOK #1'!$M$64 -> 0.0071296296 | R37: ='COMIC BOOK #1'!$V$39 -> 0 | S37: ='COMIC BOOK #1'!$V$40 -> 2500 | T37: ='COMIC BOOK #1'!$V$41 -> 1303 | U37: ='COMIC BOOK #1'!$V$44 -> 1 | V37: ='COMIC BOOK #1'!$V$42 -> 0 | W37: ='COMIC BOOK #1'!$V$43 -> 1 | X37: ='COMIC BOOK #1'!$V$46 -> 0 | Y37: ='COMIC BOOK #1'!$V$47 -> 0 | Z37: ='COMIC BOOK #1'!$V$48 -> 0 | AA37: ='COMIC BOOK #1'!$V$49 -> 0 | AB37: ='COMIC BOOK #1'!$V$50 -> 0 | AC37: ='COMIC BOOK #1'!$V$51 -> 0 | AD37: ='COMIC BOOK #1'!V$52+'COMIC BOOK #1'!V$53 -> 1195 | AE37: =(R37+S37)-SUM(T37:AC37) -> 1195
A38: 32 | B38: GHOSNS203533OT | C38: COMIC BOOK SISTER IMPERATOR #2 | D38: DARK HORSE COMICS | E38: =VLOOKUP($A:$A,'COGS NEW TEMPLATE'!$A:$G,5,FALSE) -> 2 | F38: =VLOOKUP($A:$A,'COGS NEW TEMPLATE'!$A:$G,6,FALSE) -> 0 | G38: =VLOOKUP($A:$A,'COGS NEW TEMPLATE'!$A:$G,7,FALSE) -> 0 | H38: =SUM(E38:G38) -> 2 | J38: ='COMIC BOOK #2'!$C$64 -> 301 | K38: ='COMIC BOOK #2'!$G$64 -> 301 | L38: ='COMIC BOOK #2'!$L$64 -> 0 | M38: ='COMIC BOOK #2'!$S$64 -> 0 | N38: ='COMIC BOOK #2'!$M$64 -> 0.0015185185 | R38: ='COMIC BOOK #2'!$V$39 -> 0 | S38: ='COMIC BOOK #2'!$V$40 -> 300 | T38: ='COMIC BOOK #2'!$V$41 -> 301 | U38: ='COMIC BOOK #2'!$V$44 -> 0 | V38: ='COMIC BOOK #2'!$V$42 -> 0 | W38: ='COMIC BOOK #2'!$V$43 -> 0 | X38: ='COMIC BOOK #2'!$V$46 -> -1 | Y38: ='COMIC BOOK #2'!$V$47 -> 0 | Z38: ='COMIC BOOK #2'!$V$48 -> 0 | AA38: ='COMIC BOOK #2'!$V$49 -> 0 | AB38: ='COMIC BOOK #2'!$V$50 -> 0 | AC38: ='COMIC BOOK #2'!$V$51 -> 0 | AD38: ='COMIC BOOK #2'!V$52+'COMIC BOOK #2'!V$53 -> 0 | AE38: =(R38+S38)-SUM(T38:AC38) -> 0
A39: 33 | B39: GHOSNS203534OT | C39: COMIC BOOK SISTER IMPERATOR #3 | D39: DARK HORSE COMICS | E39: =VLOOKUP($A:$A,'COGS NEW TEMPLATE'!$A:$G,5,FALSE) -> 2 | F39: =VLOOKUP($A:$A,'COGS NEW TEMPLATE'!$A:$G,6,FALSE) -> 0 | G39: =VLOOKUP($A:$A,'COGS NEW TEMPLATE'!$A:$G,7,FALSE) -> 0 | H39: =SUM(E39:G39) -> 2 | J39: ='COMIC BOOK #3'!$C$64 -> 299 | K39: ='COMIC BOOK #3'!$G$64 -> 299 | L39: ='COMIC BOOK #3'!$L$64 -> 0 | M39: ='COMIC BOOK #3'!$S$64 -> 0 | N39: ='COMIC BOOK #3'!$M$64 -> 0.0010555556 | R39: ='COMIC BOOK #3'!$V$39 -> 0 | S39: ='COMIC BOOK #3'!$V$40 -> 300 | T39: ='COMIC BOOK #3'!$V$41 -> 299 | U39: ='COMIC BOOK #3'!$V$44 -> 0 | V39: ='COMIC BOOK #3'!$V$42 -> 0 | W39: ='COMIC BOOK #3'!$V$43 -> 0 | X39: ='COMIC BOOK #3'!$V$46 -> 1 | Y39: ='COMIC BOOK #3'!$V$47 -> 0 | Z39: ='COMIC BOOK #3'!$V$48 -> 0 | AA39: ='COMIC BOOK #3'!$V$49 -> 0 | AB39: ='COMIC BOOK #3'!$V$50 -> 0 | AC39: ='COMIC BOOK #3'!$V$51 -> 0 | AD39: ='COMIC BOOK #3'!V$52+'COMIC BOOK #3'!V$53 -> 0 | AE39: =(R39+S39)-SUM(T39:AC39) -> 0
A40: 34 | B40: GHOSNS203535OT | C40: COMIC BOOK SISTER IMPERATOR #4 | D40: DARK HORSE COMICS | E40: =VLOOKUP($A:$A,'COGS NEW TEMPLATE'!$A:$G,5,FALSE) -> 2 | F40: =VLOOKUP($A:$A,'COGS NEW TEMPLATE'!$A:$G,6,FALSE) -> 0 | G40: =VLOOKUP($A:$A,'COGS NEW TEMPLATE'!$A:$G,7,FALSE) -> 0 | H40: =SUM(E40:G40) -> 2 | J40: ='COMIC BOOK #4'!$C$64 -> 297 | K40: ='COMIC BOOK #4'!$G$64 -> 297 | L40: ='COMIC BOOK #4'!$L$64 -> 0 | M40: ='COMIC BOOK #4'!$S$64 -> 0 | N40: ='COMIC BOOK #4'!$M$64 -> 0.0011685185 | R40: ='COMIC BOOK #4'!$V$39 -> 0 | S40: ='COMIC BOOK #4'!$V$40 -> 300 | T40: ='COMIC BOOK #4'!$V$41 -> 297 | U40: ='COMIC BOOK #4'!$V$44 -> 0 | V40: ='COMIC BOOK #4'!$V$42 -> 0 | W40: ='COMIC BOOK #4'!$V$43 -> 0 | X40: ='COMIC BOOK #4'!$V$46 -> 3 | Y40: ='COMIC BOOK #4'!$V$47 -> 0 | Z40: ='COMIC BOOK #4'!$V$48 -> 0 | AA40: ='COMIC BOOK #4'!$V$49 -> 0 | AB40: ='COMIC BOOK #4'!$V$50 -> 0 | AC40: ='COMIC BOOK #4'!$V$51 -> 0 | AD40: ='COMIC BOOK #4'!V$52+'COMIC BOOK #4'!V$53 -> 0 | AE40: =(R40+S40)-SUM(T40:AC40) -> 0
A41: 35 | E41: =VLOOKUP($A:$A,'COGS NEW TEMPLATE'!$A:$G,5,FALSE) -> 0 | F41: =VLOOKUP($A:$A,'COGS NEW TEMPLATE'!$A:$G,6,FALSE) -> 0 | G41: =VLOOKUP($A:$A,'COGS NEW TEMPLATE'!$A:$G,7,FALSE) -> 0 | H41: =SUM(E41:G41) -> 0 | J41: ='35'!$C$64 -> 0 | K41: ='35'!$G$64 -> 0 | L41: ='35'!$L$64 -> 0 | M41: ='35'!$S$64 -> 0 | N41: ='35'!$M$64 -> 0 | R41: ='35'!$V$39 -> 0 | S41: ='35'!$V$40 -> 0 | T41: ='35'!$V$41 -> 0 | U41: ='35'!$V$44 -> 0 | V41: ='35'!$V$42 -> 0 | W41: ='35'!$V$43 -> 0 | X41: ='35'!$V$46 -> 0 | Y41: ='35'!$V$47 -> 0 | Z41: ='35'!$V$48 -> 0 | AA41: ='35'!$V$49 -> 0 | AB41: ='35'!$V$50 -> 0 | AC41: ='35'!$V$51 -> 0 | AD41: ='35'!V$52+'35'!V$53 -> 0 | AE41: =(R41+S41)-SUM(T41:AC41) -> 0
...

Sheet NORTH AMERICA
A1: GLOBAL MERCHANDISING SERVICES, INC
A2: TOUR BUDGET - NORTH AMERICA
A4: ARTIST | I4: BRAND MANAGER
A5: TERRITORY | B5: NORTH AMERICA | I5: CURRENCY | L5: USD
A6: TOUR START/LOAD IN DATE | I6: FIRST SHOW CITY
A7: TOUR FINISH/LOUD OUT DATE | I7: LAST SHOW CITY
A8: TOUR DAYS | B8: =B7-B6 -> 0 | I8: TRANSPORT - RECOUP | L8: YES
A9: ROAD MANAGER | B9: Yes | I9: SECURITY - RECOUP | L9: YES
A11: TOUR ASSUMPTIONS | B11: USA | E11: CANADA | H11: FESTIVALS | K11: TOUR TOTAL
A13: TOTAL CAPACITY | K13: =E13+B13+H13 -> 0
A14: PROJ.ATTENDANCE | B14: 1 | E14: 1 | H14: 0 | K14: =IFERROR(K15/K13,0) -> 0
A15: PROJ.ATTENDANCE | B15: =B13*B14 -> 0 | E15: =E13*E14 -> 0 | H15: 0 | K15: =E15+B15+H15 -> 0
A16: TOUR STAFF | K16: =B16 -> 0
A17: NO.OF SHOWS | K17: =E17+B17+H17 -> 0
A18: P/HEAD | K18: =IFERROR(K20/K15,0) -> 0
A20: GROSS SALES | B20: =B18*B15 -> 0 | E20: =E18*E15 -> 0 | H20: =H18*H15 -> 0 | K20: =E20+B20+H20 -> 0
A21: CREDIT CARD % | B21: 1 | E21: 1 | H21: 1 | K21: =IFERROR(K22/K20,0) -> 0
A22: CREDT CARD AMOUNT | B22: =B20*B21 -> 0 | E22: =E20*E21 -> 0 | H22: =H20*H21 -> 0 | K22: =E22+B22+H22 -> 0
A23: PROGRAM PERCENTAGE | B23: 0 | E23: 0 | H23: 0 | K23: =IFERROR(K24/K20,0) -> 0
A24: PROGRAM GROSS | B24: =B23*B20 -> 0 | E24: =E23*E20 -> 0 | H24: =H23*H20 -> 0 | K24: =E24+B24+H24 -> 0
A25: TAX: | B25: =(B20-B24)*C25/(1+C25) -> 0 | C25: 0.08 | E25: =E20*F25/(1+F25) -> 0 | F25: 0.13 | H25: =H20*I25/(1+I25) -> 0 | I25: 0.08 | K25: =E25+B25+H25 -> 0 | L25: =IF(K25=0,0,K25/$K$26) -> 0
A26: NET SALES | B26: =B20-B25 -> 0 | E26: =E20-E25 -> 0 | H26: =H20-H25 -> 0 | K26: =E26+B26+H26 -> 0
A29: TOUR COSTS - ON NET | B29: =B11 -> USA | E29: =E11 -> CANADA | H29: =H11 -> FESTIVALS | K29: =K11 -> TOUR TOTAL
A31: COST OF GOODS | B31: =ROUND((B$26*C31),2) -> 0 | C31: 0 | E31: =ROUND((E$26*F31),2) -> 0 | F31: 0 | H31: =ROUND((H$26*I31),2) -> 0 | I31: 0 | K31: =B31+E31+H31 -> 0 | L31: =IF(K31=0,0,K31/$K$26) -> 0
A32: COST OF GOODS - UPLIFT | B32: =ROUND(B31*C32,2) -> 0 | C32: 0 | E32: =ROUND(E31*F32,2) -> 0 | F32: 0 | H32: =ROUND(H31*I32,2) -> 0 | I32: 0 | K32: =B32+E32+H32 -> 0 | L32: =IF(K32=0,0,K32/$K$26) -> 0
A33: ARTWORK | B33: =ROUND((B$26*C33),2) -> 0 | C33: 0 | E33: =ROUND((E$26*F33),2) -> 0 | F33: 0 | H33: =ROUND((H$26*I33),2) -> 0 | I33: 0 | K33: =B33+E33+H33 -> 0 | L33: =IF(K33=0,0,K33/$K$26) -> 0
A34: HALL FEES | B34: =ROUND((B$26*C34),2) -> 0 | C34: 0 | E34: =ROUND((E$26*F34),2) -> 0 | F34: 0 | H34: =ROUND((H$26*I34),2) -> 0 | I34: 0 | K34: =B34+E34+H34 -> 0 | L34: =IF(K34=0,0,K34/$K$26) -> 0
A35: CREDIT CARD FEE | B35: =ROUND(((B$26*B21)*C35),2) -> 0 | C35: 0 | E35: =ROUND(((E$26*E21)*F35),2) -> 0 | F35: 0 | H35: =ROUND(((H$26*H21)*I35),2) -> 0 | I35: 0 | K35: =B35+E35+H35 -> 0 | L35: =IF(K35=0,0,K35/$K$26) -> 0
A36: BOOTLEG SECURITY & LEGAL | B36: =IF($L$9="YES",0,ROUND((B$26*C36),2)) -> 0 | C36: 0 | E36: =IF($L$9="YES",0,ROUND((E$26*F36),2)) -> 0 | F36: 0 | H36: =IF($L$9="YES",0,ROUND((H$26*I36),2)) -> 0 | I36: 0 | K36: =B36+E36+H36 -> 0 | L36: =IF(K36=0,0,K36/$K$26) -> 0
A37: VENDORS | B37: =ROUND((B$26*C37),2) -> 0 | C37: 0 | E37: =ROUND((E$26*F37),2) -> 0 | F37: 0 | H37: =ROUND((H$26*I37),2) -> 0 | I37: 0 | K37: =B37+E37+H37 -> 0 | L37: =IF(K37=0,0,K37/$K$26) -> 0
A38: FREIGHT COST | B38: =ROUND((B$26*C38),2) -> 0 | C38: 0 | E38: =ROUND((E$26*F38),2) -> 0 | F38: 0 | H38: =ROUND((H$26*I38),2) -> 0 | I38: 0 | K38: =B38+E38+H38 -> 0 | L38: =IF(K38=0,0,K38/$K$26) -> 0
A39: DUTIES/TAXES | B39: =ROUND((B$31*C39),2) -> 0 | C39: 0 | E39: =ROUND((E$31*F39),2) -> 0 | F39: 0 | H39: =ROUND((H$31*I39),2) -> 0 | I39: 0 | K39: =B39+E39+H39 -> 0 | L39: =IF(K39=0,0,K39/$K$26) -> 0
A40: ROAD EXPENSES | B40: =IF($L$8="YES",B71-SUM(B66:B69),B71) -> 0 | C40: =IF(B40=0,0,B40/B26) -> 0 | E40: =IF($L$8="YES",E71-SUM(E66:E69),E71) -> 0 | F40: =IF(E40=0,0,E40/E26) -> 0 | H40: =IF($L$8="YES",H71-SUM(H66:H69),H71) -> 0 | I40: =IF(H40=0,0,H40/H26) -> 0 | K40: =B40+E40+H40 -> 0 | L40: =IF(K40=0,0,K40/$K$26) -> 0
A41: ADMIN FEE | B41: =ROUND((B$26*C41),2) -> 0 | C41: 0.03 | E41: =ROUND((E$26*F41),2) -> 0 | F41: 0.03 | H41: =ROUND((H$26*I41),2) -> 0 | I41: 0.03 | K41: =B41+E41+H41 -> 0 | L41: =IF(K41=0,0,K41/$K$26) -> 0
A42: TRANSPORT - RECOUPABLE | B42: =IF($L$8="YES",SUM(B66:B69),0) -> 0 | C42: =IF(B42=0,0,B42/B26) -> 0 | E42: =IF($L$8="YES",SUM(E66:E69),0) -> 0 | F42: =IF(E42=0,0,E42/E26) -> 0 | H42: =IF($L$8="YES",SUM(H66:H69),0) -> 0 | I42: =IF(H42=0,0,H42/H26) -> 0 | K42: =B42+E42+H42 -> 0 | L42: =IF(K42=0,0,K42/$K$26) -> 0
A43: BOOTLEG SECURITY & LEGAL - RECOUPABLE | B43: =IF($L$9="YES",ROUND((B$26*C43),2),0) -> 0 | C43: =C36 -> 0 | E43: =IF($L$9="YES",ROUND((E$26*F43),2),0) -> 0 | F43: =F36 -> 0 | H43: =IF($L$9="YES",ROUND((H$26*I43),2),0) -> 0 | I43: =I36 -> 0 | K43: =B43+E43+H43 -> 0 | L43: =IF(K43=0,0,K43/$K$26) -> 0
A45: TOTAL TOUR COSTS | B45: =SUM(B31:B41) -> 0 | C45: =IF(B45=0,0,B45/B26) -> 0 | E45: =SUM(E31:E41) -> 0 | F45: =IF(E45=0,0,E45/E26) -> 0 | H45: =SUM(H31:H41) -> 0 | I45: =IF(H45=0,0,H45/H26) -> 0 | K45: =SUM(K31:K41) -> 0 | L45: =IF(K45=0,0,K45/K26) -> 0
A46: PROFIT | B46: =B26-B45 -> 0 | C46: =IF(B46=0,0,B46/B26) -> 0 | E46: =E26-E45 -> 0 | F46: =IF(E46=0,0,E46/E26) -> 0 | H46: =H26-H45 -> 0 | I46: =IF(H46=0,0,H46/H26) -> 0 | K46: =B46+E46+H46 -> 0 | L46: =IF(K46=0,0,K46/K26) -> 0
A47: ARTIST | B47: =B46*C47 -> 0 | C47: 0.8 | E47: =E46*F47 -> 0 | F47: 0.8 | H47: =H46*I47 -> 0 | I47: 0.8 | K47: =B47+E47+H47 -> 0 | L47: =IF(K47=0,0,K47/K46) -> 0
A48: GLOBAL | B48: =B46*C48 -> 0 | C48: =1-C47 -> 0.2 | E48: =E46*F48 -> 0 | F48: =1-F47 -> 0.2 | H48: =H46*I48 -> 0 | I48: =1-I47 -> 0.2 | K48: =B48+E48+H48 -> 0 | L48: =IF(K48=0,0,K48/K46) -> 0
...

Sheet COGS NEW TEMPLATE
A1: GLOBAL MERCHANDISING SERVICES, INC.
A2: =Inventory!C3 -> GHOST
A3: TOUR COST OF GOODS SCHEDULE - NORTH AMERICA in USD
A4: 45874
A6: Brand Manager: | C6: KAYLA
A7: Enter sales tax rate: | C7: 0
A8: Enter specials rate: | C8: 0.2 | E8: CLOSE WHEN PDFing and SENDING TO CLIENT
A9: APPAREL | R9: APPAREL - ADJUSTED PRICE FOR SPECIAL
A10: ITEM # | B10: SKU # | C10: DESCRIPTION | D10: SIZE | E10: BLANK | F10: PRINT | G10: FULL PACKAGE | H10: COG | I10: COG 2 | J10: TOTAL COG | K10: SUGGESTED PRICE | L10: =("TAX @ " &C7) -> TAX @ 0 | M10: AFTER TAX ADJ. GROSS | N10: PRODUCT COST % (A.T.G.) | O10: SPECIAL YES/NO | P10: AGREED DATE BY BM | R10: SPECIAL ITEM PRICE | S10: =L10 -> TAX @ 0 | T10: AFTER TAX ADJ. GROSS | U10: SPECIAL COST % (A.T.G.) | V10: SPECIAL YES/NO
A11: 1 | B11: =VLOOKUP($A:$A,Inventory!$A:$C,2,FALSE) -> GHOSRX203729BK | C11: =VLOOKUP($A:$A,Inventory!$A:$C,3,FALSE) -> BLACK T SKELETOUR 2025 ITIN | D11: SM-XL | E11: 0 | F11: 0 | G11: 5.7 | H11: =SUM(E11:G11) -> 5.7 | I11: 0 | J11: =SUM(H11:I11) -> 5.7 | K11: 50 | L11: =$C$7 -> 0 | M11: =K11-IF(K11<>0,K11-(K11/(1+L11)),0) -> 50 | N11: =J11/M11 -> 0.114 | O11: =IF(N11>$C$8,"YES","NO") -> NO | R11: 55 | S11: =$C$7 -> 0 | T11: =R11-IF(R11<>0,R11-(R11/(1+S11)),0) -> 55 | U11: =J11/T11 -> 0.10363636 | V11: =IF(U11>$C$8,"YES","NO") -> NO
D12: 2XL | E12: 0 | F12: 0 | G12: 7.89 | H12: =SUM(E12:G12) -> 7.89 | I12: 0 | J12: =SUM(H12:I12) -> 7.89 | K12: 50 | L12: =$C$7 -> 0 | M12: =K12-IF(K12<>0,K12-(K12/(1+L12)),0) -> 50 | N12: =J12/M12 -> 0.1578 | O12: =IF(N12>$C$8,"YES","NO") -> NO | R12: 55 | S12: =$C$7 -> 0 | T12: =R12-IF(R12<>0,R12-(R12/(1+S12)),0) -> 55 | U12: =J12/T12 -> 0.14345455 | V12: =IF(U12>$C$8,"YES","NO") -> NO
D13: 3XL | E13: 0 | F13: 0 | G13: 9.22 | H13: =SUM(E13:G13) -> 9.22 | I13: 0 | J13: =SUM(H13:I13) -> 9.22 | K13: 50 | L13: =$C$7 -> 0 | M13: =K13-IF(K13<>0,K13-(K13/(1+L13)),0) -> 50 | N13: =J13/M13 -> 0.1844 | O13: =IF(N13>$C$8,"YES","NO") -> NO | R13: 55 | S13: =$C$7 -> 0 | T13: =R13-IF(R13<>0,R13-(R13/(1+S13)),0) -> 55 | U13: =J13/T13 -> 0.16763636 | V13: =IF(U13>$C$8,"YES","NO") -> NO
D14: 4XL | E14: 0 | F14: 0 | G14: 0 | H14: =SUM(E14:G14) -> 0 | I14: 0 | J14: =SUM(H14:I14) -> 0 | K14: 50 | L14: =$C$7 -> 0 | M14: =K14-IF(K14<>0,K14-(K14/(1+L14)),0) -> 50 | N14: =J14/M14 -> 0 | O14: =IF(N14>$C$8,"YES","NO") -> NO | R14: 55 | S14: =$C$7 -> 0 | T14: =R14-IF(R14<>0,R14-(R14/(1+S14)),0) -> 55 | U14: =J14/T14 -> 0 | V14: =IF(U14>$C$8,"YES","NO") -> NO
A15: 2 | B15: =VLOOKUP($A:$A,Inventory!$A:$C,2,FALSE) -> GHOSRX203728BK | C15: =VLOOKUP($A:$A,Inventory!$A:$C,3,FALSE) -> BLACK T SKELETA ALBUM COVER 2025 ITIN | D15: SM-XL | E15: 0 | F15: 0 | G15: 5.7 | H15: =SUM(E15:G15) -> 5.7 | I15: 0 | J15: =SUM(H15:I15) -> 5.7 | K15: 50 | L15: =$C$7 -> 0 | M15: =K15-IF(K15<>0,K15-(K15/(1+L15)),0) -> 50 | N15: =J15/M15 -> 0.114 | O15: =IF(N15>$C$8,"YES","NO") -> NO | R15: 55 | S15: =$C$7 -> 0 | T15: =R15-IF(R15<>0,R15-(R15/(1+S15)),0) -> 55 | U15: =J15/T15 -> 0.10363636 | V15: =IF(U15>$C$8,"YES","NO") -> NO
D16: 2XL | E16: 0 | F16: 0 | G16: 7.89 | H16: =SUM(E16:G16) -> 7.89 | I16: 0 | J16: =SUM(H16:I16) -> 7.89 | K16: 50 | L16: =$C$7 -> 0 | M16: =K16-IF(K16<>0,K16-(K16/(1+L16)),0) -> 50 | N16: =J16/M16 -> 0.1578 | O16: =IF(N16>$C$8,"YES","NO") -> NO | R16: 55 | S16: =$C$7 -> 0 | T16: =R16-IF(R16<>0,R16-(R16/(1+S16)),0) -> 55 | U16: =J16/T16 -> 0.14345455 | V16: =IF(U16>$C$8,"YES","NO") -> NO
D17: 3XL | E17: 0 | F17: 0 | G17: 9.22 | H17: =SUM(E17:G17) -> 9.22 | I17: 0 | J17: =SUM(H17:I17) -> 9.22 | K17: 50 | L17: =$C$7 -> 0 | M17: =K17-IF(K17<>0,K17-(K17/(1+L17)),0) -> 50 | N17: =J17/M17 -> 0.1844 | O17: =IF(N17>$C$8,"YES","NO") -> NO | R17: 55 | S17: =$C$7 -> 0 | T17: =R17-IF(R17<>0,R17-(R17/(1+S17)),0) -> 55 | U17: =J17/T17 -> 0.16763636 | V17: =IF(U17>$C$8,"YES","NO") -> NO
D18: 4XL | E18: 0 | F18: 0 | G18: 0 | H18: =SUM(E18:G18) -> 0 | I18: 0 | J18: =SUM(H18:I18) -> 0 | K18: 50 | L18: =$C$7 -> 0 | M18: =K18-IF(K18<>0,K18-(K18/(1+L18)),0) -> 50 | N18: =J18/M18 -> 0 | O18: =IF(N18>$C$8,"YES","NO") -> NO | R18: 55 | S18: =$C$7 -> 0 | T18: =R18-IF(R18<>0,R18-(R18/(1+S18)),0) -> 55 | U18: =J18/T18 -> 0 | V18: =IF(U18>$C$8,"YES","NO") -> NO
A19: 3 | B19: =VLOOKUP($A:$A,Inventory!$A:$C,2,FALSE) -> GHOSRX203730BK | C19: =VLOOKUP($A:$A,Inventory!$A:$C,3,FALSE) -> BLACK T WESTERN EMERITUS 2025 ITIN | D19: SM-XL | E19: 0 | F19: 0 | G19: 5.7 | H19: =SUM(E19:G19) -> 5.7 | I19: 0 | J19: =SUM(H19:I19) -> 5.7 | K19: 50 | L19: =$C$7 -> 0 | M19: =K19-IF(K19<>0,K19-(K19/(1+L19)),0) -> 50 | N19: =J19/M19 -> 0.114 | O19: =IF(N19>$C$8,"YES","NO") -> NO | R19: 55 | S19: =$C$7 -> 0 | T19: =R19-IF(R19<>0,R19-(R19/(1+S19)),0) -> 55 | U19: =J19/T19 -> 0.10363636 | V19: =IF(U19>$C$8,"YES","NO") -> NO
D20: 2XL | E20: 0 | F20: 0 | G20: 7.89 | H20: =SUM(E20:G20) -> 7.89 | I20: 0 | J20: =SUM(H20:I20) -> 7.89 | K20: 50 | L20: =$C$7 -> 0 | M20: =K20-IF(K20<>0,K20-(K20/(1+L20)),0) -> 50 | N20: =J20/M20 -> 0.1578 | O20: =IF(N20>$C$8,"YES","NO") -> NO | R20: 55 | S20: =$C$7 -> 0 | T20: =R20-IF(R20<>0,R20-(R20/(1+S20)),0) -> 55 | U20: =J20/T20 -> 0.14345455 | V20: =IF(U20>$C$8,"YES","NO") -> NO
D21: 3XL | E21: 0 | F21: 0 | G21: 9.22 | H21: =SUM(E21:G21) -> 9.22 | I21: 0 | J21: =SUM(H21:I21) -> 9.22 | K21: 50 | L21: =$C$7 -> 0 | M21: =K21-IF(K21<>0,K21-(K21/(1+L21)),0) -> 50 | N21: =J21/M21 -> 0.1844 | O21: =IF(N21>$C$8,"YES","NO") -> NO | R21: 55 | S21: =$C$7 -> 0 | T21: =R21-IF(R21<>0,R21-(R21/(1+S21)),0) -> 55 | U21: =J21/T21 -> 0.16763636 | V21: =IF(U21>$C$8,"YES","NO") -> NO
D22: 4XL | E22: 0 | F22: 0 | G22: 0 | H22: =SUM(E22:G22) -> 0 | I22: 0 | J22: =SUM(H22:I22) -> 0 | K22: 50 | L22: =$C$7 -> 0 | M22: =K22-IF(K22<>0,K22-(K22/(1+L22)),0) -> 50 | N22: =J22/M22 -> 0 | O22: =IF(N22>$C$8,"YES","NO") -> NO | R22: 55 | S22: =$C$7 -> 0 | T22: =R22-IF(R22<>0,R22-(R22/(1+S22)),0) -> 55 | U22: =J22/T22 -> 0 | V22: =IF(U22>$C$8,"YES","NO") -> NO
A23: 4 | B23: =VLOOKUP($A:$A,Inventory!$A:$C,2,FALSE) -> GHOSRX103726BK | C23: =VLOOKUP($A:$A,Inventory!$A:$C,3,FALSE) -> BLACK TANK OPUS EPONYMOUS | D23: SM-XL | E23: 0 | F23: 0 | G23: 7.38 | H23: =SUM(E23:G23) -> 7.38 | I23: 0 | J23: =SUM(H23:I23) -> 7.38 | K23: 50 | L23: =$C$7 -> 0 | M23: =K23-IF(K23<>0,K23-(K23/(1+L23)),0) -> 50 | N23: =J23/M23 -> 0.1476 | O23: =IF(N23>$C$8,"YES","NO") -> NO | R23: 55 | S23: =$C$7 -> 0 | T23: =R23-IF(R23<>0,R23-(R23/(1+S23)),0) -> 55 | U23: =J23/T23 -> 0.13418182 | V23: =IF(U23>$C$8,"YES","NO") -> NO
D24: 2XL | E24: 0 | F24: 0 | G24: 7.38 | H24: =SUM(E24:G24) -> 7.38 | I24: 0 | J24: =SUM(H24:I24) -> 7.38 | K24: 50 | L24: =$C$7 -> 0 | M24: =K24-IF(K24<>0,K24-(K24/(1+L24)),0) -> 50 | N24: =J24/M24 -> 0.1476 | O24: =IF(N24>$C$8,"YES","NO") -> NO | R24: 55 | S24: =$C$7 -> 0 | T24: =R24-IF(R24<>0,R24-(R24/(1+S24)),0) -> 55 | U24: =J24/T24 -> 0.13418182 | V24: =IF(U24>$C$8,"YES","NO") -> NO
D25: 3XL | E25: 0 | F25: 0 | G25: 7.38 | H25: =SUM(E25:G25) -> 7.38 | I25: 0 | J25: =SUM(H25:I25) -> 7.38 | K25: 50 | L25: =$C$7 -> 0 | M25: =K25-IF(K25<>0,K25-(K25/(1+L25)),0) -> 50 | N25: =J25/M25 -> 0.1476 | O25: =IF(N25>$C$8,"YES","NO") -> NO | R25: 55 | S25: =$C$7 -> 0 | T25: =R25-IF(R25<>0,R25-(R25/(1+S25)),0) -> 55 | U25: =J25/T25 -> 0.13418182 | V25: =IF(U25>$C$8,"YES","NO") -> NO
D26: 4XL | E26: 0 | F26: 0 | G26: 0 | H26: =SUM(E26:G26) -> 0 | I26: 0 | J26: =SUM(H26:I26) -> 0 | K26: 50 | L26: =$C$7 -> 0 | M26: =K26-IF(K26<>0,K26-(K26/(1+L26)),0) -> 50 | N26: =J26/M26 -> 0 | O26: =IF(N26>$C$8,"YES","NO") -> NO | R26: 55 | S26: =$C$7 -> 0 | T26: =R26-IF(R26<>0,R26-(R26/(1+S26)),0) -> 55 | U26: =J26/T26 -> 0 | V26: =IF(U26>$C$8,"YES","NO") -> NO
A27: 5 | B27: =VLOOKUP($A:$A,Inventory!$A:$C,2,FALSE) -> GHOSRX203400BK | C27: =VLOOKUP($A:$A,Inventory!$A:$C,3,FALSE) -> LADIES CROP TOP SHOWGHOULS | D27: SM-XL | E27: 0 | F27: 0 | G27: 9.77 | H27: =SUM(E27:G27) -> 9.77 | I27: 0 | J27: =SUM(H27:I27) -> 9.77 | K27: 50 | L27: =$C$7 -> 0 | M27: =K27-IF(K27<>0,K27-(K27/(1+L27)),0) -> 50 | N27: =J27/M27 -> 0.1954 | O27: =IF(N27>$C$8,"YES","NO") -> NO | R27: 55 | S27: =$C$7 -> 0 | T27: =R27-IF(R27<>0,R27-(R27/(1+S27)),0) -> 55 | U27: =J27/T27 -> 0.17763636 | V27: =IF(U27>$C$8,"YES","NO") -> NO
D28: 2XL | E28: 0 | F28: 0 | G28: 0 | H28: =SUM(E28:G28) -> 0 | I28: 0 | J28: =SUM(H28:I28) -> 0 | K28: 50 | L28: =$C$7 -> 0 | M28: =K28-IF(K28<>0,K28-(K28/(1+L28)),0) -> 50 | N28: =J28/M28 -> 0 | O28: =IF(N28>$C$8,"YES","NO") -> NO | R28: 55 | S28: =$C$7 -> 0 | T28: =R28-IF(R28<>0,R28-(R28/(1+S28)),0) -> 55 | U28: =J28/T28 -> 0 | V28: =IF(U28>$C$8,"YES","NO") -> NO
D29: 3XL | E29: 0 | F29: 0 | G29: 0 | H29: =SUM(E29:G29) -> 0 | I29: 0 | J29: =SUM(H29:I29) -> 0 | K29: 50 | L29: =$C$7 -> 0 | M29: =K29-IF(K29<>0,K29-(K29/(1+L29)),0) -> 50 | N29: =J29/M29 -> 0 | O29: =IF(N29>$C$8,"YES","NO") -> NO | R29: 55 | S29: =$C$7 -> 0 | T29: =R29-IF(R29<>0,R29-(R29/(1+S29)),0) -> 55 | U29: =J29/T29 -> 0 | V29: =IF(U29>$C$8,"YES","NO") -> NO
D30: 4XL | E30: 0 | F30: 0 | G30: 0 | H30: =SUM(E30:G30) -> 0 | I30: 0 | J30: =SUM(H30:I30) -> 0 | K30: 50 | L30: =$C$7 -> 0 | M30: =K30-IF(K30<>0,K30-(K30/(1+L30)),0) -> 50 | N30: =J30/M30 -> 0 | O30: =IF(N30>$C$8,"YES","NO") -> NO | R30: 55 | S30: =$C$7 -> 0 | T30: =R30-IF(R30<>0,R30-(R30/(1+S30)),0) -> 55 | U30: =J30/T30 -> 0 | V30: =IF(U30>$C$8,"YES","NO") -> NO
A31: 6 | B31: =VLOOKUP($A:$A,Inventory!$A:$C,2,FALSE) -> GHOSRX203727PK | C31: =VLOOKUP($A:$A,Inventory!$A:$C,3,FALSE) -> LADIES PINK RAGLAN GARGOYLE | D31: SM-XL | E31: 0 | F31: 0 | G31: 12.29 | H31: =SUM(E31:G31) -> 12.29 | I31: 0 | J31: =SUM(H31:I31) -> 12.29 | K31: 50 | L31: =$C$7 -> 0 | M31: =K31-IF(K31<>0,K31-(K31/(1+L31)),0) -> 50 | N31: =J31/M31 -> 0.2458 | O31: =IF(N31>$C$8,"YES","NO") -> YES | R31: 55 | S31: =$C$7 -> 0 | T31: =R31-IF(R31<>0,R31-(R31/(1+S31)),0) -> 55 | U31: =J31/T31 -> 0.22345455 | V31: =IF(U31>$C$8,"YES","NO") -> YES
D32: 2XL | E32: 0 | F32: 0 | G32: 0 | H32: =SUM(E32:G32) -> 0 | I32: 0 | J32: =SUM(H32:I32) -> 0 | K32: 50 | L32: =$C$7 -> 0 | M32: =K32-IF(K32<>0,K32-(K32/(1+L32)),0) -> 50 | N32: =J32/M32 -> 0 | O32: =IF(N32>$C$8,"YES","NO") -> NO | R32: 55 | S32: =$C$7 -> 0 | T32: =R32-IF(R32<>0,R32-(R32/(1+S32)),0) -> 55 | U32: =J32/T32 -> 0 | V32: =IF(U32>$C$8,"YES","NO") -> NO
D33: 3XL | E33: 0 | F33: 0 | G33: 0 | H33: =SUM(E33:G33) -> 0 | I33: 0 | J33: =SUM(H33:I33) -> 0 | K33: 50 | L33: =$C$7 -> 0 | M33: =K33-IF(K33<>0,K33-(K33/(1+L33)),0) -> 50 | N33: =J33/M33 -> 0 | O33: =IF(N33>$C$8,"YES","NO") -> NO | R33: 55 | S33: =$C$7 -> 0 | T33: =R33-IF(R33<>0,R33-(R33/(1+S33)),0) -> 55 | U33: =J33/T33 -> 0 | V33: =IF(U33>$C$8,"YES","NO") -> NO
D34: 4XL | E34: 0 | F34: 0 | G34: 0 | H34: =SUM(E34:G34) -> 0 | I34: 0 | J34: =SUM(H34:I34) -> 0 | K34: 50 | L34: =$C$7 -> 0 | M34: =K34-IF(K34<>0,K34-(K34/(1+L34)),0) -> 50 | N34: =J34/M34 -> 0 | O34: =IF(N34>$C$8,"YES","NO") -> NO | R34: 55 | S34: =$C$7 -> 0 | T34: =R34-IF(R34<>0,R34-(R34/(1+S34)),0) -> 55 | U34: =J34/T34 -> 0 | V34: =IF(U34>$C$8,"YES","NO") -> NO
A35: 7 | B35: =VLOOKUP($A:$A,Inventory!$A:$C,2,FALSE) -> 0 | C35: =VLOOKUP($A:$A,Inventory!$A:$C,3,FALSE) -> 0 | D35: SM-XL | E35: 0 | F35: 0 | G35: 0 | H35: =SUM(E35:G35) -> 0 | I35: 0 | J35: =SUM(H35:I35) -> 0 | K35: 50 | L35: =$C$7 -> 0 | M35: =K35-IF(K35<>0,K35-(K35/(1+L35)),0) -> 50 | N35: =J35/M35 -> 0 | O35: =IF(N35>$C$8,"YES","NO") -> NO | R35: 55 | S35: =$C$7 -> 0 | T35: =R35-IF(R35<>0,R35-(R35/(1+S35)),0) -> 55 | U35: =J35/T35 -> 0 | V35: =IF(U35>$C$8,"YES","NO") -> NO
D36: 2XL | E36: 0 | F36: 0 | G36: 0 | H36: =SUM(E36:G36) -> 0 | I36: 0 | J36: =SUM(H36:I36) -> 0 | K36: 50 | L36: =$C$7 -> 0 | M36: =K36-IF(K36<>0,K36-(K36/(1+L36)),0) -> 50 | N36: =J36/M36 -> 0 | O36: =IF(N36>$C$8,"YES","NO") -> NO | R36: 55 | S36: =$C$7 -> 0 | T36: =R36-IF(R36<>0,R36-(R36/(1+S36)),0) -> 55 | U36: =J36/T36 -> 0 | V36: =IF(U36>$C$8,"YES","NO") -> NO
D37: 3XL | E37: 0 | F37: 0 | G37: 0 | H37: =SUM(E37:G37) -> 0 | I37: 0 | J37: =SUM(H37:I37) -> 0 | K37: 50 | L37: =$C$7 -> 0 | M37: =K37-IF(K37<>0,K37-(K37/(1+L37)),0) -> 50 | N37: =J37/M37 -> 0 | O37: =IF(N37>$C$8,"YES","NO") -> NO | R37: 55 | S37: =$C$7 -> 0 | T37: =R37-IF(R37<>0,R37-(R37/(1+S37)),0) -> 55 | U37: =J37/T37 -> 0 | V37: =IF(U37>$C$8,"YES","NO") -> NO
D38: 4XL | E38: 0 | F38: 0 | G38: 0 | H38: =SUM(E38:G38) -> 0 | I38: 0 | J38: =SUM(H38:I38) -> 0 | K38: 50 | L38: =$C$7 -> 0 | M38: =K38-IF(K38<>0,K38-(K38/(1+L38)),0) -> 50 | N38: =J38/M38 -> 0 | O38: =IF(N38>$C$8,"YES","NO") -> NO | R38: 55 | S38: =$C$7 -> 0 | T38: =R38-IF(R38<>0,R38-(R38/(1+S38)),0) -> 55 | U38: =J38/T38 -> 0 | V38: =IF(U38>$C$8,"YES","NO") -> NO
A39: 8 | B39: =VLOOKUP($A:$A,Inventory!$A:$C,2,FALSE) -> GHOSNS903311BK | C39: =VLOOKUP($A:$A,Inventory!$A:$C,3,FALSE) -> BATWING HOODY | D39: SM-XL | E39: 0 | F39: 0 | G39: 28.5 | H39: =SUM(E39:G39) -> 28.5 | I39: 0 | J39: =SUM(H39:I39) -> 28.5 | K39: 125 | L39: =$C$7 -> 0 | M39: =K39-IF(K39<>0,K39-(K39/(1+L39)),0) -> 125 | N39: =J39/M39 -> 0.228 | O39: =IF(N39>$C$8,"YES","NO") -> YES | R39: 55 | S39: =$C$7 -> 0 | T39: =R39-IF(R39<>0,R39-(R39/(1+S39)),0) -> 55 | U39: =J39/T39 -> 0.51818182 | V39: =IF(U39>$C$8,"YES","NO") -> YES
D40: 2XL | E40: 0 | F40: 0 | G40: 28.5 | H40: =SUM(E40:G40) -> 28.5 | I40: 0 | J40: =SUM(H40:I40) -> 28.5 | K40: 125 | L40: =$C$7 -> 0 | M40: =K40-IF(K40<>0,K40-(K40/(1+L40)),0) -> 125 | N40: =J40/M40 -> 0.228 | O40: =IF(N40>$C$8,"YES","NO") -> YES | R40: 55 | S40: =$C$7 -> 0 | T40: =R40-IF(R40<>0,R40-(R40/(1+S40)),0) -> 55 | U40: =J40/T40 -> 0.51818182 | V40: =IF(U40>$C$8,"YES","NO") -> YES
D41: 3XL | E41: 0 | F41: 0 | G41: 28.5 | H41: =SUM(E41:G41) -> 28.5 | I41: 0 | J41: =SUM(H41:I41) -> 28.5 | K41: 125 | L41: =$C$7 -> 0 | M41: =K41-IF(K41<>0,K41-(K41/(1+L41)),0) -> 125 | N41: =J41/M41 -> 0.228 | O41: =IF(N41>$C$8,"YES","NO") -> YES | R41: 55 | S41: =$C$7 -> 0 | T41: =R41-IF(R41<>0,R41-(R41/(1+S41)),0) -> 55 | U41: =J41/T41 -> 0.51818182 | V41: =IF(U41>$C$8,"YES","NO") -> YES
...

Sheet Selling Prices
A1: Tour Inventory
B3: Tour | C3: =Inventory!C3 -> GHOST
B4: Tour Date | C4: =Inventory!C4 -> SUMMER 2025
D6: USD | E6: CAD
B7: NAV Item Code | C7: Product Description | D7: Selling Price | E7: Selling Price | F7: Selling Price | G7: Selling Price
A8: 1 | B8: =Inventory!B7 -> GHOSRX203729BK | C8: =Inventory!C7 -> BLACK T SKELETOUR 2025 ITIN | D8: ='Projection Sheet'!D15 -> 50
A9: 2 | B9: =Inventory!B8 -> GHOSRX203728BK | C9: =Inventory!C8 -> BLACK T SKELETA ALBUM COVER 2025 ITIN | D9: ='Projection Sheet'!D16 -> 50
A10: 3 | B10: =Inventory!B9 -> GHOSRX203730BK | C10: =Inventory!C9 -> BLACK T WESTERN EMERITUS 2025 ITIN | D10: ='Projection Sheet'!D17 -> 50
A11: 4 | B11: =Inventory!B10 -> GHOSRX103726BK | C11: =Inventory!C10 -> BLACK TANK OPUS EPONYMOUS | D11: ='Projection Sheet'!D18 -> 50
A12: 5 | B12: =Inventory!B11 -> GHOSRX203400BK | C12: =Inventory!C11 -> LADIES CROP TOP SHOWGHOULS | D12: ='Projection Sheet'!D19 -> 50
A13: 6 | B13: =Inventory!B12 -> GHOSRX203727PK | C13: =Inventory!C12 -> LADIES PINK RAGLAN GARGOYLE | D13: ='Projection Sheet'!D20 -> 50
A14: 7 | B14: =Inventory!B13 -> 0 | C14: =Inventory!C13 -> 0 | D14: ='Projection Sheet'!D21 -> 1
A15: 8 | B15: =Inventory!B14 -> GHOSNS903311BK | C15: =Inventory!C14 -> BATWING HOODY | D15: ='Projection Sheet'!D22 -> 125
A16: 9 | B16: =Inventory!B15 -> GHOSRX203401BK | C16: =Inventory!C15 -> PULLOVER HOODY SKELETON | D16: ='Projection Sheet'!D23 -> 80
A17: 10 | B17: =Inventory!B16 -> GHOSRX203275BK | C17: =Inventory!C16 -> SHORTS BLACK/ WHT PAPA V COSTUME CLAWS | D17: ='Projection Sheet'!D24 -> 45
A18: 11 | B18: =Inventory!B17 -> GHOSRX103510OT | C18: =Inventory!C17 -> TIE DYE T TOP HAT | D18: ='Projection Sheet'!D25 -> 60
A19: 12 | B19: =Inventory!B18 -> GHOSRX103437OT | C19: =Inventory!C18 -> CRYSTAL WASHED T AT THE GATES | D19: ='Projection Sheet'!D26 -> 60
... A67: 60 | B67: =Inventory!B66 -> 0 | C67: =Inventory!C66 -> 0 | D67: ='Projection Sheet'!D74 -> 0
A68: 61 | B68: =Inventory!B67 -> 0 | C68: =Inventory!C67 -> 0 | D68: ='Projection Sheet'!D75 -> 0
A69: 62 | B69: =Inventory!B68 -> 0 | C69: =Inventory!C68 -> 0 | D69: ='Projection Sheet'!D76 -> 0
A70: 63 | B70: =Inventory!B69 -> 0 | C70: =Inventory!C69 -> 0 | D70: ='Projection Sheet'!D77 -> 0
A71: 64 | B71: =Inventory!B70 -> 0 | C71: =Inventory!C70 -> 0 | D71: ='Projection Sheet'!D78 -> 0
A72: 65 | B72: =Inventory!B71 -> 0 | C72: =Inventory!C71 -> 0 | D72: ='Projection Sheet'!D79 -> 0
A73: 66 | B73: =Inventory!B72 -> 0 | C73: =Inventory!C72 -> 0 | D73: ='Projection Sheet'!D80 -> 0
A74: 67 | B74: =Inventory!B73 -> 0 | C74: =Inventory!C73 -> 0 | D74: ='Projection Sheet'!D81 -> 0
A75: 68 | B75: =Inventory!B74 -> 0 | C75: =Inventory!C74 -> 0 | D75: ='Projection Sheet'!D82 -> 0
A76: 69 | B76: =Inventory!B75 -> 0 | C76: =Inventory!C75 -> 0 | D76: ='Projection Sheet'!D83 -> 0
A77: 70 | B77: =Inventory!B76 -> 0 | C77: =Inventory!C76 -> 0 | D77: ='Projection Sheet'!D84 -> 0
A78: 71 | B78: =Inventory!B77 -> 0 | C78: =Inventory!C77 -> 0 | D78: ='Projection Sheet'!D85 -> 0
A79: 72 | B79: =Inventory!B78 -> 0 | C79: =Inventory!C78 -> 0 | D79: ='Projection Sheet'!D86 -> 0
... A107: 100 | B107: =Inventory!B106 -> 0 | C107: =Inventory!C106 -> 0 | D107: ='Projection Sheet'!D114 -> 0

Sheet Projection Sheet
F2: SM | G2: MED | H2: LG | I2: XL | J2: 2X | K2: 3X | L2: TOTAL | N2: TOUR STOCK | O2: ORDER QTY | P2: TOTAL | Q2: SIZE | R2: SIZE % | S2: AMOUNT | T2: LESS TOUR INV | U2: ORDER QTY | X2: TS | Y2: LADIES | Z2: LS | AA2: ZIP | AB2: SHORTS
L3: =SUM(F3:K3) -> 0 | N3: 1811 | O3: 720 | P3: =N3+O3 -> 2531 | Q3: SM | R3: 0.08 | S3: =P3*R3 -> 202.48 | T3: 107 | U3: =S3-T3 -> 95.48 | X3: 0.09 | Y3: 0.25 | Z3: 0.04 | AA3: 0.08 | AB3: 0.2
L4: =SUM(F4:K4) -> 0 | P4: =P3 -> 2531 | Q4: MED | R4: 0.18 | S4: =P4*R4 -> 455.58 | T4: 356 | U4: =S4-T4 -> 99.58 | X4: 0.21 | Y4: 0.32 | Z4: 0.17 | AA4: 0.18 | AB4: 0.27
L5: =SUM(F5:K5) -> 0 | P5: =P3 -> 2531 | Q5: LG | R5: 0.27 | S5: =P5*R5 -> 683.37 | T5: 415 | U5: =S5-T5 -> 268.37 | X5: 0.29 | Y5: 0.24 | Z5: 0.24 | AA5: 0.27 | AB5: 0.21 | AG5: DATE | AH5: CITY | AI5: ST | AJ5: VENUE | AK5: CAPACITY | AL5: SOLD | AM5: EXPECT | AO5: PH | AP5: GROSS | AQ5: SELLS | AR5: MERCH | AS5: MEDIA
B6: DATE: | C6: 45796 | L6: =SUM(F6:K6) -> 0 | P6: =P3 -> 2531 | Q6: XL | R6: 0.23 | S6: =P6*R6 -> 582.13 | T6: 540 | U6: =S6-T6 -> 42.13 | X6: 0.23 | Y6: 0.19 | Z6: 0.26 | AA6: 0.23 | AB6: 0.2 | AG6: ='Tour Dates'!A4 -> 45847 | AH6: ='Tour Dates'!B4 -> Baltimore | AI6: ='Tour Dates'!C4 -> MD | AJ6: ='Tour Dates'!D4 -> CFG Bank Arena | AK6: 10153 | AL6: 7892 | AM6: 8500 | AO6: 30 | AP6: =AM6*AO6 -> 255000
B7: BAND: | C7: =Inventory!C3 -> GHOST | L7: =SUM(F7:K7) -> 0 | P7: =P5 -> 2531 | Q7: 2X | R7: 0.15 | S7: =P7*R7 -> 379.65 | T7: 393 | U7: =S7-T7 -> -13.35 | X7: 0.12 | Y7: 0 | Z7: 0.18 | AA7: 0.15 | AB7: 0.12 | AG7: ='Tour Dates'!A5 -> 45849 | AH7: ='Tour Dates'!B5 -> Atlanta | AI7: ='Tour Dates'!C5 -> GA | AJ7: ='Tour Dates'!D5 -> State Farm Arena | AK7: 10699 | AL7: 8803 | AM7: 9500 | AO7: 30 | AP7: =AM7*AO7 -> 285000
B8: TOUR: | C8: North America | L8: =SUM(F8:K8) -> 0 | P8: =P5 -> 2531 | Q8: 3X | R8: 0.09 | S8: =P8*R8 -> 227.79 | T8: 0 | U8: =S8-T8 -> 227.79 | X8: 0.06 | Y8: 0 | Z8: 0.09 | AA8: 0.09 | AB8: 0 | AG8: ='Tour Dates'!A6 -> 45850 | AH8: ='Tour Dates'!B6 -> Tampa | AI8: ='Tour Dates'!C6 -> FL | AJ8: ='Tour Dates'!D6 -> Amalie Arena | AK8: 12354 | AL8: 11053 | AM8: 11500 | AO8: 30 | AP8: =AM8*AO8 -> 345000
B9: # OF SHOWS: | C9: 27 | R9: =SUM(R3:R8) -> 1 | T9: =SUM(T3:T8) -> 1811 | U9: =SUM(U3:U8) -> 720 | X9: 0 | Y9: 0 | Z9: 0.02 | AA9: 0 | AB9: 0 | AG9: ='Tour Dates'!A7 -> 45851 | AH9: ='Tour Dates'!B7 -> Miami | AI9: ='Tour Dates'!C7 -> FL | AJ9: ='Tour Dates'!D7 -> Kaseya Center | AK9: 5497 | AL9: 4290 | AM9: 4500 | AO9: 30 | AP9: =AM9*AO9 -> 135000
